2025-03-31 00:05:25,210 - INFO: 临时目录创建于: C:\Users\C\AppData\Local\Temp\music_bucextgq
2025-03-31 00:05:25,212 - INFO: 服务启动初始化完成
2025-03-31 00:22:31,705 - INFO: 临时目录创建于: C:\Users\C\AppData\Local\Temp\music__u68vyr0
2025-03-31 00:22:31,710 - INFO: 服务启动初始化完成
2025-03-31 00:38:26,514 - INFO: 临时目录创建于: C:\Users\C\AppData\Local\Temp\music_3dk0r_c1
2025-03-31 00:38:26,521 - INFO: 服务启动初始化完成
2025-03-31 00:40:01,761 - INFO: 临时目录创建于: C:\Users\C\AppData\Local\Temp\music_mj4tytee
2025-03-31 00:40:01,769 - INFO: 服务启动初始化完成
2025-03-31 01:16:11,613 - INFO: 临时目录创建于: C:\Users\C\AppData\Local\Temp\music_hhiaphx_
2025-03-31 01:16:11,619 - INFO: 服务启动初始化完成
2025-03-31 16:03:01,979 - INFO: 临时目录创建于: C:\Users\C\AppData\Local\Temp\music_4z0xk30e
2025-03-31 16:03:01,988 - INFO: 服务启动初始化完成
2025-03-31 16:04:35,402 - ERROR: Exception on /register [POST]
Traceback (most recent call last):
  File "C:\Users\C\.conda\envs\tryagain\lib\site-packages\flask\app.py", line 1473, in wsgi_app
    response = self.full_dispatch_request()
  File "C:\Users\C\.conda\envs\tryagain\lib\site-packages\flask\app.py", line 882, in full_dispatch_request
    rv = self.handle_user_exception(e)
  File "C:\Users\C\.conda\envs\tryagain\lib\site-packages\flask_cors\extension.py", line 194, in wrapped_function
    return cors_after_request(app.make_response(f(*args, **kwargs)))
  File "C:\Users\C\.conda\envs\tryagain\lib\site-packages\flask\app.py", line 880, in full_dispatch_request
    rv = self.dispatch_request()
  File "C:\Users\C\.conda\envs\tryagain\lib\site-packages\flask\app.py", line 865, in dispatch_request
    return self.ensure_sync(self.view_functions[rule.endpoint])(**view_args)  # type: ignore[no-any-return]
  File "d:\Psystem\Databased\DataBase\music\app.py", line 351, in register_user
    result = database.add_user(data["username"], data["account"], data["phone"], data["password"])
  File "d:\Psystem\Databased\DataBase\music\database.py", line 43, in add_user
    user_exists = cursor.fetchone()[0]  # 获取计数结果
TypeError: 'NoneType' object is not subscriptable
2025-03-31 16:12:28,404 - INFO: 临时目录创建于: C:\Users\C\AppData\Local\Temp\music_mq7om7t9
2025-03-31 16:12:28,407 - INFO: 服务启动初始化完成
2025-03-31 17:08:01,266 - ERROR: Exception on /device/connect [POST]
Traceback (most recent call last):
  File "C:\Users\C\.conda\envs\tryagain\lib\site-packages\flask\app.py", line 1473, in wsgi_app
    response = self.full_dispatch_request()
  File "C:\Users\C\.conda\envs\tryagain\lib\site-packages\flask\app.py", line 882, in full_dispatch_request
    rv = self.handle_user_exception(e)
  File "C:\Users\C\.conda\envs\tryagain\lib\site-packages\flask_cors\extension.py", line 194, in wrapped_function
    return cors_after_request(app.make_response(f(*args, **kwargs)))
  File "C:\Users\C\.conda\envs\tryagain\lib\site-packages\flask\app.py", line 880, in full_dispatch_request
    rv = self.dispatch_request()
  File "C:\Users\C\.conda\envs\tryagain\lib\site-packages\flask\app.py", line 865, in dispatch_request
    return self.ensure_sync(self.view_functions[rule.endpoint])(**view_args)  # type: ignore[no-any-return]
  File "d:\Psystem\Databased\DataBase\music\app.py", line 360, in connect_device
    result = database.record_device_connection(data["account"], data["device_id"], data["status"],data["device_name"],data["mac_address"])
  File "d:\Psystem\Databased\DataBase\music\database.py", line 98, in record_device_connection
    cursor.execute(sql,(account, device_id))
  File "C:\Users\C\.conda\envs\tryagain\lib\site-packages\pymysql\cursors.py", line 148, in execute
    result = self._query(query)
  File "C:\Users\C\.conda\envs\tryagain\lib\site-packages\pymysql\cursors.py", line 310, in _query
    conn.query(q)
  File "C:\Users\C\.conda\envs\tryagain\lib\site-packages\pymysql\connections.py", line 548, in query
    self._affected_rows = self._read_query_result(unbuffered=unbuffered)
  File "C:\Users\C\.conda\envs\tryagain\lib\site-packages\pymysql\connections.py", line 775, in _read_query_result
    result.read()
  File "C:\Users\C\.conda\envs\tryagain\lib\site-packages\pymysql\connections.py", line 1156, in read
    first_packet = self.connection._read_packet()
  File "C:\Users\C\.conda\envs\tryagain\lib\site-packages\pymysql\connections.py", line 725, in _read_packet
    packet.raise_for_error()
  File "C:\Users\C\.conda\envs\tryagain\lib\site-packages\pymysql\protocol.py", line 221, in raise_for_error
    err.raise_mysql_exception(self._data)
  File "C:\Users\C\.conda\envs\tryagain\lib\site-packages\pymysql\err.py", line 143, in raise_mysql_exception
    raise errorclass(errno, errval)
pymysql.err.IntegrityError: (1452, 'Cannot add or update a child row: a foreign key constraint fails (`calmwave_databases`.`device_connection_history`, CONSTRAINT `device_connection_history_ibfk_1` FOREIGN KEY (`account`) REFERENCES `user` (`account`))')
2025-03-31 17:11:34,701 - ERROR: Exception on /device/connect [POST]
Traceback (most recent call last):
  File "C:\Users\C\.conda\envs\tryagain\lib\site-packages\flask\app.py", line 1473, in wsgi_app
    response = self.full_dispatch_request()
  File "C:\Users\C\.conda\envs\tryagain\lib\site-packages\flask\app.py", line 882, in full_dispatch_request
    rv = self.handle_user_exception(e)
  File "C:\Users\C\.conda\envs\tryagain\lib\site-packages\flask_cors\extension.py", line 194, in wrapped_function
    return cors_after_request(app.make_response(f(*args, **kwargs)))
  File "C:\Users\C\.conda\envs\tryagain\lib\site-packages\flask\app.py", line 880, in full_dispatch_request
    rv = self.dispatch_request()
  File "C:\Users\C\.conda\envs\tryagain\lib\site-packages\flask\app.py", line 865, in dispatch_request
    return self.ensure_sync(self.view_functions[rule.endpoint])(**view_args)  # type: ignore[no-any-return]
  File "d:\Psystem\Databased\DataBase\music\app.py", line 360, in connect_device
    result = database.record_device_connection(data["account"], data["device_id"], data["status"],data["device_name"],data["mac_address"])
  File "d:\Psystem\Databased\DataBase\music\database.py", line 98, in record_device_connection
    elif status=="已断开":
  File "C:\Users\C\.conda\envs\tryagain\lib\site-packages\pymysql\cursors.py", line 148, in execute
    result = self._query(query)
  File "C:\Users\C\.conda\envs\tryagain\lib\site-packages\pymysql\cursors.py", line 310, in _query
    conn.query(q)
  File "C:\Users\C\.conda\envs\tryagain\lib\site-packages\pymysql\connections.py", line 548, in query
    self._affected_rows = self._read_query_result(unbuffered=unbuffered)
  File "C:\Users\C\.conda\envs\tryagain\lib\site-packages\pymysql\connections.py", line 775, in _read_query_result
    result.read()
  File "C:\Users\C\.conda\envs\tryagain\lib\site-packages\pymysql\connections.py", line 1156, in read
    first_packet = self.connection._read_packet()
  File "C:\Users\C\.conda\envs\tryagain\lib\site-packages\pymysql\connections.py", line 725, in _read_packet
    packet.raise_for_error()
  File "C:\Users\C\.conda\envs\tryagain\lib\site-packages\pymysql\protocol.py", line 221, in raise_for_error
    err.raise_mysql_exception(self._data)
  File "C:\Users\C\.conda\envs\tryagain\lib\site-packages\pymysql\err.py", line 143, in raise_mysql_exception
    raise errorclass(errno, errval)
pymysql.err.IntegrityError: (1452, 'Cannot add or update a child row: a foreign key constraint fails (`calmwave_databases`.`device_connection_history`, CONSTRAINT `device_connection_history_ibfk_1` FOREIGN KEY (`account`) REFERENCES `user` (`account`))')
2025-03-31 17:12:29,912 - ERROR: Exception on /device/connect [POST]
Traceback (most recent call last):
  File "C:\Users\C\.conda\envs\tryagain\lib\site-packages\flask\app.py", line 1473, in wsgi_app
    response = self.full_dispatch_request()
  File "C:\Users\C\.conda\envs\tryagain\lib\site-packages\flask\app.py", line 882, in full_dispatch_request
    rv = self.handle_user_exception(e)
  File "C:\Users\C\.conda\envs\tryagain\lib\site-packages\flask_cors\extension.py", line 194, in wrapped_function
    return cors_after_request(app.make_response(f(*args, **kwargs)))
  File "C:\Users\C\.conda\envs\tryagain\lib\site-packages\flask\app.py", line 880, in full_dispatch_request
    rv = self.dispatch_request()
  File "C:\Users\C\.conda\envs\tryagain\lib\site-packages\flask\app.py", line 865, in dispatch_request
    return self.ensure_sync(self.view_functions[rule.endpoint])(**view_args)  # type: ignore[no-any-return]
  File "d:\Psystem\Databased\DataBase\music\app.py", line 360, in connect_device
  File "d:\Psystem\Databased\DataBase\music\database.py", line 98, in record_device_connection
    elif status=="已断开":
  File "C:\Users\C\.conda\envs\tryagain\lib\site-packages\pymysql\cursors.py", line 148, in execute
    result = self._query(query)
  File "C:\Users\C\.conda\envs\tryagain\lib\site-packages\pymysql\cursors.py", line 310, in _query
    conn.query(q)
  File "C:\Users\C\.conda\envs\tryagain\lib\site-packages\pymysql\connections.py", line 548, in query
    self._affected_rows = self._read_query_result(unbuffered=unbuffered)
  File "C:\Users\C\.conda\envs\tryagain\lib\site-packages\pymysql\connections.py", line 775, in _read_query_result
    result.read()
  File "C:\Users\C\.conda\envs\tryagain\lib\site-packages\pymysql\connections.py", line 1156, in read
    first_packet = self.connection._read_packet()
  File "C:\Users\C\.conda\envs\tryagain\lib\site-packages\pymysql\connections.py", line 725, in _read_packet
    packet.raise_for_error()
  File "C:\Users\C\.conda\envs\tryagain\lib\site-packages\pymysql\protocol.py", line 221, in raise_for_error
    err.raise_mysql_exception(self._data)
  File "C:\Users\C\.conda\envs\tryagain\lib\site-packages\pymysql\err.py", line 143, in raise_mysql_exception
    raise errorclass(errno, errval)
pymysql.err.IntegrityError: (1452, 'Cannot add or update a child row: a foreign key constraint fails (`calmwave_databases`.`device_connection_history`, CONSTRAINT `device_connection_history_ibfk_1` FOREIGN KEY (`account`) REFERENCES `user` (`account`))')
2025-03-31 17:58:39,767 - INFO: 临时目录创建于: C:\Users\C\AppData\Local\Temp\music__e_ta6ug
2025-03-31 17:58:39,770 - INFO: 服务启动初始化完成
2025-03-31 18:02:05,736 - ERROR: Exception on /device/connect [POST]
Traceback (most recent call last):
  File "C:\Users\C\.conda\envs\tryagain\lib\site-packages\flask\app.py", line 1473, in wsgi_app
    response = self.full_dispatch_request()
  File "C:\Users\C\.conda\envs\tryagain\lib\site-packages\flask\app.py", line 882, in full_dispatch_request
    rv = self.handle_user_exception(e)
  File "C:\Users\C\.conda\envs\tryagain\lib\site-packages\flask_cors\extension.py", line 194, in wrapped_function
    return cors_after_request(app.make_response(f(*args, **kwargs)))
  File "C:\Users\C\.conda\envs\tryagain\lib\site-packages\flask\app.py", line 880, in full_dispatch_request
    rv = self.dispatch_request()
  File "C:\Users\C\.conda\envs\tryagain\lib\site-packages\flask\app.py", line 865, in dispatch_request
    return self.ensure_sync(self.view_functions[rule.endpoint])(**view_args)  # type: ignore[no-any-return]
  File "d:\Psystem\Databased\DataBase\music\app.py", line 361, in connect_device
    result = database.record_device_connection(data["account"], data["device_id"], data["status"],data["device_name"],data["mac_address"])
  File "d:\Psystem\Databased\DataBase\music\database.py", line 97, in record_device_connection
  File "C:\Users\C\.conda\envs\tryagain\lib\site-packages\pymysql\cursors.py", line 148, in execute
    result = self._query(query)
  File "C:\Users\C\.conda\envs\tryagain\lib\site-packages\pymysql\cursors.py", line 310, in _query
    conn.query(q)
  File "C:\Users\C\.conda\envs\tryagain\lib\site-packages\pymysql\connections.py", line 548, in query
    self._affected_rows = self._read_query_result(unbuffered=unbuffered)
  File "C:\Users\C\.conda\envs\tryagain\lib\site-packages\pymysql\connections.py", line 775, in _read_query_result
    result.read()
  File "C:\Users\C\.conda\envs\tryagain\lib\site-packages\pymysql\connections.py", line 1156, in read
    first_packet = self.connection._read_packet()
  File "C:\Users\C\.conda\envs\tryagain\lib\site-packages\pymysql\connections.py", line 725, in _read_packet
    packet.raise_for_error()
  File "C:\Users\C\.conda\envs\tryagain\lib\site-packages\pymysql\protocol.py", line 221, in raise_for_error
    err.raise_mysql_exception(self._data)
  File "C:\Users\C\.conda\envs\tryagain\lib\site-packages\pymysql\err.py", line 143, in raise_mysql_exception
    raise errorclass(errno, errval)
pymysql.err.IntegrityError: (1452, 'Cannot add or update a child row: a foreign key constraint fails (`calmwave_databases`.`device_connection_history`, CONSTRAINT `device_connection_history_ibfk_1` FOREIGN KEY (`account`) REFERENCES `user` (`account`))')
2025-03-31 18:03:29,474 - INFO: 临时目录创建于: C:\Users\C\AppData\Local\Temp\music_zcg3i1pt
2025-03-31 18:03:29,477 - INFO: 服务启动初始化完成
2025-03-31 18:13:42,866 - INFO: 临时目录创建于: C:\Users\C\AppData\Local\Temp\music_e034aa8a
2025-03-31 18:13:42,869 - INFO: 服务启动初始化完成
2025-03-31 18:13:46,265 - ERROR: Exception on /device/connect [POST]
Traceback (most recent call last):
  File "C:\Users\C\.conda\envs\tryagain\lib\site-packages\flask\app.py", line 1473, in wsgi_app
    response = self.full_dispatch_request()
  File "C:\Users\C\.conda\envs\tryagain\lib\site-packages\flask\app.py", line 882, in full_dispatch_request
    rv = self.handle_user_exception(e)
  File "C:\Users\C\.conda\envs\tryagain\lib\site-packages\flask_cors\extension.py", line 194, in wrapped_function
    return cors_after_request(app.make_response(f(*args, **kwargs)))
  File "C:\Users\C\.conda\envs\tryagain\lib\site-packages\flask\app.py", line 880, in full_dispatch_request
    rv = self.dispatch_request()
  File "C:\Users\C\.conda\envs\tryagain\lib\site-packages\flask\app.py", line 865, in dispatch_request
    return self.ensure_sync(self.view_functions[rule.endpoint])(**view_args)  # type: ignore[no-any-return]
  File "d:\Psystem\Databased\DataBase\music\app.py", line 361, in connect_device
    result = database.record_device_connection(data["account"], data["device_id"], data["status"],data["device_name"],data["mac_address"])
  File "d:\Psystem\Databased\DataBase\music\database.py", line 101, in record_device_connection
    cursor.execute(sql,(account, device_id))
  File "C:\Users\C\.conda\envs\tryagain\lib\site-packages\pymysql\cursors.py", line 148, in execute
    result = self._query(query)
  File "C:\Users\C\.conda\envs\tryagain\lib\site-packages\pymysql\cursors.py", line 310, in _query
    conn.query(q)
  File "C:\Users\C\.conda\envs\tryagain\lib\site-packages\pymysql\connections.py", line 548, in query
    self._affected_rows = self._read_query_result(unbuffered=unbuffered)
  File "C:\Users\C\.conda\envs\tryagain\lib\site-packages\pymysql\connections.py", line 775, in _read_query_result
    result.read()
  File "C:\Users\C\.conda\envs\tryagain\lib\site-packages\pymysql\connections.py", line 1156, in read
    first_packet = self.connection._read_packet()
  File "C:\Users\C\.conda\envs\tryagain\lib\site-packages\pymysql\connections.py", line 725, in _read_packet
    packet.raise_for_error()
  File "C:\Users\C\.conda\envs\tryagain\lib\site-packages\pymysql\protocol.py", line 221, in raise_for_error
    err.raise_mysql_exception(self._data)
  File "C:\Users\C\.conda\envs\tryagain\lib\site-packages\pymysql\err.py", line 143, in raise_mysql_exception
    raise errorclass(errno, errval)
pymysql.err.IntegrityError: (1452, 'Cannot add or update a child row: a foreign key constraint fails (`calmwave_databases`.`device_connection_history`, CONSTRAINT `device_connection_history_ibfk_1` FOREIGN KEY (`account`) REFERENCES `user` (`account`))')
2025-03-31 18:20:38,100 - ERROR: Exception on /device/connect [POST]
Traceback (most recent call last):
  File "C:\Users\C\.conda\envs\tryagain\lib\site-packages\flask\app.py", line 1473, in wsgi_app
    response = self.full_dispatch_request()
  File "C:\Users\C\.conda\envs\tryagain\lib\site-packages\flask\app.py", line 882, in full_dispatch_request
    rv = self.handle_user_exception(e)
  File "C:\Users\C\.conda\envs\tryagain\lib\site-packages\flask_cors\extension.py", line 194, in wrapped_function
    return cors_after_request(app.make_response(f(*args, **kwargs)))
  File "C:\Users\C\.conda\envs\tryagain\lib\site-packages\flask\app.py", line 880, in full_dispatch_request
    rv = self.dispatch_request()
  File "C:\Users\C\.conda\envs\tryagain\lib\site-packages\flask\app.py", line 865, in dispatch_request
    return self.ensure_sync(self.view_functions[rule.endpoint])(**view_args)  # type: ignore[no-any-return]
  File "d:\Psystem\Databased\DataBase\music\app.py", line 361, in connect_device
    result = database.record_device_connection(data["account"], data["device_id"], data["status"],data["device_name"],data["mac_address"])
  File "d:\Psystem\Databased\DataBase\music\database.py", line 101, in record_device_connection
    cursor.execute(sql,(account, device_id))
  File "C:\Users\C\.conda\envs\tryagain\lib\site-packages\pymysql\cursors.py", line 148, in execute
    result = self._query(query)
  File "C:\Users\C\.conda\envs\tryagain\lib\site-packages\pymysql\cursors.py", line 310, in _query
    conn.query(q)
  File "C:\Users\C\.conda\envs\tryagain\lib\site-packages\pymysql\connections.py", line 548, in query
    self._affected_rows = self._read_query_result(unbuffered=unbuffered)
  File "C:\Users\C\.conda\envs\tryagain\lib\site-packages\pymysql\connections.py", line 775, in _read_query_result
    result.read()
  File "C:\Users\C\.conda\envs\tryagain\lib\site-packages\pymysql\connections.py", line 1156, in read
    first_packet = self.connection._read_packet()
  File "C:\Users\C\.conda\envs\tryagain\lib\site-packages\pymysql\connections.py", line 725, in _read_packet
    packet.raise_for_error()
  File "C:\Users\C\.conda\envs\tryagain\lib\site-packages\pymysql\protocol.py", line 221, in raise_for_error
    err.raise_mysql_exception(self._data)
  File "C:\Users\C\.conda\envs\tryagain\lib\site-packages\pymysql\err.py", line 143, in raise_mysql_exception
    raise errorclass(errno, errval)
pymysql.err.IntegrityError: (1452, 'Cannot add or update a child row: a foreign key constraint fails (`calmwave_databases`.`device_connection_history`, CONSTRAINT `device_connection_history_ibfk_1` FOREIGN KEY (`account`) REFERENCES `user` (`account`))')
2025-03-31 18:20:47,667 - INFO: 临时目录创建于: C:\Users\C\AppData\Local\Temp\music_a3jjxvc8
2025-03-31 18:20:47,669 - INFO: 服务启动初始化完成
2025-03-31 18:20:51,043 - ERROR: Exception on /device/connect [POST]
Traceback (most recent call last):
  File "C:\Users\C\.conda\envs\tryagain\lib\site-packages\flask\app.py", line 1473, in wsgi_app
    response = self.full_dispatch_request()
  File "C:\Users\C\.conda\envs\tryagain\lib\site-packages\flask\app.py", line 882, in full_dispatch_request
    rv = self.handle_user_exception(e)
  File "C:\Users\C\.conda\envs\tryagain\lib\site-packages\flask_cors\extension.py", line 194, in wrapped_function
    return cors_after_request(app.make_response(f(*args, **kwargs)))
  File "C:\Users\C\.conda\envs\tryagain\lib\site-packages\flask\app.py", line 880, in full_dispatch_request
    rv = self.dispatch_request()
  File "C:\Users\C\.conda\envs\tryagain\lib\site-packages\flask\app.py", line 865, in dispatch_request
    return self.ensure_sync(self.view_functions[rule.endpoint])(**view_args)  # type: ignore[no-any-return]
  File "d:\Psystem\Databased\DataBase\music\app.py", line 361, in connect_device
    result = database.record_device_connection(data["account"], data["device_id"], data["status"],data["device_name"],data["mac_address"])
  File "d:\Psystem\Databased\DataBase\music\database.py", line 101, in record_device_connection
    cursor.execute(sql,(account, device_id))
  File "C:\Users\C\.conda\envs\tryagain\lib\site-packages\pymysql\cursors.py", line 148, in execute
    result = self._query(query)
  File "C:\Users\C\.conda\envs\tryagain\lib\site-packages\pymysql\cursors.py", line 310, in _query
    conn.query(q)
  File "C:\Users\C\.conda\envs\tryagain\lib\site-packages\pymysql\connections.py", line 548, in query
    self._affected_rows = self._read_query_result(unbuffered=unbuffered)
  File "C:\Users\C\.conda\envs\tryagain\lib\site-packages\pymysql\connections.py", line 775, in _read_query_result
    result.read()
  File "C:\Users\C\.conda\envs\tryagain\lib\site-packages\pymysql\connections.py", line 1156, in read
    first_packet = self.connection._read_packet()
  File "C:\Users\C\.conda\envs\tryagain\lib\site-packages\pymysql\connections.py", line 725, in _read_packet
    packet.raise_for_error()
  File "C:\Users\C\.conda\envs\tryagain\lib\site-packages\pymysql\protocol.py", line 221, in raise_for_error
    err.raise_mysql_exception(self._data)
  File "C:\Users\C\.conda\envs\tryagain\lib\site-packages\pymysql\err.py", line 143, in raise_mysql_exception
    raise errorclass(errno, errval)
pymysql.err.IntegrityError: (1452, 'Cannot add or update a child row: a foreign key constraint fails (`calmwave_databases`.`device_connection_history`, CONSTRAINT `device_connection_history_ibfk_1` FOREIGN KEY (`account`) REFERENCES `user` (`account`))')
2025-03-31 20:42:51,275 - INFO: 临时目录创建于: C:\Users\C\AppData\Local\Temp\music_7sejlm2d
2025-03-31 20:42:51,279 - INFO: 服务启动初始化完成
2025-03-31 20:43:00,932 - ERROR: Exception on /device/connect [POST]
Traceback (most recent call last):
  File "C:\Users\C\.conda\envs\tryagain\lib\site-packages\flask\app.py", line 1473, in wsgi_app
    response = self.full_dispatch_request()
  File "C:\Users\C\.conda\envs\tryagain\lib\site-packages\flask\app.py", line 882, in full_dispatch_request
    rv = self.handle_user_exception(e)
  File "C:\Users\C\.conda\envs\tryagain\lib\site-packages\flask_cors\extension.py", line 194, in wrapped_function
    return cors_after_request(app.make_response(f(*args, **kwargs)))
  File "C:\Users\C\.conda\envs\tryagain\lib\site-packages\flask\app.py", line 880, in full_dispatch_request
    rv = self.dispatch_request()
  File "C:\Users\C\.conda\envs\tryagain\lib\site-packages\flask\app.py", line 865, in dispatch_request
    return self.ensure_sync(self.view_functions[rule.endpoint])(**view_args)  # type: ignore[no-any-return]
  File "d:\Psystem\Databased\DataBase\music\app.py", line 361, in connect_device
    result = database.record_device_connection(data["account"], data["device_id"], data["status"],data["device_name"],data["mac_address"])
  File "d:\Psystem\Databased\DataBase\music\database.py", line 106, in record_device_connection
    raise UserNotFoundError(account)
database.UserNotFoundError: 用户账号 xm1213 不存在
2025-03-31 20:52:44,919 - ERROR: Exception on /device/connect [POST]
Traceback (most recent call last):
  File "C:\Users\C\.conda\envs\tryagain\lib\site-packages\flask\app.py", line 1473, in wsgi_app
    response = self.full_dispatch_request()
  File "C:\Users\C\.conda\envs\tryagain\lib\site-packages\flask\app.py", line 882, in full_dispatch_request
    rv = self.handle_user_exception(e)
  File "C:\Users\C\.conda\envs\tryagain\lib\site-packages\flask_cors\extension.py", line 194, in wrapped_function
    return cors_after_request(app.make_response(f(*args, **kwargs)))
  File "C:\Users\C\.conda\envs\tryagain\lib\site-packages\flask\app.py", line 880, in full_dispatch_request
    rv = self.dispatch_request()
  File "C:\Users\C\.conda\envs\tryagain\lib\site-packages\flask\app.py", line 865, in dispatch_request
    return self.ensure_sync(self.view_functions[rule.endpoint])(**view_args)  # type: ignore[no-any-return]
  File "d:\Psystem\Databased\DataBase\music\app.py", line 361, in connect_device
    result = database.record_device_connection(data["account"], data["device_id"], data["status"],data["device_name"],data["mac_address"])
  File "d:\Psystem\Databased\DataBase\music\database.py", line 106, in record_device_connection
    raise UserNotFoundError(account)
database.UserNotFoundError: 用户账号 xm1213 不存在
2025-04-01 09:18:45,409 - INFO: 临时目录创建于: C:\Users\C\AppData\Local\Temp\music_rl9ybipg
2025-04-01 09:18:45,418 - INFO: 服务启动初始化完成
2025-04-01 09:19:15,435 - ERROR: Exception on /device/connect [POST]
Traceback (most recent call last):
  File "d:\Psystem\Databased\DataBase\music\app.py", line 367, in connect_device
    result = database.record_device_connection(data["account"], data["device_id"], data["status"],data["device_name"],data["mac_address"])
  File "d:\Psystem\Databased\DataBase\music\database.py", line 106, in record_device_connection
    raise UserNotFoundError(account)
database.UserNotFoundError: 用户账号 xm1213 不存在

During handling of the above exception, another exception occurred:

Traceback (most recent call last):
  File "C:\Users\C\.conda\envs\tryagain\lib\site-packages\flask\app.py", line 1473, in wsgi_app
    response = self.full_dispatch_request()
  File "C:\Users\C\.conda\envs\tryagain\lib\site-packages\flask\app.py", line 882, in full_dispatch_request
    rv = self.handle_user_exception(e)
  File "C:\Users\C\.conda\envs\tryagain\lib\site-packages\flask_cors\extension.py", line 194, in wrapped_function
    return cors_after_request(app.make_response(f(*args, **kwargs)))
  File "C:\Users\C\.conda\envs\tryagain\lib\site-packages\flask\app.py", line 880, in full_dispatch_request
    rv = self.dispatch_request()
  File "C:\Users\C\.conda\envs\tryagain\lib\site-packages\flask\app.py", line 865, in dispatch_request
    return self.ensure_sync(self.view_functions[rule.endpoint])(**view_args)  # type: ignore[no-any-return]
  File "d:\Psystem\Databased\DataBase\music\app.py", line 371, in connect_device
    except pymysql.IntegrityError as e:
NameError: name 'pymysql' is not defined
2025-04-01 09:27:00,550 - ERROR: Exception on /device/connect [POST]
Traceback (most recent call last):
  File "d:\Psystem\Databased\DataBase\music\app.py", line 367, in connect_device
    result = database.record_device_connection(data["account"], data["device_id"], data["status"],data["device_name"],data["mac_address"])
  File "d:\Psystem\Databased\DataBase\music\database.py", line 106, in record_device_connection
    raise UserNotFoundError(account)
database.UserNotFoundError: 用户账号 xm1213 不存在

During handling of the above exception, another exception occurred:

Traceback (most recent call last):
  File "C:\Users\C\.conda\envs\tryagain\lib\site-packages\flask\app.py", line 1473, in wsgi_app
    response = self.full_dispatch_request()
  File "C:\Users\C\.conda\envs\tryagain\lib\site-packages\flask\app.py", line 882, in full_dispatch_request
    rv = self.handle_user_exception(e)
  File "C:\Users\C\.conda\envs\tryagain\lib\site-packages\flask_cors\extension.py", line 194, in wrapped_function
    return cors_after_request(app.make_response(f(*args, **kwargs)))
  File "C:\Users\C\.conda\envs\tryagain\lib\site-packages\flask\app.py", line 880, in full_dispatch_request
    rv = self.dispatch_request()
  File "C:\Users\C\.conda\envs\tryagain\lib\site-packages\flask\app.py", line 865, in dispatch_request
    return self.ensure_sync(self.view_functions[rule.endpoint])(**view_args)  # type: ignore[no-any-return]
  File "d:\Psystem\Databased\DataBase\music\app.py", line 371, in connect_device
    except pymysql.IntegrityError as e:
NameError: name 'pymysql' is not defined
2025-04-01 09:29:57,648 - INFO: 临时目录创建于: C:\Users\C\AppData\Local\Temp\music_w4pcc46_
2025-04-01 09:29:57,656 - INFO: 服务启动初始化完成
2025-04-01 09:30:17,350 - ERROR: Exception on /device/connect [POST]
Traceback (most recent call last):
  File "d:\Psystem\Databased\DataBase\music\app.py", line 367, in connect_device
    result = database.record_device_connection(data["account"], data["device_id"], data["status"],data["device_name"],data["mac_address"])
  File "d:\Psystem\Databased\DataBase\music\database.py", line 107, in record_device_connection
    raise UserNotFoundError(account)
database.UserNotFoundError: 用户账号 xm1213 不存在

During handling of the above exception, another exception occurred:

Traceback (most recent call last):
  File "C:\Users\C\.conda\envs\tryagain\lib\site-packages\flask\app.py", line 1473, in wsgi_app
    response = self.full_dispatch_request()
  File "C:\Users\C\.conda\envs\tryagain\lib\site-packages\flask\app.py", line 882, in full_dispatch_request
    rv = self.handle_user_exception(e)
  File "C:\Users\C\.conda\envs\tryagain\lib\site-packages\flask_cors\extension.py", line 194, in wrapped_function
    return cors_after_request(app.make_response(f(*args, **kwargs)))
  File "C:\Users\C\.conda\envs\tryagain\lib\site-packages\flask\app.py", line 880, in full_dispatch_request
    rv = self.dispatch_request()
  File "C:\Users\C\.conda\envs\tryagain\lib\site-packages\flask\app.py", line 865, in dispatch_request
    return self.ensure_sync(self.view_functions[rule.endpoint])(**view_args)  # type: ignore[no-any-return]
  File "d:\Psystem\Databased\DataBase\music\app.py", line 371, in connect_device
    except pymysql.IntegrityError as e:
NameError: name 'pymysql' is not defined
2025-04-01 09:30:49,002 - ERROR: Exception on /device/connect [POST]
Traceback (most recent call last):
  File "d:\Psystem\Databased\DataBase\music\app.py", line 367, in connect_device
    #print(date+" "+account)
  File "d:\Psystem\Databased\DataBase\music\database.py", line 107, in record_device_connection
    raise UserNotFoundError(account)
database.UserNotFoundError: 用户账号 xm1213 不存在

During handling of the above exception, another exception occurred:

Traceback (most recent call last):
  File "C:\Users\C\.conda\envs\tryagain\lib\site-packages\flask\app.py", line 1473, in wsgi_app
    response = self.full_dispatch_request()
  File "C:\Users\C\.conda\envs\tryagain\lib\site-packages\flask\app.py", line 882, in full_dispatch_request
    rv = self.handle_user_exception(e)
  File "C:\Users\C\.conda\envs\tryagain\lib\site-packages\flask_cors\extension.py", line 194, in wrapped_function
    return cors_after_request(app.make_response(f(*args, **kwargs)))
  File "C:\Users\C\.conda\envs\tryagain\lib\site-packages\flask\app.py", line 880, in full_dispatch_request
    rv = self.dispatch_request()
  File "C:\Users\C\.conda\envs\tryagain\lib\site-packages\flask\app.py", line 865, in dispatch_request
    return self.ensure_sync(self.view_functions[rule.endpoint])(**view_args)  # type: ignore[no-any-return]
  File "d:\Psystem\Databased\DataBase\music\app.py", line 371, in connect_device
NameError: name 'pymysql' is not defined
2025-04-01 09:31:03,770 - ERROR: Exception on /device/connect [POST]
Traceback (most recent call last):
  File "d:\Psystem\Databased\DataBase\music\app.py", line 367, in connect_device
  File "d:\Psystem\Databased\DataBase\music\database.py", line 107, in record_device_connection
    raise UserNotFoundError(account)
database.UserNotFoundError: 用户账号 xm1213 不存在

During handling of the above exception, another exception occurred:

Traceback (most recent call last):
  File "C:\Users\C\.conda\envs\tryagain\lib\site-packages\flask\app.py", line 1473, in wsgi_app
    response = self.full_dispatch_request()
  File "C:\Users\C\.conda\envs\tryagain\lib\site-packages\flask\app.py", line 882, in full_dispatch_request
    rv = self.handle_user_exception(e)
  File "C:\Users\C\.conda\envs\tryagain\lib\site-packages\flask_cors\extension.py", line 194, in wrapped_function
    return cors_after_request(app.make_response(f(*args, **kwargs)))
  File "C:\Users\C\.conda\envs\tryagain\lib\site-packages\flask\app.py", line 880, in full_dispatch_request
    rv = self.dispatch_request()
  File "C:\Users\C\.conda\envs\tryagain\lib\site-packages\flask\app.py", line 865, in dispatch_request
    return self.ensure_sync(self.view_functions[rule.endpoint])(**view_args)  # type: ignore[no-any-return]
  File "d:\Psystem\Databased\DataBase\music\app.py", line 371, in connect_device
    result = database.get_pressure_data(account, date)
NameError: name 'pymysql' is not defined
2025-04-01 09:42:17,418 - ERROR: Exception on /device/connect [POST]
Traceback (most recent call last):
  File "d:\Psystem\Databased\DataBase\music\app.py", line 367, in connect_device
  File "d:\Psystem\Databased\DataBase\music\database.py", line 107, in record_device_connection
    raise UserNotFoundError(account)
database.UserNotFoundError: 用户账号 xm1213 不存在

During handling of the above exception, another exception occurred:

Traceback (most recent call last):
  File "C:\Users\C\.conda\envs\tryagain\lib\site-packages\flask\app.py", line 1473, in wsgi_app
    response = self.full_dispatch_request()
  File "C:\Users\C\.conda\envs\tryagain\lib\site-packages\flask\app.py", line 882, in full_dispatch_request
    rv = self.handle_user_exception(e)
  File "C:\Users\C\.conda\envs\tryagain\lib\site-packages\flask_cors\extension.py", line 194, in wrapped_function
    return cors_after_request(app.make_response(f(*args, **kwargs)))
  File "C:\Users\C\.conda\envs\tryagain\lib\site-packages\flask\app.py", line 880, in full_dispatch_request
    rv = self.dispatch_request()
  File "C:\Users\C\.conda\envs\tryagain\lib\site-packages\flask\app.py", line 865, in dispatch_request
    return self.ensure_sync(self.view_functions[rule.endpoint])(**view_args)  # type: ignore[no-any-return]
  File "d:\Psystem\Databased\DataBase\music\app.py", line 371, in connect_device
    result = database.get_pressure_data(account, date)
NameError: name 'pymysql' is not defined
2025-04-01 09:49:59,726 - INFO: 临时目录创建于: C:\Users\C\AppData\Local\Temp\music_46ank2_1
2025-04-01 09:49:59,731 - INFO: 服务启动初始化完成
2025-04-01 09:50:14,895 - ERROR: Exception on /device/connect [POST]
Traceback (most recent call last):
  File "C:\Users\C\.conda\envs\tryagain\lib\site-packages\flask\app.py", line 1473, in wsgi_app
    response = self.full_dispatch_request()
  File "C:\Users\C\.conda\envs\tryagain\lib\site-packages\flask\app.py", line 882, in full_dispatch_request
    rv = self.handle_user_exception(e)
  File "C:\Users\C\.conda\envs\tryagain\lib\site-packages\flask_cors\extension.py", line 194, in wrapped_function
    return cors_after_request(app.make_response(f(*args, **kwargs)))
  File "C:\Users\C\.conda\envs\tryagain\lib\site-packages\flask\app.py", line 880, in full_dispatch_request
    rv = self.dispatch_request()
  File "C:\Users\C\.conda\envs\tryagain\lib\site-packages\flask\app.py", line 865, in dispatch_request
    return self.ensure_sync(self.view_functions[rule.endpoint])(**view_args)  # type: ignore[no-any-return]
  File "d:\Psystem\Databased\DataBase\music\app.py", line 339, in connect_device
    result = database.record_device_connection(data["account"], data["device_id"], data["status"],data["device_name"],data["mac_address"])
  File "d:\Psystem\Databased\DataBase\music\database.py", line 107, in record_device_connection
    raise UserNotFoundError(account)
database.UserNotFoundError: 用户账号 xm1213 不存在
2025-04-01 09:51:54,400 - ERROR: Exception on /device/connect [POST]
Traceback (most recent call last):
  File "C:\Users\C\.conda\envs\tryagain\lib\site-packages\flask\app.py", line 1473, in wsgi_app
    response = self.full_dispatch_request()
  File "C:\Users\C\.conda\envs\tryagain\lib\site-packages\flask\app.py", line 882, in full_dispatch_request
    rv = self.handle_user_exception(e)
  File "C:\Users\C\.conda\envs\tryagain\lib\site-packages\flask_cors\extension.py", line 194, in wrapped_function
    return cors_after_request(app.make_response(f(*args, **kwargs)))
  File "C:\Users\C\.conda\envs\tryagain\lib\site-packages\flask\app.py", line 880, in full_dispatch_request
    rv = self.dispatch_request()
  File "C:\Users\C\.conda\envs\tryagain\lib\site-packages\flask\app.py", line 865, in dispatch_request
    return self.ensure_sync(self.view_functions[rule.endpoint])(**view_args)  # type: ignore[no-any-return]
  File "d:\Psystem\Databased\DataBase\music\app.py", line 339, in connect_device
    result = database.record_device_connection(data["account"], data["device_id"], data["status"],data["device_name"],data["mac_address"])
  File "d:\Psystem\Databased\DataBase\music\database.py", line 107, in record_device_connection
    raise UserNotFoundError(account)
database.UserNotFoundError: 用户账号 xm1213 不存在
2025-04-01 09:52:08,412 - INFO: 临时目录创建于: C:\Users\C\AppData\Local\Temp\music_yxm8bcdy
2025-04-01 09:52:08,421 - INFO: 服务启动初始化完成
2025-04-01 09:52:16,839 - ERROR: Exception on /device/connect [POST]
Traceback (most recent call last):
  File "C:\Users\C\.conda\envs\tryagain\lib\site-packages\flask\app.py", line 1473, in wsgi_app
    response = self.full_dispatch_request()
  File "C:\Users\C\.conda\envs\tryagain\lib\site-packages\flask\app.py", line 882, in full_dispatch_request
    rv = self.handle_user_exception(e)
  File "C:\Users\C\.conda\envs\tryagain\lib\site-packages\flask_cors\extension.py", line 194, in wrapped_function
    return cors_after_request(app.make_response(f(*args, **kwargs)))
  File "C:\Users\C\.conda\envs\tryagain\lib\site-packages\flask\app.py", line 880, in full_dispatch_request
    rv = self.dispatch_request()
  File "C:\Users\C\.conda\envs\tryagain\lib\site-packages\flask\app.py", line 865, in dispatch_request
    return self.ensure_sync(self.view_functions[rule.endpoint])(**view_args)  # type: ignore[no-any-return]
  File "d:\Psystem\Databased\DataBase\music\app.py", line 339, in connect_device
    result = database.record_device_connection(data["account"], data["device_id"], data["status"],data["device_name"],data["mac_address"])
  File "d:\Psystem\Databased\DataBase\music\database.py", line 107, in record_device_connection
    raise UserNotFoundError(account)
database.UserNotFoundError: 用户账号 xm1213 不存在
2025-04-01 09:53:25,476 - ERROR: Exception on /device/connect [POST]
Traceback (most recent call last):
  File "C:\Users\C\.conda\envs\tryagain\lib\site-packages\flask\app.py", line 1473, in wsgi_app
    response = self.full_dispatch_request()
  File "C:\Users\C\.conda\envs\tryagain\lib\site-packages\flask\app.py", line 882, in full_dispatch_request
    rv = self.handle_user_exception(e)
  File "C:\Users\C\.conda\envs\tryagain\lib\site-packages\flask_cors\extension.py", line 194, in wrapped_function
    return cors_after_request(app.make_response(f(*args, **kwargs)))
  File "C:\Users\C\.conda\envs\tryagain\lib\site-packages\flask\app.py", line 880, in full_dispatch_request
    rv = self.dispatch_request()
  File "C:\Users\C\.conda\envs\tryagain\lib\site-packages\flask\app.py", line 865, in dispatch_request
    return self.ensure_sync(self.view_functions[rule.endpoint])(**view_args)  # type: ignore[no-any-return]
  File "d:\Psystem\Databased\DataBase\music\app.py", line 339, in connect_device
    result = database.record_device_connection(data["account"], data["device_id"], data["status"],data["device_name"],data["mac_address"])
  File "d:\Psystem\Databased\DataBase\music\database.py", line 107, in record_device_connection
    raise UserNotFoundError(account)
database.UserNotFoundError: 用户账号 xm1213 不存在
2025-04-01 09:54:01,150 - ERROR: Exception on /device/connect [POST]
Traceback (most recent call last):
  File "C:\Users\C\.conda\envs\tryagain\lib\site-packages\flask\app.py", line 1473, in wsgi_app
    response = self.full_dispatch_request()
  File "C:\Users\C\.conda\envs\tryagain\lib\site-packages\flask\app.py", line 882, in full_dispatch_request
    rv = self.handle_user_exception(e)
  File "C:\Users\C\.conda\envs\tryagain\lib\site-packages\flask_cors\extension.py", line 194, in wrapped_function
    return cors_after_request(app.make_response(f(*args, **kwargs)))
  File "C:\Users\C\.conda\envs\tryagain\lib\site-packages\flask\app.py", line 880, in full_dispatch_request
    rv = self.dispatch_request()
  File "C:\Users\C\.conda\envs\tryagain\lib\site-packages\flask\app.py", line 865, in dispatch_request
    return self.ensure_sync(self.view_functions[rule.endpoint])(**view_args)  # type: ignore[no-any-return]
  File "d:\Psystem\Databased\DataBase\music\app.py", line 339, in connect_device
    result = database.record_device_connection(data["account"], data["device_id"], data["status"],data["device_name"],data["mac_address"])
  File "d:\Psystem\Databased\DataBase\music\database.py", line 107, in record_device_connection
    raise UserNotFoundError(account)
database.UserNotFoundError: 用户账号 xm1213 不存在
2025-04-01 09:54:25,894 - INFO: 临时目录创建于: C:\Users\C\AppData\Local\Temp\music_vggbwgfx
2025-04-01 09:54:25,900 - INFO: 服务启动初始化完成
2025-04-01 09:54:34,443 - ERROR: Exception on /device/connect [POST]
Traceback (most recent call last):
  File "C:\Users\C\.conda\envs\tryagain\lib\site-packages\flask\app.py", line 1473, in wsgi_app
    response = self.full_dispatch_request()
  File "C:\Users\C\.conda\envs\tryagain\lib\site-packages\flask\app.py", line 882, in full_dispatch_request
    rv = self.handle_user_exception(e)
  File "C:\Users\C\.conda\envs\tryagain\lib\site-packages\flask_cors\extension.py", line 194, in wrapped_function
    return cors_after_request(app.make_response(f(*args, **kwargs)))
  File "C:\Users\C\.conda\envs\tryagain\lib\site-packages\flask\app.py", line 880, in full_dispatch_request
    rv = self.dispatch_request()
  File "C:\Users\C\.conda\envs\tryagain\lib\site-packages\flask\app.py", line 865, in dispatch_request
    return self.ensure_sync(self.view_functions[rule.endpoint])(**view_args)  # type: ignore[no-any-return]
  File "d:\Psystem\Databased\DataBase\music\app.py", line 339, in connect_device
    result = database.record_device_connection(data["account"], data["device_id"], data["status"],data["device_name"],data["mac_address"])
  File "d:\Psystem\Databased\DataBase\music\database.py", line 107, in record_device_connection
    raise UserNotFoundError(account)
database.UserNotFoundError: User xm1213 is entry
2025-04-01 10:15:45,792 - ERROR: Exception on /device/connect [POST]
Traceback (most recent call last):
  File "C:\Users\C\.conda\envs\tryagain\lib\site-packages\flask\app.py", line 1473, in wsgi_app
    response = self.full_dispatch_request()
  File "C:\Users\C\.conda\envs\tryagain\lib\site-packages\flask\app.py", line 882, in full_dispatch_request
    rv = self.handle_user_exception(e)
  File "C:\Users\C\.conda\envs\tryagain\lib\site-packages\flask_cors\extension.py", line 194, in wrapped_function
    return cors_after_request(app.make_response(f(*args, **kwargs)))
  File "C:\Users\C\.conda\envs\tryagain\lib\site-packages\flask\app.py", line 880, in full_dispatch_request
    rv = self.dispatch_request()
  File "C:\Users\C\.conda\envs\tryagain\lib\site-packages\flask\app.py", line 865, in dispatch_request
    return self.ensure_sync(self.view_functions[rule.endpoint])(**view_args)  # type: ignore[no-any-return]
  File "d:\Psystem\Databased\DataBase\music\app.py", line 339, in connect_device
    result = database.record_device_connection(
  File "d:\Psystem\Databased\DataBase\music\database.py", line 107, in record_device_connection
    sql="""INSERT INTO device_connection_history (account, device_id, connection_time, connection_status)
database.UserNotFoundError: User xm1213 is entry
2025-04-01 10:15:49,637 - INFO: 临时目录创建于: C:\Users\C\AppData\Local\Temp\music_ha0cy3yg
2025-04-01 10:15:49,640 - INFO: 服务启动初始化完成
2025-04-01 10:23:56,672 - INFO: 临时目录创建于: C:\Users\C\AppData\Local\Temp\music_a8xyx4qm
2025-04-01 10:23:56,676 - INFO: 服务启动初始化完成
2025-04-01 14:25:22,836 - INFO: 临时目录创建于: C:\Users\C\AppData\Local\Temp\music_u4jv96r5
2025-04-01 14:25:22,848 - INFO: 服务启动初始化完成
2025-04-01 15:01:22,059 - INFO: 临时目录创建于: C:\Users\C\AppData\Local\Temp\music_kwlg55ka
2025-04-01 15:01:22,062 - INFO: 服务启动初始化完成
2025-04-01 15:02:09,248 - ERROR: Exception on /login [POST]
Traceback (most recent call last):
  File "C:\Users\C\.conda\envs\tryagain\lib\site-packages\flask\app.py", line 1473, in wsgi_app
    response = self.full_dispatch_request()
  File "C:\Users\C\.conda\envs\tryagain\lib\site-packages\flask\app.py", line 882, in full_dispatch_request
    rv = self.handle_user_exception(e)
  File "C:\Users\C\.conda\envs\tryagain\lib\site-packages\flask_cors\extension.py", line 194, in wrapped_function
    return cors_after_request(app.make_response(f(*args, **kwargs)))
  File "C:\Users\C\.conda\envs\tryagain\lib\site-packages\flask\app.py", line 880, in full_dispatch_request
    rv = self.dispatch_request()
  File "C:\Users\C\.conda\envs\tryagain\lib\site-packages\flask\app.py", line 865, in dispatch_request
    return self.ensure_sync(self.view_functions[rule.endpoint])(**view_args)  # type: ignore[no-any-return]
  File "d:\Psystem\Databased\DataBase\music\app.py", line 325, in login
    result = database.login_with_account_password(account, password)
  File "d:\Psystem\Databased\DataBase\music\database.py", line 67, in login_with_account_password
    if check_password_hash(user['password'], password):
TypeError: tuple indices must be integers or slices, not str
2025-04-01 15:02:42,214 - ERROR: Exception on /login [POST]
Traceback (most recent call last):
  File "C:\Users\C\.conda\envs\tryagain\lib\site-packages\flask\app.py", line 1473, in wsgi_app
    response = self.full_dispatch_request()
  File "C:\Users\C\.conda\envs\tryagain\lib\site-packages\flask\app.py", line 882, in full_dispatch_request
    rv = self.handle_user_exception(e)
  File "C:\Users\C\.conda\envs\tryagain\lib\site-packages\flask_cors\extension.py", line 194, in wrapped_function
    return cors_after_request(app.make_response(f(*args, **kwargs)))
  File "C:\Users\C\.conda\envs\tryagain\lib\site-packages\flask\app.py", line 880, in full_dispatch_request
    rv = self.dispatch_request()
  File "C:\Users\C\.conda\envs\tryagain\lib\site-packages\flask\app.py", line 865, in dispatch_request
    return self.ensure_sync(self.view_functions[rule.endpoint])(**view_args)  # type: ignore[no-any-return]
  File "d:\Psystem\Databased\DataBase\music\app.py", line 325, in login
    result = database.login_with_account_password(account, password)
  File "d:\Psystem\Databased\DataBase\music\database.py", line 67, in login_with_account_password
    if check_password_hash(user['password'], password):
TypeError: tuple indices must be integers or slices, not str
2025-04-01 15:04:33,248 - ERROR: Exception on /login [POST]
Traceback (most recent call last):
  File "C:\Users\C\.conda\envs\tryagain\lib\site-packages\flask\app.py", line 1473, in wsgi_app
    response = self.full_dispatch_request()
  File "C:\Users\C\.conda\envs\tryagain\lib\site-packages\flask\app.py", line 882, in full_dispatch_request
    rv = self.handle_user_exception(e)
  File "C:\Users\C\.conda\envs\tryagain\lib\site-packages\flask_cors\extension.py", line 194, in wrapped_function
    return cors_after_request(app.make_response(f(*args, **kwargs)))
  File "C:\Users\C\.conda\envs\tryagain\lib\site-packages\flask\app.py", line 880, in full_dispatch_request
    rv = self.dispatch_request()
  File "C:\Users\C\.conda\envs\tryagain\lib\site-packages\flask\app.py", line 865, in dispatch_request
    return self.ensure_sync(self.view_functions[rule.endpoint])(**view_args)  # type: ignore[no-any-return]
  File "d:\Psystem\Databased\DataBase\music\app.py", line 325, in login
    result = database.login_with_account_password(account, password)
  File "d:\Psystem\Databased\DataBase\music\database.py", line 67, in login_with_account_password
    if check_password_hash(user['password'], password):
TypeError: tuple indices must be integers or slices, not str
2025-04-01 15:06:05,710 - ERROR: Exception on /login [POST]
Traceback (most recent call last):
  File "C:\Users\C\.conda\envs\tryagain\lib\site-packages\flask\app.py", line 1473, in wsgi_app
    response = self.full_dispatch_request()
  File "C:\Users\C\.conda\envs\tryagain\lib\site-packages\flask\app.py", line 882, in full_dispatch_request
    rv = self.handle_user_exception(e)
  File "C:\Users\C\.conda\envs\tryagain\lib\site-packages\flask_cors\extension.py", line 194, in wrapped_function
    return cors_after_request(app.make_response(f(*args, **kwargs)))
  File "C:\Users\C\.conda\envs\tryagain\lib\site-packages\flask\app.py", line 880, in full_dispatch_request
    rv = self.dispatch_request()
  File "C:\Users\C\.conda\envs\tryagain\lib\site-packages\flask\app.py", line 865, in dispatch_request
    return self.ensure_sync(self.view_functions[rule.endpoint])(**view_args)  # type: ignore[no-any-return]
  File "d:\Psystem\Databased\DataBase\music\app.py", line 325, in login
    result = database.login_with_account_password(account, password)
  File "d:\Psystem\Databased\DataBase\music\database.py", line 67, in login_with_account_password
    if check_password_hash(user['password'], password):
TypeError: tuple indices must be integers or slices, not str
2025-04-01 15:07:08,806 - ERROR: Exception on /login [POST]
Traceback (most recent call last):
  File "C:\Users\C\.conda\envs\tryagain\lib\site-packages\flask\app.py", line 1473, in wsgi_app
    response = self.full_dispatch_request()
  File "C:\Users\C\.conda\envs\tryagain\lib\site-packages\flask\app.py", line 882, in full_dispatch_request
    rv = self.handle_user_exception(e)
  File "C:\Users\C\.conda\envs\tryagain\lib\site-packages\flask_cors\extension.py", line 194, in wrapped_function
    return cors_after_request(app.make_response(f(*args, **kwargs)))
  File "C:\Users\C\.conda\envs\tryagain\lib\site-packages\flask\app.py", line 880, in full_dispatch_request
    rv = self.dispatch_request()
  File "C:\Users\C\.conda\envs\tryagain\lib\site-packages\flask\app.py", line 865, in dispatch_request
    return self.ensure_sync(self.view_functions[rule.endpoint])(**view_args)  # type: ignore[no-any-return]
  File "d:\Psystem\Databased\DataBase\music\app.py", line 325, in login
    result = database.login_with_account_password(account, password)
  File "d:\Psystem\Databased\DataBase\music\database.py", line 67, in login_with_account_password
    if check_password_hash(user['password'], password):
TypeError: tuple indices must be integers or slices, not str
2025-04-01 15:07:25,083 - ERROR: Exception on /login [POST]
Traceback (most recent call last):
  File "C:\Users\C\.conda\envs\tryagain\lib\site-packages\flask\app.py", line 1473, in wsgi_app
    response = self.full_dispatch_request()
  File "C:\Users\C\.conda\envs\tryagain\lib\site-packages\flask\app.py", line 882, in full_dispatch_request
    rv = self.handle_user_exception(e)
  File "C:\Users\C\.conda\envs\tryagain\lib\site-packages\flask_cors\extension.py", line 194, in wrapped_function
    return cors_after_request(app.make_response(f(*args, **kwargs)))
  File "C:\Users\C\.conda\envs\tryagain\lib\site-packages\flask\app.py", line 880, in full_dispatch_request
    rv = self.dispatch_request()
  File "C:\Users\C\.conda\envs\tryagain\lib\site-packages\flask\app.py", line 865, in dispatch_request
    return self.ensure_sync(self.view_functions[rule.endpoint])(**view_args)  # type: ignore[no-any-return]
  File "d:\Psystem\Databased\DataBase\music\app.py", line 325, in login
    result = database.login_with_account_password(account, password)
  File "d:\Psystem\Databased\DataBase\music\database.py", line 67, in login_with_account_password
    if check_password_hash(user['password'], password):
TypeError: tuple indices must be integers or slices, not str
2025-04-01 15:07:35,925 - ERROR: Exception on /login [POST]
Traceback (most recent call last):
  File "C:\Users\C\.conda\envs\tryagain\lib\site-packages\flask\app.py", line 1473, in wsgi_app
    response = self.full_dispatch_request()
  File "C:\Users\C\.conda\envs\tryagain\lib\site-packages\flask\app.py", line 882, in full_dispatch_request
    rv = self.handle_user_exception(e)
  File "C:\Users\C\.conda\envs\tryagain\lib\site-packages\flask_cors\extension.py", line 194, in wrapped_function
    return cors_after_request(app.make_response(f(*args, **kwargs)))
  File "C:\Users\C\.conda\envs\tryagain\lib\site-packages\flask\app.py", line 880, in full_dispatch_request
    rv = self.dispatch_request()
  File "C:\Users\C\.conda\envs\tryagain\lib\site-packages\flask\app.py", line 865, in dispatch_request
    return self.ensure_sync(self.view_functions[rule.endpoint])(**view_args)  # type: ignore[no-any-return]
  File "d:\Psystem\Databased\DataBase\music\app.py", line 325, in login
    result = database.login_with_account_password(account, password)
  File "d:\Psystem\Databased\DataBase\music\database.py", line 67, in login_with_account_password
    if check_password_hash(user['password'], password):
TypeError: tuple indices must be integers or slices, not str
2025-04-01 15:08:37,267 - ERROR: Exception on /login [POST]
Traceback (most recent call last):
  File "C:\Users\C\.conda\envs\tryagain\lib\site-packages\flask\app.py", line 1473, in wsgi_app
    response = self.full_dispatch_request()
  File "C:\Users\C\.conda\envs\tryagain\lib\site-packages\flask\app.py", line 882, in full_dispatch_request
    rv = self.handle_user_exception(e)
  File "C:\Users\C\.conda\envs\tryagain\lib\site-packages\flask_cors\extension.py", line 194, in wrapped_function
    return cors_after_request(app.make_response(f(*args, **kwargs)))
  File "C:\Users\C\.conda\envs\tryagain\lib\site-packages\flask\app.py", line 880, in full_dispatch_request
    rv = self.dispatch_request()
  File "C:\Users\C\.conda\envs\tryagain\lib\site-packages\flask\app.py", line 865, in dispatch_request
    return self.ensure_sync(self.view_functions[rule.endpoint])(**view_args)  # type: ignore[no-any-return]
  File "d:\Psystem\Databased\DataBase\music\app.py", line 325, in login
    result = database.login_with_account_password(account, password)
  File "d:\Psystem\Databased\DataBase\music\database.py", line 67, in login_with_account_password
    if check_password_hash(user['password'], password):
TypeError: tuple indices must be integers or slices, not str
2025-04-01 15:09:10,584 - INFO: 临时目录创建于: C:\Users\C\AppData\Local\Temp\music_16cxobh4
2025-04-01 15:09:10,592 - INFO: 服务启动初始化完成
2025-04-01 15:13:55,878 - INFO: 临时目录创建于: C:\Users\C\AppData\Local\Temp\music_im90g627
2025-04-01 15:13:55,878 - INFO: 服务启动初始化完成
2025-04-01 15:14:27,244 - INFO: 临时目录创建于: C:\Users\C\AppData\Local\Temp\music_znkikjbf
2025-04-01 15:14:27,248 - INFO: 服务启动初始化完成
2025-04-01 16:08:08,266 - INFO: 临时目录创建于: C:\Users\C\AppData\Local\Temp\music_ylu7_ckt
2025-04-01 16:08:08,269 - INFO: 服务启动初始化完成
2025-04-01 16:10:10,018 - INFO: 临时目录创建于: C:\Users\C\AppData\Local\Temp\music_0bwp92it
2025-04-01 16:10:10,022 - INFO: 服务启动初始化完成
2025-04-01 16:10:17,597 - ERROR: Exception on /login [POST]
Traceback (most recent call last):
  File "C:\Users\C\.conda\envs\tryagain\lib\site-packages\flask\app.py", line 1473, in wsgi_app
    response = self.full_dispatch_request()
  File "C:\Users\C\.conda\envs\tryagain\lib\site-packages\flask\app.py", line 882, in full_dispatch_request
    rv = self.handle_user_exception(e)
  File "C:\Users\C\.conda\envs\tryagain\lib\site-packages\flask_cors\extension.py", line 194, in wrapped_function
    return cors_after_request(app.make_response(f(*args, **kwargs)))
  File "C:\Users\C\.conda\envs\tryagain\lib\site-packages\flask\app.py", line 880, in full_dispatch_request
    rv = self.dispatch_request()
  File "C:\Users\C\.conda\envs\tryagain\lib\site-packages\flask\app.py", line 865, in dispatch_request
    return self.ensure_sync(self.view_functions[rule.endpoint])(**view_args)  # type: ignore[no-any-return]
  File "d:\Psystem\Databased\DataBase\music\app.py", line 325, in login
    result = database.login_with_account_password(account, password)
  File "d:\Psystem\Databased\DataBase\music\database.py", line 70, in login_with_account_password
    if check_password(user['password'], password):
  File "d:\Psystem\Databased\DataBase\music\database.py", line 145, in check_password
    return bcrypt.checkpw(provided_password.encode('utf-8'), stored_password.encode('utf-8'))
ValueError: Invalid salt
2025-04-01 16:13:08,964 - ERROR: Exception on /login [POST]
Traceback (most recent call last):
  File "C:\Users\C\.conda\envs\tryagain\lib\site-packages\flask\app.py", line 1473, in wsgi_app
    response = self.full_dispatch_request()
  File "C:\Users\C\.conda\envs\tryagain\lib\site-packages\flask\app.py", line 882, in full_dispatch_request
    rv = self.handle_user_exception(e)
  File "C:\Users\C\.conda\envs\tryagain\lib\site-packages\flask_cors\extension.py", line 194, in wrapped_function
    return cors_after_request(app.make_response(f(*args, **kwargs)))
  File "C:\Users\C\.conda\envs\tryagain\lib\site-packages\flask\app.py", line 880, in full_dispatch_request
    rv = self.dispatch_request()
  File "C:\Users\C\.conda\envs\tryagain\lib\site-packages\flask\app.py", line 865, in dispatch_request
    return self.ensure_sync(self.view_functions[rule.endpoint])(**view_args)  # type: ignore[no-any-return]
  File "d:\Psystem\Databased\DataBase\music\app.py", line 325, in login
    result = database.login_with_account_password(account, password)
  File "d:\Psystem\Databased\DataBase\music\database.py", line 70, in login_with_account_password
    if check_password(user['password'], password):
  File "d:\Psystem\Databased\DataBase\music\database.py", line 145, in check_password
    return bcrypt.checkpw(provided_password.encode('utf-8'), stored_password.encode('utf-8'))
ValueError: Invalid salt
2025-04-01 16:18:01,420 - INFO: 临时目录创建于: C:\Users\C\AppData\Local\Temp\music_kv5la3mt
2025-04-01 16:18:01,422 - INFO: 服务启动初始化完成
2025-04-01 16:18:04,067 - ERROR: Exception on /login [POST]
Traceback (most recent call last):
  File "C:\Users\C\.conda\envs\tryagain\lib\site-packages\flask\app.py", line 1473, in wsgi_app
    response = self.full_dispatch_request()
  File "C:\Users\C\.conda\envs\tryagain\lib\site-packages\flask\app.py", line 882, in full_dispatch_request
    rv = self.handle_user_exception(e)
  File "C:\Users\C\.conda\envs\tryagain\lib\site-packages\flask_cors\extension.py", line 194, in wrapped_function
    return cors_after_request(app.make_response(f(*args, **kwargs)))
  File "C:\Users\C\.conda\envs\tryagain\lib\site-packages\flask\app.py", line 880, in full_dispatch_request
    rv = self.dispatch_request()
  File "C:\Users\C\.conda\envs\tryagain\lib\site-packages\flask\app.py", line 865, in dispatch_request
    return self.ensure_sync(self.view_functions[rule.endpoint])(**view_args)  # type: ignore[no-any-return]
  File "d:\Psystem\Databased\DataBase\music\app.py", line 325, in login
    result = database.login_with_account_password(account, password)
  File "d:\Psystem\Databased\DataBase\music\database.py", line 70, in login_with_account_password
    if check_password(user['password'], password):
  File "d:\Psystem\Databased\DataBase\music\database.py", line 145, in check_password
    return bcrypt.checkpw(provided_password.encode('utf-8'), stored_password.encode('utf-8'))
ValueError: Invalid salt
2025-04-01 16:18:20,078 - ERROR: Exception on /login [POST]
Traceback (most recent call last):
  File "C:\Users\C\.conda\envs\tryagain\lib\site-packages\flask\app.py", line 1473, in wsgi_app
    response = self.full_dispatch_request()
  File "C:\Users\C\.conda\envs\tryagain\lib\site-packages\flask\app.py", line 882, in full_dispatch_request
    rv = self.handle_user_exception(e)
  File "C:\Users\C\.conda\envs\tryagain\lib\site-packages\flask_cors\extension.py", line 194, in wrapped_function
    return cors_after_request(app.make_response(f(*args, **kwargs)))
  File "C:\Users\C\.conda\envs\tryagain\lib\site-packages\flask\app.py", line 880, in full_dispatch_request
    rv = self.dispatch_request()
  File "C:\Users\C\.conda\envs\tryagain\lib\site-packages\flask\app.py", line 865, in dispatch_request
    return self.ensure_sync(self.view_functions[rule.endpoint])(**view_args)  # type: ignore[no-any-return]
  File "d:\Psystem\Databased\DataBase\music\app.py", line 325, in login
    result = database.login_with_account_password(account, password)
  File "d:\Psystem\Databased\DataBase\music\database.py", line 70, in login_with_account_password
    if check_password(user['password'], password):
  File "d:\Psystem\Databased\DataBase\music\database.py", line 145, in check_password
    return bcrypt.checkpw(provided_password.encode('utf-8'), stored_password.encode('utf-8'))
ValueError: Invalid salt
2025-04-01 16:19:00,853 - INFO: 临时目录创建于: C:\Users\C\AppData\Local\Temp\music_r02ujihr
2025-04-01 16:19:00,855 - INFO: 服务启动初始化完成
2025-04-01 16:19:02,718 - ERROR: Exception on /login [POST]
Traceback (most recent call last):
  File "C:\Users\C\.conda\envs\tryagain\lib\site-packages\flask\app.py", line 1473, in wsgi_app
    response = self.full_dispatch_request()
  File "C:\Users\C\.conda\envs\tryagain\lib\site-packages\flask\app.py", line 882, in full_dispatch_request
    rv = self.handle_user_exception(e)
  File "C:\Users\C\.conda\envs\tryagain\lib\site-packages\flask_cors\extension.py", line 194, in wrapped_function
    return cors_after_request(app.make_response(f(*args, **kwargs)))
  File "C:\Users\C\.conda\envs\tryagain\lib\site-packages\flask\app.py", line 880, in full_dispatch_request
    rv = self.dispatch_request()
  File "C:\Users\C\.conda\envs\tryagain\lib\site-packages\flask\app.py", line 865, in dispatch_request
    return self.ensure_sync(self.view_functions[rule.endpoint])(**view_args)  # type: ignore[no-any-return]
  File "d:\Psystem\Databased\DataBase\music\app.py", line 325, in login
    result = database.login_with_account_password(account, password)
  File "d:\Psystem\Databased\DataBase\music\database.py", line 71, in login_with_account_password
    if check_password(user['password'], password):
  File "d:\Psystem\Databased\DataBase\music\database.py", line 146, in check_password
    return bcrypt.checkpw(provided_password.encode('utf-8'), stored_password.encode('utf-8'))
ValueError: Invalid salt
2025-04-01 16:21:47,923 - INFO: 临时目录创建于: C:\Users\C\AppData\Local\Temp\music_2ie112h5
2025-04-01 16:21:47,926 - INFO: 服务启动初始化完成
2025-04-01 16:21:50,185 - ERROR: Exception on /login [POST]
Traceback (most recent call last):
  File "C:\Users\C\.conda\envs\tryagain\lib\site-packages\flask\app.py", line 1473, in wsgi_app
    response = self.full_dispatch_request()
  File "C:\Users\C\.conda\envs\tryagain\lib\site-packages\flask\app.py", line 882, in full_dispatch_request
    rv = self.handle_user_exception(e)
  File "C:\Users\C\.conda\envs\tryagain\lib\site-packages\flask_cors\extension.py", line 194, in wrapped_function
    return cors_after_request(app.make_response(f(*args, **kwargs)))
  File "C:\Users\C\.conda\envs\tryagain\lib\site-packages\flask\app.py", line 880, in full_dispatch_request
    rv = self.dispatch_request()
  File "C:\Users\C\.conda\envs\tryagain\lib\site-packages\flask\app.py", line 865, in dispatch_request
    return self.ensure_sync(self.view_functions[rule.endpoint])(**view_args)  # type: ignore[no-any-return]
  File "d:\Psystem\Databased\DataBase\music\app.py", line 325, in login
    result = database.login_with_account_password(account, password)
  File "d:\Psystem\Databased\DataBase\music\database.py", line 72, in login_with_account_password
    if check_password(user['password'], password):
  File "d:\Psystem\Databased\DataBase\music\database.py", line 147, in check_password
    return bcrypt.checkpw(provided_password.encode('utf-8'), stored_password.encode('utf-8'))
ValueError: Invalid salt
2025-04-01 16:23:18,701 - INFO: 临时目录创建于: C:\Users\C\AppData\Local\Temp\music_vxzasf2l
2025-04-01 16:23:18,704 - INFO: 服务启动初始化完成
2025-04-01 16:23:25,191 - ERROR: Exception on /login [POST]
Traceback (most recent call last):
  File "C:\Users\C\.conda\envs\tryagain\lib\site-packages\flask\app.py", line 1473, in wsgi_app
    response = self.full_dispatch_request()
  File "C:\Users\C\.conda\envs\tryagain\lib\site-packages\flask\app.py", line 882, in full_dispatch_request
    rv = self.handle_user_exception(e)
  File "C:\Users\C\.conda\envs\tryagain\lib\site-packages\flask_cors\extension.py", line 194, in wrapped_function
    return cors_after_request(app.make_response(f(*args, **kwargs)))
  File "C:\Users\C\.conda\envs\tryagain\lib\site-packages\flask\app.py", line 880, in full_dispatch_request
    rv = self.dispatch_request()
  File "C:\Users\C\.conda\envs\tryagain\lib\site-packages\flask\app.py", line 865, in dispatch_request
    return self.ensure_sync(self.view_functions[rule.endpoint])(**view_args)  # type: ignore[no-any-return]
  File "d:\Psystem\Databased\DataBase\music\app.py", line 325, in login
    result = database.login_with_account_password(account, password)
  File "d:\Psystem\Databased\DataBase\music\database.py", line 73, in login_with_account_password
    if check_password(user['password'], password):
  File "d:\Psystem\Databased\DataBase\music\database.py", line 148, in check_password
    return bcrypt.checkpw(provided_password.encode('utf-8'), stored_password.encode('utf-8'))
ValueError: Invalid salt
2025-04-01 16:27:51,415 - INFO: 临时目录创建于: C:\Users\C\AppData\Local\Temp\music_cxyavhx4
2025-04-01 16:27:51,417 - INFO: 服务启动初始化完成
2025-04-01 16:28:13,723 - ERROR: Exception on /login [POST]
Traceback (most recent call last):
  File "C:\Users\C\.conda\envs\tryagain\lib\site-packages\flask\app.py", line 1473, in wsgi_app
    response = self.full_dispatch_request()
  File "C:\Users\C\.conda\envs\tryagain\lib\site-packages\flask\app.py", line 882, in full_dispatch_request
    rv = self.handle_user_exception(e)
  File "C:\Users\C\.conda\envs\tryagain\lib\site-packages\flask_cors\extension.py", line 194, in wrapped_function
    return cors_after_request(app.make_response(f(*args, **kwargs)))
  File "C:\Users\C\.conda\envs\tryagain\lib\site-packages\flask\app.py", line 880, in full_dispatch_request
    rv = self.dispatch_request()
  File "C:\Users\C\.conda\envs\tryagain\lib\site-packages\flask\app.py", line 865, in dispatch_request
    return self.ensure_sync(self.view_functions[rule.endpoint])(**view_args)  # type: ignore[no-any-return]
  File "d:\Psystem\Databased\DataBase\music\app.py", line 325, in login
    result = database.login_with_account_password(account, password)
  File "d:\Psystem\Databased\DataBase\music\database.py", line 74, in login_with_account_password
    return {"status": "success", "message": "登录成功", "user_id": user['id'], "username": user['username']}
KeyError: 'id'
2025-04-01 16:28:22,483 - ERROR: Exception on /login [POST]
Traceback (most recent call last):
  File "C:\Users\C\.conda\envs\tryagain\lib\site-packages\flask\app.py", line 1473, in wsgi_app
    response = self.full_dispatch_request()
  File "C:\Users\C\.conda\envs\tryagain\lib\site-packages\flask\app.py", line 882, in full_dispatch_request
    rv = self.handle_user_exception(e)
  File "C:\Users\C\.conda\envs\tryagain\lib\site-packages\flask_cors\extension.py", line 194, in wrapped_function
    return cors_after_request(app.make_response(f(*args, **kwargs)))
  File "C:\Users\C\.conda\envs\tryagain\lib\site-packages\flask\app.py", line 880, in full_dispatch_request
    rv = self.dispatch_request()
  File "C:\Users\C\.conda\envs\tryagain\lib\site-packages\flask\app.py", line 865, in dispatch_request
    return self.ensure_sync(self.view_functions[rule.endpoint])(**view_args)  # type: ignore[no-any-return]
  File "d:\Psystem\Databased\DataBase\music\app.py", line 325, in login
    result = database.login_with_account_password(account, password)
  File "d:\Psystem\Databased\DataBase\music\database.py", line 74, in login_with_account_password
    return {"status": "success", "message": "登录成功", "user_id": user['id'], "username": user['username']}
KeyError: 'id'
2025-04-01 16:29:05,134 - ERROR: Exception on /login [POST]
Traceback (most recent call last):
  File "C:\Users\C\.conda\envs\tryagain\lib\site-packages\flask\app.py", line 1473, in wsgi_app
    response = self.full_dispatch_request()
  File "C:\Users\C\.conda\envs\tryagain\lib\site-packages\flask\app.py", line 882, in full_dispatch_request
    rv = self.handle_user_exception(e)
  File "C:\Users\C\.conda\envs\tryagain\lib\site-packages\flask_cors\extension.py", line 194, in wrapped_function
    return cors_after_request(app.make_response(f(*args, **kwargs)))
  File "C:\Users\C\.conda\envs\tryagain\lib\site-packages\flask\app.py", line 880, in full_dispatch_request
    rv = self.dispatch_request()
  File "C:\Users\C\.conda\envs\tryagain\lib\site-packages\flask\app.py", line 865, in dispatch_request
    return self.ensure_sync(self.view_functions[rule.endpoint])(**view_args)  # type: ignore[no-any-return]
  File "d:\Psystem\Databased\DataBase\music\app.py", line 325, in login
    result = database.login_with_account_password(account, password)
  File "d:\Psystem\Databased\DataBase\music\database.py", line 74, in login_with_account_password
    return {"status": "success", "message": "登录成功", "user_id": user['id'], "username": user['username']}
KeyError: 'id'
2025-04-01 16:29:14,653 - ERROR: Exception on /login [POST]
Traceback (most recent call last):
  File "C:\Users\C\.conda\envs\tryagain\lib\site-packages\flask\app.py", line 1473, in wsgi_app
    response = self.full_dispatch_request()
  File "C:\Users\C\.conda\envs\tryagain\lib\site-packages\flask\app.py", line 882, in full_dispatch_request
    rv = self.handle_user_exception(e)
  File "C:\Users\C\.conda\envs\tryagain\lib\site-packages\flask_cors\extension.py", line 194, in wrapped_function
    return cors_after_request(app.make_response(f(*args, **kwargs)))
  File "C:\Users\C\.conda\envs\tryagain\lib\site-packages\flask\app.py", line 880, in full_dispatch_request
    rv = self.dispatch_request()
  File "C:\Users\C\.conda\envs\tryagain\lib\site-packages\flask\app.py", line 865, in dispatch_request
    return self.ensure_sync(self.view_functions[rule.endpoint])(**view_args)  # type: ignore[no-any-return]
  File "d:\Psystem\Databased\DataBase\music\app.py", line 325, in login
    result = database.login_with_account_password(account, password)
  File "d:\Psystem\Databased\DataBase\music\database.py", line 74, in login_with_account_password
    return {"status": "success", "message": "登录成功", "user_id": user['user_id'], "username": user['username']}
KeyError: 'id'
2025-04-01 16:29:22,170 - INFO: 临时目录创建于: C:\Users\C\AppData\Local\Temp\music_cfif1ejo
2025-04-01 16:29:22,174 - INFO: 服务启动初始化完成
2025-04-01 16:52:49,273 - ERROR: Exception on /wechat_login [POST]
Traceback (most recent call last):
  File "C:\Users\C\.conda\envs\tryagain\lib\site-packages\flask\app.py", line 1473, in wsgi_app
    response = self.full_dispatch_request()
  File "C:\Users\C\.conda\envs\tryagain\lib\site-packages\flask\app.py", line 882, in full_dispatch_request
    rv = self.handle_user_exception(e)
  File "C:\Users\C\.conda\envs\tryagain\lib\site-packages\flask_cors\extension.py", line 194, in wrapped_function
    return cors_after_request(app.make_response(f(*args, **kwargs)))
  File "C:\Users\C\.conda\envs\tryagain\lib\site-packages\flask\app.py", line 880, in full_dispatch_request
    rv = self.dispatch_request()
  File "C:\Users\C\.conda\envs\tryagain\lib\site-packages\flask\app.py", line 865, in dispatch_request
    return self.ensure_sync(self.view_functions[rule.endpoint])(**view_args)  # type: ignore[no-any-return]
  File "d:\Psystem\Databased\DataBase\music\app.py", line 336, in wechat_login
    result = database.login_with_wechat(wechat_openid)
  File "d:\Psystem\Databased\DataBase\music\database.py", line 92, in login_with_wechat
    register_wechat_user(wechat_openid)
  File "d:\Psystem\Databased\DataBase\music\database.py", line 105, in register_wechat_user
    cursor.execute(sql_check, (wechat_openid,))
  File "C:\Users\C\.conda\envs\tryagain\lib\site-packages\pymysql\cursors.py", line 148, in execute
    result = self._query(query)
  File "C:\Users\C\.conda\envs\tryagain\lib\site-packages\pymysql\cursors.py", line 310, in _query
    conn.query(q)
  File "C:\Users\C\.conda\envs\tryagain\lib\site-packages\pymysql\connections.py", line 548, in query
    self._affected_rows = self._read_query_result(unbuffered=unbuffered)
  File "C:\Users\C\.conda\envs\tryagain\lib\site-packages\pymysql\connections.py", line 775, in _read_query_result
    result.read()
  File "C:\Users\C\.conda\envs\tryagain\lib\site-packages\pymysql\connections.py", line 1156, in read
    first_packet = self.connection._read_packet()
  File "C:\Users\C\.conda\envs\tryagain\lib\site-packages\pymysql\connections.py", line 725, in _read_packet
    packet.raise_for_error()
  File "C:\Users\C\.conda\envs\tryagain\lib\site-packages\pymysql\protocol.py", line 221, in raise_for_error
    err.raise_mysql_exception(self._data)
  File "C:\Users\C\.conda\envs\tryagain\lib\site-packages\pymysql\err.py", line 143, in raise_mysql_exception
    raise errorclass(errno, errval)
pymysql.err.OperationalError: (1054, "Unknown column 'id' in 'field list'")
2025-04-01 16:53:42,661 - ERROR: Exception on /wechat_login [POST]
Traceback (most recent call last):
  File "C:\Users\C\.conda\envs\tryagain\lib\site-packages\flask\app.py", line 1473, in wsgi_app
    response = self.full_dispatch_request()
  File "C:\Users\C\.conda\envs\tryagain\lib\site-packages\flask\app.py", line 882, in full_dispatch_request
    rv = self.handle_user_exception(e)
  File "C:\Users\C\.conda\envs\tryagain\lib\site-packages\flask_cors\extension.py", line 194, in wrapped_function
    return cors_after_request(app.make_response(f(*args, **kwargs)))
  File "C:\Users\C\.conda\envs\tryagain\lib\site-packages\flask\app.py", line 880, in full_dispatch_request
    rv = self.dispatch_request()
  File "C:\Users\C\.conda\envs\tryagain\lib\site-packages\flask\app.py", line 865, in dispatch_request
    return self.ensure_sync(self.view_functions[rule.endpoint])(**view_args)  # type: ignore[no-any-return]
  File "d:\Psystem\Databased\DataBase\music\app.py", line 336, in wechat_login
    result = database.login_with_wechat(wechat_openid)
  File "d:\Psystem\Databased\DataBase\music\database.py", line 92, in login_with_wechat
    register_wechat_user(wechat_openid)
  File "d:\Psystem\Databased\DataBase\music\database.py", line 105, in register_wechat_user
    cursor.execute(sql_check, (wechat_openid,))
  File "C:\Users\C\.conda\envs\tryagain\lib\site-packages\pymysql\cursors.py", line 148, in execute
    result = self._query(query)
  File "C:\Users\C\.conda\envs\tryagain\lib\site-packages\pymysql\cursors.py", line 310, in _query
    conn.query(q)
  File "C:\Users\C\.conda\envs\tryagain\lib\site-packages\pymysql\connections.py", line 548, in query
    self._affected_rows = self._read_query_result(unbuffered=unbuffered)
  File "C:\Users\C\.conda\envs\tryagain\lib\site-packages\pymysql\connections.py", line 775, in _read_query_result
    result.read()
  File "C:\Users\C\.conda\envs\tryagain\lib\site-packages\pymysql\connections.py", line 1156, in read
    first_packet = self.connection._read_packet()
  File "C:\Users\C\.conda\envs\tryagain\lib\site-packages\pymysql\connections.py", line 725, in _read_packet
    packet.raise_for_error()
  File "C:\Users\C\.conda\envs\tryagain\lib\site-packages\pymysql\protocol.py", line 221, in raise_for_error
    err.raise_mysql_exception(self._data)
  File "C:\Users\C\.conda\envs\tryagain\lib\site-packages\pymysql\err.py", line 143, in raise_mysql_exception
    raise errorclass(errno, errval)
pymysql.err.OperationalError: (1054, "Unknown column 'id' in 'field list'")
2025-04-01 16:53:50,705 - INFO: 临时目录创建于: C:\Users\C\AppData\Local\Temp\music_v58qnr0a
2025-04-01 16:53:50,709 - INFO: 服务启动初始化完成
2025-04-01 16:53:51,602 - ERROR: Exception on /wechat_login [POST]
Traceback (most recent call last):
  File "C:\Users\C\.conda\envs\tryagain\lib\site-packages\flask\app.py", line 1473, in wsgi_app
    response = self.full_dispatch_request()
  File "C:\Users\C\.conda\envs\tryagain\lib\site-packages\flask\app.py", line 882, in full_dispatch_request
    rv = self.handle_user_exception(e)
  File "C:\Users\C\.conda\envs\tryagain\lib\site-packages\flask_cors\extension.py", line 194, in wrapped_function
    return cors_after_request(app.make_response(f(*args, **kwargs)))
  File "C:\Users\C\.conda\envs\tryagain\lib\site-packages\flask\app.py", line 880, in full_dispatch_request
    rv = self.dispatch_request()
  File "C:\Users\C\.conda\envs\tryagain\lib\site-packages\flask\app.py", line 865, in dispatch_request
    return self.ensure_sync(self.view_functions[rule.endpoint])(**view_args)  # type: ignore[no-any-return]
  File "d:\Psystem\Databased\DataBase\music\app.py", line 336, in wechat_login
    result = database.login_with_wechat(wechat_openid)
  File "d:\Psystem\Databased\DataBase\music\database.py", line 92, in login_with_wechat
    register_wechat_user(wechat_openid)
  File "d:\Psystem\Databased\DataBase\music\database.py", line 105, in register_wechat_user
    cursor.execute(sql_check, (wechat_openid,))
  File "C:\Users\C\.conda\envs\tryagain\lib\site-packages\pymysql\cursors.py", line 148, in execute
    result = self._query(query)
  File "C:\Users\C\.conda\envs\tryagain\lib\site-packages\pymysql\cursors.py", line 310, in _query
    conn.query(q)
  File "C:\Users\C\.conda\envs\tryagain\lib\site-packages\pymysql\connections.py", line 548, in query
    self._affected_rows = self._read_query_result(unbuffered=unbuffered)
  File "C:\Users\C\.conda\envs\tryagain\lib\site-packages\pymysql\connections.py", line 775, in _read_query_result
    result.read()
  File "C:\Users\C\.conda\envs\tryagain\lib\site-packages\pymysql\connections.py", line 1156, in read
    first_packet = self.connection._read_packet()
  File "C:\Users\C\.conda\envs\tryagain\lib\site-packages\pymysql\connections.py", line 725, in _read_packet
    packet.raise_for_error()
  File "C:\Users\C\.conda\envs\tryagain\lib\site-packages\pymysql\protocol.py", line 221, in raise_for_error
    err.raise_mysql_exception(self._data)
  File "C:\Users\C\.conda\envs\tryagain\lib\site-packages\pymysql\err.py", line 143, in raise_mysql_exception
    raise errorclass(errno, errval)
pymysql.err.OperationalError: (1054, "Unknown column 'id' in 'field list'")
2025-04-01 16:56:35,716 - INFO: 临时目录创建于: C:\Users\C\AppData\Local\Temp\music_316jnujh
2025-04-01 16:56:35,720 - INFO: 服务启动初始化完成
2025-04-01 16:56:41,921 - ERROR: Exception on /wechat_login [POST]
Traceback (most recent call last):
  File "C:\Users\C\.conda\envs\tryagain\lib\site-packages\flask\app.py", line 1473, in wsgi_app
    response = self.full_dispatch_request()
  File "C:\Users\C\.conda\envs\tryagain\lib\site-packages\flask\app.py", line 882, in full_dispatch_request
    rv = self.handle_user_exception(e)
  File "C:\Users\C\.conda\envs\tryagain\lib\site-packages\flask_cors\extension.py", line 194, in wrapped_function
    return cors_after_request(app.make_response(f(*args, **kwargs)))
  File "C:\Users\C\.conda\envs\tryagain\lib\site-packages\flask\app.py", line 880, in full_dispatch_request
    rv = self.dispatch_request()
  File "C:\Users\C\.conda\envs\tryagain\lib\site-packages\flask\app.py", line 865, in dispatch_request
    return self.ensure_sync(self.view_functions[rule.endpoint])(**view_args)  # type: ignore[no-any-return]
  File "d:\Psystem\Databased\DataBase\music\app.py", line 336, in wechat_login
    result = database.login_with_wechat(wechat_openid)
  File "d:\Psystem\Databased\DataBase\music\database.py", line 92, in login_with_wechat
    register_wechat_user(wechat_openid)
  File "d:\Psystem\Databased\DataBase\music\database.py", line 105, in register_wechat_user
    cursor.execute(sql_check, (wechat_openid,))
  File "C:\Users\C\.conda\envs\tryagain\lib\site-packages\pymysql\cursors.py", line 148, in execute
    result = self._query(query)
  File "C:\Users\C\.conda\envs\tryagain\lib\site-packages\pymysql\cursors.py", line 310, in _query
    conn.query(q)
  File "C:\Users\C\.conda\envs\tryagain\lib\site-packages\pymysql\connections.py", line 548, in query
    self._affected_rows = self._read_query_result(unbuffered=unbuffered)
  File "C:\Users\C\.conda\envs\tryagain\lib\site-packages\pymysql\connections.py", line 775, in _read_query_result
    result.read()
  File "C:\Users\C\.conda\envs\tryagain\lib\site-packages\pymysql\connections.py", line 1156, in read
    first_packet = self.connection._read_packet()
  File "C:\Users\C\.conda\envs\tryagain\lib\site-packages\pymysql\connections.py", line 725, in _read_packet
    packet.raise_for_error()
  File "C:\Users\C\.conda\envs\tryagain\lib\site-packages\pymysql\protocol.py", line 221, in raise_for_error
    err.raise_mysql_exception(self._data)
  File "C:\Users\C\.conda\envs\tryagain\lib\site-packages\pymysql\err.py", line 143, in raise_mysql_exception
    raise errorclass(errno, errval)
pymysql.err.OperationalError: (1054, "Unknown column 'id' in 'field list'")
2025-04-01 16:59:25,199 - INFO: 临时目录创建于: C:\Users\C\AppData\Local\Temp\music_b2rynznd
2025-04-01 16:59:25,201 - INFO: 服务启动初始化完成
2025-04-01 16:59:30,005 - ERROR: Exception on /wechat_login [POST]
Traceback (most recent call last):
  File "C:\Users\C\.conda\envs\tryagain\lib\site-packages\flask\app.py", line 1473, in wsgi_app
    response = self.full_dispatch_request()
  File "C:\Users\C\.conda\envs\tryagain\lib\site-packages\flask\app.py", line 882, in full_dispatch_request
    rv = self.handle_user_exception(e)
  File "C:\Users\C\.conda\envs\tryagain\lib\site-packages\flask_cors\extension.py", line 194, in wrapped_function
    return cors_after_request(app.make_response(f(*args, **kwargs)))
  File "C:\Users\C\.conda\envs\tryagain\lib\site-packages\flask\app.py", line 880, in full_dispatch_request
    rv = self.dispatch_request()
  File "C:\Users\C\.conda\envs\tryagain\lib\site-packages\flask\app.py", line 865, in dispatch_request
    return self.ensure_sync(self.view_functions[rule.endpoint])(**view_args)  # type: ignore[no-any-return]
  File "d:\Psystem\Databased\DataBase\music\app.py", line 336, in wechat_login
    result = database.login_with_wechat(wechat_openid)
  File "d:\Psystem\Databased\DataBase\music\database.py", line 92, in login_with_wechat
    register_wechat_user(wechat_openid)
  File "d:\Psystem\Databased\DataBase\music\database.py", line 105, in register_wechat_user
    cursor.execute(sql_check, (wechat_openid,))
  File "C:\Users\C\.conda\envs\tryagain\lib\site-packages\pymysql\cursors.py", line 148, in execute
    result = self._query(query)
  File "C:\Users\C\.conda\envs\tryagain\lib\site-packages\pymysql\cursors.py", line 310, in _query
    conn.query(q)
  File "C:\Users\C\.conda\envs\tryagain\lib\site-packages\pymysql\connections.py", line 548, in query
    self._affected_rows = self._read_query_result(unbuffered=unbuffered)
  File "C:\Users\C\.conda\envs\tryagain\lib\site-packages\pymysql\connections.py", line 775, in _read_query_result
    result.read()
  File "C:\Users\C\.conda\envs\tryagain\lib\site-packages\pymysql\connections.py", line 1156, in read
    first_packet = self.connection._read_packet()
  File "C:\Users\C\.conda\envs\tryagain\lib\site-packages\pymysql\connections.py", line 725, in _read_packet
    packet.raise_for_error()
  File "C:\Users\C\.conda\envs\tryagain\lib\site-packages\pymysql\protocol.py", line 221, in raise_for_error
    err.raise_mysql_exception(self._data)
  File "C:\Users\C\.conda\envs\tryagain\lib\site-packages\pymysql\err.py", line 143, in raise_mysql_exception
    raise errorclass(errno, errval)
pymysql.err.OperationalError: (1054, "Unknown column 'id' in 'field list'")
2025-04-01 17:02:33,703 - INFO: 临时目录创建于: C:\Users\C\AppData\Local\Temp\music_dex6mi6p
2025-04-01 17:02:33,706 - INFO: 服务启动初始化完成
2025-04-01 17:02:35,106 - ERROR: Exception on /wechat_login [POST]
Traceback (most recent call last):
  File "C:\Users\C\.conda\envs\tryagain\lib\site-packages\flask\app.py", line 1473, in wsgi_app
    response = self.full_dispatch_request()
  File "C:\Users\C\.conda\envs\tryagain\lib\site-packages\flask\app.py", line 882, in full_dispatch_request
    rv = self.handle_user_exception(e)
  File "C:\Users\C\.conda\envs\tryagain\lib\site-packages\flask_cors\extension.py", line 194, in wrapped_function
    return cors_after_request(app.make_response(f(*args, **kwargs)))
  File "C:\Users\C\.conda\envs\tryagain\lib\site-packages\flask\app.py", line 880, in full_dispatch_request
    rv = self.dispatch_request()
  File "C:\Users\C\.conda\envs\tryagain\lib\site-packages\flask\app.py", line 865, in dispatch_request
    return self.ensure_sync(self.view_functions[rule.endpoint])(**view_args)  # type: ignore[no-any-return]
  File "d:\Psystem\Databased\DataBase\music\app.py", line 336, in wechat_login
    result = database.login_with_wechat(wechat_openid)
  File "d:\Psystem\Databased\DataBase\music\database.py", line 92, in login_with_wechat
    register_wechat_user(wechat_openid)
  File "d:\Psystem\Databased\DataBase\music\database.py", line 112, in register_wechat_user
    cursor.execute(sql_check, (wechat_openid,))
  File "C:\Users\C\.conda\envs\tryagain\lib\site-packages\pymysql\cursors.py", line 148, in execute
    result = self._query(query)
  File "C:\Users\C\.conda\envs\tryagain\lib\site-packages\pymysql\cursors.py", line 310, in _query
    conn.query(q)
  File "C:\Users\C\.conda\envs\tryagain\lib\site-packages\pymysql\connections.py", line 548, in query
    self._affected_rows = self._read_query_result(unbuffered=unbuffered)
  File "C:\Users\C\.conda\envs\tryagain\lib\site-packages\pymysql\connections.py", line 775, in _read_query_result
    result.read()
  File "C:\Users\C\.conda\envs\tryagain\lib\site-packages\pymysql\connections.py", line 1156, in read
    first_packet = self.connection._read_packet()
  File "C:\Users\C\.conda\envs\tryagain\lib\site-packages\pymysql\connections.py", line 725, in _read_packet
    packet.raise_for_error()
  File "C:\Users\C\.conda\envs\tryagain\lib\site-packages\pymysql\protocol.py", line 221, in raise_for_error
    err.raise_mysql_exception(self._data)
  File "C:\Users\C\.conda\envs\tryagain\lib\site-packages\pymysql\err.py", line 143, in raise_mysql_exception
    raise errorclass(errno, errval)
pymysql.err.OperationalError: (1054, "Unknown column 'id' in 'field list'")
2025-04-01 17:03:37,789 - INFO: 临时目录创建于: C:\Users\C\AppData\Local\Temp\music_j9oon_t6
2025-04-01 17:03:37,792 - INFO: 服务启动初始化完成
2025-04-01 17:03:40,229 - ERROR: Exception on /wechat_login [POST]
Traceback (most recent call last):
  File "C:\Users\C\.conda\envs\tryagain\lib\site-packages\flask\app.py", line 1473, in wsgi_app
    response = self.full_dispatch_request()
  File "C:\Users\C\.conda\envs\tryagain\lib\site-packages\flask\app.py", line 882, in full_dispatch_request
    rv = self.handle_user_exception(e)
  File "C:\Users\C\.conda\envs\tryagain\lib\site-packages\flask_cors\extension.py", line 194, in wrapped_function
    return cors_after_request(app.make_response(f(*args, **kwargs)))
  File "C:\Users\C\.conda\envs\tryagain\lib\site-packages\flask\app.py", line 880, in full_dispatch_request
    rv = self.dispatch_request()
  File "C:\Users\C\.conda\envs\tryagain\lib\site-packages\flask\app.py", line 865, in dispatch_request
    return self.ensure_sync(self.view_functions[rule.endpoint])(**view_args)  # type: ignore[no-any-return]
  File "d:\Psystem\Databased\DataBase\music\app.py", line 336, in wechat_login
    result = database.login_with_wechat(wechat_openid)
  File "d:\Psystem\Databased\DataBase\music\database.py", line 92, in login_with_wechat
    register_wechat_user(wechat_openid)
  File "d:\Psystem\Databased\DataBase\music\database.py", line 112, in register_wechat_user
    cursor.execute(sql_check, (wechat_openid,))
  File "C:\Users\C\.conda\envs\tryagain\lib\site-packages\pymysql\cursors.py", line 148, in execute
    result = self._query(query)
  File "C:\Users\C\.conda\envs\tryagain\lib\site-packages\pymysql\cursors.py", line 310, in _query
    conn.query(q)
  File "C:\Users\C\.conda\envs\tryagain\lib\site-packages\pymysql\connections.py", line 548, in query
    self._affected_rows = self._read_query_result(unbuffered=unbuffered)
  File "C:\Users\C\.conda\envs\tryagain\lib\site-packages\pymysql\connections.py", line 775, in _read_query_result
    result.read()
  File "C:\Users\C\.conda\envs\tryagain\lib\site-packages\pymysql\connections.py", line 1156, in read
    first_packet = self.connection._read_packet()
  File "C:\Users\C\.conda\envs\tryagain\lib\site-packages\pymysql\connections.py", line 725, in _read_packet
    packet.raise_for_error()
  File "C:\Users\C\.conda\envs\tryagain\lib\site-packages\pymysql\protocol.py", line 221, in raise_for_error
    err.raise_mysql_exception(self._data)
  File "C:\Users\C\.conda\envs\tryagain\lib\site-packages\pymysql\err.py", line 143, in raise_mysql_exception
    raise errorclass(errno, errval)
pymysql.err.OperationalError: (1054, "Unknown column 'id' in 'field list'")
2025-04-01 17:05:33,479 - INFO: 临时目录创建于: C:\Users\C\AppData\Local\Temp\music_ljvp4ket
2025-04-01 17:05:33,482 - INFO: 服务启动初始化完成
2025-04-01 17:05:37,671 - ERROR: Exception on /wechat_login [POST]
Traceback (most recent call last):
  File "C:\Users\C\.conda\envs\tryagain\lib\site-packages\flask\app.py", line 1473, in wsgi_app
    response = self.full_dispatch_request()
  File "C:\Users\C\.conda\envs\tryagain\lib\site-packages\flask\app.py", line 882, in full_dispatch_request
    rv = self.handle_user_exception(e)
  File "C:\Users\C\.conda\envs\tryagain\lib\site-packages\flask_cors\extension.py", line 194, in wrapped_function
    return cors_after_request(app.make_response(f(*args, **kwargs)))
  File "C:\Users\C\.conda\envs\tryagain\lib\site-packages\flask\app.py", line 880, in full_dispatch_request
    rv = self.dispatch_request()
  File "C:\Users\C\.conda\envs\tryagain\lib\site-packages\flask\app.py", line 865, in dispatch_request
    return self.ensure_sync(self.view_functions[rule.endpoint])(**view_args)  # type: ignore[no-any-return]
  File "d:\Psystem\Databased\DataBase\music\app.py", line 336, in wechat_login
    result = database.login_with_wechat(wechat_openid)
  File "d:\Psystem\Databased\DataBase\music\database.py", line 92, in login_with_wechat
    register_wechat_user(wechat_openid)
  File "d:\Psystem\Databased\DataBase\music\database.py", line 112, in register_wechat_user
    cursor.execute(sql_check, (wechat_openid,))
  File "C:\Users\C\.conda\envs\tryagain\lib\site-packages\pymysql\cursors.py", line 148, in execute
    result = self._query(query)
  File "C:\Users\C\.conda\envs\tryagain\lib\site-packages\pymysql\cursors.py", line 310, in _query
    conn.query(q)
  File "C:\Users\C\.conda\envs\tryagain\lib\site-packages\pymysql\connections.py", line 548, in query
    self._affected_rows = self._read_query_result(unbuffered=unbuffered)
  File "C:\Users\C\.conda\envs\tryagain\lib\site-packages\pymysql\connections.py", line 775, in _read_query_result
    result.read()
  File "C:\Users\C\.conda\envs\tryagain\lib\site-packages\pymysql\connections.py", line 1156, in read
    first_packet = self.connection._read_packet()
  File "C:\Users\C\.conda\envs\tryagain\lib\site-packages\pymysql\connections.py", line 725, in _read_packet
    packet.raise_for_error()
  File "C:\Users\C\.conda\envs\tryagain\lib\site-packages\pymysql\protocol.py", line 221, in raise_for_error
    err.raise_mysql_exception(self._data)
  File "C:\Users\C\.conda\envs\tryagain\lib\site-packages\pymysql\err.py", line 143, in raise_mysql_exception
    raise errorclass(errno, errval)
pymysql.err.OperationalError: (1054, "Unknown column 'id' in 'field list'")
2025-04-01 17:11:52,635 - ERROR: Exception on /wechat_login [POST]
Traceback (most recent call last):
  File "C:\Users\C\.conda\envs\tryagain\lib\site-packages\flask\app.py", line 1473, in wsgi_app
    response = self.full_dispatch_request()
  File "C:\Users\C\.conda\envs\tryagain\lib\site-packages\flask\app.py", line 882, in full_dispatch_request
    rv = self.handle_user_exception(e)
  File "C:\Users\C\.conda\envs\tryagain\lib\site-packages\flask_cors\extension.py", line 194, in wrapped_function
    return cors_after_request(app.make_response(f(*args, **kwargs)))
  File "C:\Users\C\.conda\envs\tryagain\lib\site-packages\flask\app.py", line 880, in full_dispatch_request
    rv = self.dispatch_request()
  File "C:\Users\C\.conda\envs\tryagain\lib\site-packages\flask\app.py", line 865, in dispatch_request
    return self.ensure_sync(self.view_functions[rule.endpoint])(**view_args)  # type: ignore[no-any-return]
  File "d:\Psystem\Databased\DataBase\music\app.py", line 336, in wechat_login
    result = database.login_with_wechat(wechat_openid)
  File "d:\Psystem\Databased\DataBase\music\database.py", line 92, in login_with_wechat
    register_wechat_user(wechat_openid)
  File "d:\Psystem\Databased\DataBase\music\database.py", line 112, in register_wechat_user
    cursor.execute(sql_check, (wechat_openid,))
  File "C:\Users\C\.conda\envs\tryagain\lib\site-packages\pymysql\cursors.py", line 148, in execute
    result = self._query(query)
  File "C:\Users\C\.conda\envs\tryagain\lib\site-packages\pymysql\cursors.py", line 310, in _query
    conn.query(q)
  File "C:\Users\C\.conda\envs\tryagain\lib\site-packages\pymysql\connections.py", line 548, in query
    self._affected_rows = self._read_query_result(unbuffered=unbuffered)
  File "C:\Users\C\.conda\envs\tryagain\lib\site-packages\pymysql\connections.py", line 775, in _read_query_result
    result.read()
  File "C:\Users\C\.conda\envs\tryagain\lib\site-packages\pymysql\connections.py", line 1156, in read
    first_packet = self.connection._read_packet()
  File "C:\Users\C\.conda\envs\tryagain\lib\site-packages\pymysql\connections.py", line 725, in _read_packet
    packet.raise_for_error()
  File "C:\Users\C\.conda\envs\tryagain\lib\site-packages\pymysql\protocol.py", line 221, in raise_for_error
    err.raise_mysql_exception(self._data)
  File "C:\Users\C\.conda\envs\tryagain\lib\site-packages\pymysql\err.py", line 143, in raise_mysql_exception
    raise errorclass(errno, errval)
pymysql.err.OperationalError: (1054, "Unknown column 'id' in 'field list'")
2025-04-01 17:12:38,638 - INFO: 临时目录创建于: C:\Users\C\AppData\Local\Temp\music_pxf1154y
2025-04-01 17:12:38,641 - INFO: 服务启动初始化完成
2025-04-01 17:12:40,262 - ERROR: Exception on /wechat_login [POST]
Traceback (most recent call last):
  File "C:\Users\C\.conda\envs\tryagain\lib\site-packages\flask\app.py", line 1473, in wsgi_app
    response = self.full_dispatch_request()
  File "C:\Users\C\.conda\envs\tryagain\lib\site-packages\flask\app.py", line 882, in full_dispatch_request
    rv = self.handle_user_exception(e)
  File "C:\Users\C\.conda\envs\tryagain\lib\site-packages\flask_cors\extension.py", line 194, in wrapped_function
    return cors_after_request(app.make_response(f(*args, **kwargs)))
  File "C:\Users\C\.conda\envs\tryagain\lib\site-packages\flask\app.py", line 880, in full_dispatch_request
    rv = self.dispatch_request()
  File "C:\Users\C\.conda\envs\tryagain\lib\site-packages\flask\app.py", line 865, in dispatch_request
    return self.ensure_sync(self.view_functions[rule.endpoint])(**view_args)  # type: ignore[no-any-return]
  File "d:\Psystem\Databased\DataBase\music\app.py", line 336, in wechat_login
    result = database.login_with_wechat(wechat_openid)
  File "d:\Psystem\Databased\DataBase\music\database.py", line 92, in login_with_wechat
    register_wechat_user(wechat_openid)
  File "d:\Psystem\Databased\DataBase\music\database.py", line 124, in register_wechat_user
    cursor.execute(sql_insert, (username, wechat_openid, phone,account))
  File "C:\Users\C\.conda\envs\tryagain\lib\site-packages\pymysql\cursors.py", line 148, in execute
    result = self._query(query)
  File "C:\Users\C\.conda\envs\tryagain\lib\site-packages\pymysql\cursors.py", line 310, in _query
    conn.query(q)
  File "C:\Users\C\.conda\envs\tryagain\lib\site-packages\pymysql\connections.py", line 548, in query
    self._affected_rows = self._read_query_result(unbuffered=unbuffered)
  File "C:\Users\C\.conda\envs\tryagain\lib\site-packages\pymysql\connections.py", line 775, in _read_query_result
    result.read()
  File "C:\Users\C\.conda\envs\tryagain\lib\site-packages\pymysql\connections.py", line 1156, in read
    first_packet = self.connection._read_packet()
  File "C:\Users\C\.conda\envs\tryagain\lib\site-packages\pymysql\connections.py", line 725, in _read_packet
    packet.raise_for_error()
  File "C:\Users\C\.conda\envs\tryagain\lib\site-packages\pymysql\protocol.py", line 221, in raise_for_error
    err.raise_mysql_exception(self._data)
  File "C:\Users\C\.conda\envs\tryagain\lib\site-packages\pymysql\err.py", line 143, in raise_mysql_exception
    raise errorclass(errno, errval)
pymysql.err.IntegrityError: (1048, "Column 'username' cannot be null")
2025-04-01 17:14:53,258 - ERROR: Exception on /wechat_login [POST]
Traceback (most recent call last):
  File "C:\Users\C\.conda\envs\tryagain\lib\site-packages\flask\app.py", line 1473, in wsgi_app
    response = self.full_dispatch_request()
  File "C:\Users\C\.conda\envs\tryagain\lib\site-packages\flask\app.py", line 882, in full_dispatch_request
    rv = self.handle_user_exception(e)
  File "C:\Users\C\.conda\envs\tryagain\lib\site-packages\flask_cors\extension.py", line 194, in wrapped_function
    return cors_after_request(app.make_response(f(*args, **kwargs)))
  File "C:\Users\C\.conda\envs\tryagain\lib\site-packages\flask\app.py", line 880, in full_dispatch_request
    rv = self.dispatch_request()
  File "C:\Users\C\.conda\envs\tryagain\lib\site-packages\flask\app.py", line 865, in dispatch_request
    return self.ensure_sync(self.view_functions[rule.endpoint])(**view_args)  # type: ignore[no-any-return]
  File "d:\Psystem\Databased\DataBase\music\app.py", line 336, in wechat_login
    result = database.login_with_wechat(wechat_openid)
  File "d:\Psystem\Databased\DataBase\music\database.py", line 92, in login_with_wechat
    register_wechat_user(wechat_openid)
  File "d:\Psystem\Databased\DataBase\music\database.py", line 124, in register_wechat_user
    cursor.execute(sql_insert, (username, wechat_openid, phone,account))
  File "C:\Users\C\.conda\envs\tryagain\lib\site-packages\pymysql\cursors.py", line 148, in execute
    result = self._query(query)
  File "C:\Users\C\.conda\envs\tryagain\lib\site-packages\pymysql\cursors.py", line 310, in _query
    conn.query(q)
  File "C:\Users\C\.conda\envs\tryagain\lib\site-packages\pymysql\connections.py", line 548, in query
    self._affected_rows = self._read_query_result(unbuffered=unbuffered)
  File "C:\Users\C\.conda\envs\tryagain\lib\site-packages\pymysql\connections.py", line 775, in _read_query_result
    result.read()
  File "C:\Users\C\.conda\envs\tryagain\lib\site-packages\pymysql\connections.py", line 1156, in read
    first_packet = self.connection._read_packet()
  File "C:\Users\C\.conda\envs\tryagain\lib\site-packages\pymysql\connections.py", line 725, in _read_packet
    packet.raise_for_error()
  File "C:\Users\C\.conda\envs\tryagain\lib\site-packages\pymysql\protocol.py", line 221, in raise_for_error
    err.raise_mysql_exception(self._data)
  File "C:\Users\C\.conda\envs\tryagain\lib\site-packages\pymysql\err.py", line 143, in raise_mysql_exception
    raise errorclass(errno, errval)
pymysql.err.IntegrityError: (1048, "Column 'username' cannot be null")
2025-04-01 17:15:04,480 - ERROR: Exception on /wechat_login [POST]
Traceback (most recent call last):
  File "C:\Users\C\.conda\envs\tryagain\lib\site-packages\flask\app.py", line 1473, in wsgi_app
    response = self.full_dispatch_request()
  File "C:\Users\C\.conda\envs\tryagain\lib\site-packages\flask\app.py", line 882, in full_dispatch_request
    rv = self.handle_user_exception(e)
  File "C:\Users\C\.conda\envs\tryagain\lib\site-packages\flask_cors\extension.py", line 194, in wrapped_function
    return cors_after_request(app.make_response(f(*args, **kwargs)))
  File "C:\Users\C\.conda\envs\tryagain\lib\site-packages\flask\app.py", line 880, in full_dispatch_request
    rv = self.dispatch_request()
  File "C:\Users\C\.conda\envs\tryagain\lib\site-packages\flask\app.py", line 865, in dispatch_request
    return self.ensure_sync(self.view_functions[rule.endpoint])(**view_args)  # type: ignore[no-any-return]
  File "d:\Psystem\Databased\DataBase\music\app.py", line 336, in wechat_login
    result = database.login_with_wechat(wechat_openid)
  File "d:\Psystem\Databased\DataBase\music\database.py", line 92, in login_with_wechat
    register_wechat_user(wechat_openid)
  File "d:\Psystem\Databased\DataBase\music\database.py", line 124, in register_wechat_user
    INSERT INTO user (username, wechat_openid, phone, account,created_at)
  File "C:\Users\C\.conda\envs\tryagain\lib\site-packages\pymysql\cursors.py", line 148, in execute
    result = self._query(query)
  File "C:\Users\C\.conda\envs\tryagain\lib\site-packages\pymysql\cursors.py", line 310, in _query
    conn.query(q)
  File "C:\Users\C\.conda\envs\tryagain\lib\site-packages\pymysql\connections.py", line 548, in query
    self._affected_rows = self._read_query_result(unbuffered=unbuffered)
  File "C:\Users\C\.conda\envs\tryagain\lib\site-packages\pymysql\connections.py", line 775, in _read_query_result
    result.read()
  File "C:\Users\C\.conda\envs\tryagain\lib\site-packages\pymysql\connections.py", line 1156, in read
    first_packet = self.connection._read_packet()
  File "C:\Users\C\.conda\envs\tryagain\lib\site-packages\pymysql\connections.py", line 725, in _read_packet
    packet.raise_for_error()
  File "C:\Users\C\.conda\envs\tryagain\lib\site-packages\pymysql\protocol.py", line 221, in raise_for_error
    err.raise_mysql_exception(self._data)
  File "C:\Users\C\.conda\envs\tryagain\lib\site-packages\pymysql\err.py", line 143, in raise_mysql_exception
    raise errorclass(errno, errval)
pymysql.err.IntegrityError: (1048, "Column 'username' cannot be null")
2025-04-01 17:15:14,638 - INFO: 临时目录创建于: C:\Users\C\AppData\Local\Temp\music_17zzy5cl
2025-04-01 17:15:14,641 - INFO: 服务启动初始化完成
2025-04-01 17:17:28,891 - INFO: 临时目录创建于: C:\Users\C\AppData\Local\Temp\music_ewou4zc8
2025-04-01 17:17:28,894 - INFO: 服务启动初始化完成
2025-04-01 17:17:37,493 - ERROR: Exception on /wechat_login [POST]
Traceback (most recent call last):
  File "C:\Users\C\.conda\envs\tryagain\lib\site-packages\flask\app.py", line 1473, in wsgi_app
    response = self.full_dispatch_request()
  File "C:\Users\C\.conda\envs\tryagain\lib\site-packages\flask\app.py", line 882, in full_dispatch_request
    rv = self.handle_user_exception(e)
  File "C:\Users\C\.conda\envs\tryagain\lib\site-packages\flask_cors\extension.py", line 194, in wrapped_function
    return cors_after_request(app.make_response(f(*args, **kwargs)))
  File "C:\Users\C\.conda\envs\tryagain\lib\site-packages\flask\app.py", line 880, in full_dispatch_request
    rv = self.dispatch_request()
  File "C:\Users\C\.conda\envs\tryagain\lib\site-packages\flask\app.py", line 865, in dispatch_request
    return self.ensure_sync(self.view_functions[rule.endpoint])(**view_args)  # type: ignore[no-any-return]
  File "d:\Psystem\Databased\DataBase\music\app.py", line 336, in wechat_login
    result = database.login_with_wechat(wechat_openid)
  File "d:\Psystem\Databased\DataBase\music\database.py", line 103, in login_with_wechat
    return {"status": "success", "message": "登录成功", "user_id": user['user_id'], "username": user['username']}
TypeError: 'NoneType' object is not subscriptable
2025-04-01 17:19:08,868 - INFO: 临时目录创建于: C:\Users\C\AppData\Local\Temp\music_ne6_32oz
2025-04-01 17:19:08,872 - INFO: 服务启动初始化完成
2025-04-02 18:01:53,311 - INFO: 临时目录创建于: C:\Users\C\AppData\Local\Temp\music_kifdn83a
2025-04-02 18:04:58,432 - INFO: 临时目录创建于: C:\Users\C\AppData\Local\Temp\music_3a54e2yp
2025-04-02 18:07:16,075 - INFO: 临时目录创建于: C:\Users\C\AppData\Local\Temp\music_j4eh5dww
2025-04-02 18:11:43,463 - INFO: 临时目录创建于: C:\Users\C\AppData\Local\Temp\music_9r47v1vz
2025-04-02 18:13:54,249 - INFO: 临时目录创建于: C:\Users\C\AppData\Local\Temp\music_5d7x3ilc
2025-04-02 18:13:54,579 - INFO: 服务启动初始化完成
2025-04-02 18:42:01,183 - INFO: 临时目录创建于: C:\Users\C\AppData\Local\Temp\music_l7chuv1z
2025-04-02 18:42:02,309 - INFO: 服务启动初始化完成
2025-04-02 18:58:23,549 - INFO: 临时目录创建于: C:\Users\C\AppData\Local\Temp\music_rwq0odur
2025-04-02 18:58:24,505 - INFO: 服务启动初始化完成
2025-04-02 19:04:28,707 - INFO: 临时目录创建于: C:\Users\C\AppData\Local\Temp\music_oaohgvdm
2025-04-02 19:04:29,632 - INFO: 服务启动初始化完成
2025-04-02 19:06:59,112 - INFO: 临时目录创建于: C:\Users\C\AppData\Local\Temp\music_z0hepqbm
2025-04-02 19:06:59,459 - INFO: 服务启动初始化完成
2025-04-02 19:21:03,559 - INFO: 临时目录创建于: C:\Users\C\AppData\Local\Temp\music_sbnpz20k
2025-04-02 19:21:03,902 - INFO: 服务启动初始化完成
2025-04-02 19:22:44,277 - INFO: 临时目录创建于: C:\Users\C\AppData\Local\Temp\music_r581az61
2025-04-02 19:22:44,609 - INFO: 服务启动初始化完成
2025-04-02 19:28:59,732 - INFO: 临时目录创建于: C:\Users\C\AppData\Local\Temp\music_ihziqj69
2025-04-02 19:29:00,088 - INFO: 服务启动初始化完成
2025-04-02 19:29:02,338 - ERROR: Exception on /api/ask-ai [POST]
Traceback (most recent call last):
  File "d:\Psystem\Databased\DataBase\music\app.py", line 436, in ask_ai
    response = client.chat.completions.create(
  File "C:\Users\C\.conda\envs\tryagain\lib\site-packages\openai\_utils\_utils.py", line 279, in wrapper
    return func(*args, **kwargs)
  File "C:\Users\C\.conda\envs\tryagain\lib\site-packages\openai\resources\chat\completions\completions.py", line 914, in create
    return self._post(
  File "C:\Users\C\.conda\envs\tryagain\lib\site-packages\openai\_base_client.py", line 1242, in post
    return cast(ResponseT, self.request(cast_to, opts, stream=stream, stream_cls=stream_cls))
  File "C:\Users\C\.conda\envs\tryagain\lib\site-packages\openai\_base_client.py", line 919, in request
    return self._request(
  File "C:\Users\C\.conda\envs\tryagain\lib\site-packages\openai\_base_client.py", line 1023, in _request
    raise self._make_status_error_from_response(err.response) from None
openai.APIStatusError: Method Not Allowed

During handling of the above exception, another exception occurred:

Traceback (most recent call last):
  File "C:\Users\C\.conda\envs\tryagain\lib\site-packages\flask\app.py", line 1473, in wsgi_app
    response = self.full_dispatch_request()
  File "C:\Users\C\.conda\envs\tryagain\lib\site-packages\flask\app.py", line 882, in full_dispatch_request
    rv = self.handle_user_exception(e)
  File "C:\Users\C\.conda\envs\tryagain\lib\site-packages\flask_cors\extension.py", line 194, in wrapped_function
    return cors_after_request(app.make_response(f(*args, **kwargs)))
  File "C:\Users\C\.conda\envs\tryagain\lib\site-packages\flask\app.py", line 880, in full_dispatch_request
    rv = self.dispatch_request()
  File "C:\Users\C\.conda\envs\tryagain\lib\site-packages\flask\app.py", line 865, in dispatch_request
    return self.ensure_sync(self.view_functions[rule.endpoint])(**view_args)  # type: ignore[no-any-return]
  File "d:\Psystem\Databased\DataBase\music\app.py", line 457, in ask_ai
    print("❌ 错误详情:", str(e))  # 调试日志
UnicodeEncodeError: 'gbk' codec can't encode character '\u274c' in position 0: illegal multibyte sequence
2025-04-02 19:30:57,155 - INFO: 临时目录创建于: C:\Users\C\AppData\Local\Temp\music_fx9t7u0_
2025-04-02 19:30:57,505 - INFO: 服务启动初始化完成
2025-04-02 19:31:08,144 - ERROR: Exception on /api/ask-ai [POST]
Traceback (most recent call last):
  File "d:\Psystem\Databased\DataBase\music\app.py", line 438, in ask_ai
    response = client.chat.completions.create(
  File "C:\Users\C\.conda\envs\tryagain\lib\site-packages\openai\_utils\_utils.py", line 279, in wrapper
    return func(*args, **kwargs)
  File "C:\Users\C\.conda\envs\tryagain\lib\site-packages\openai\resources\chat\completions\completions.py", line 914, in create
    return self._post(
  File "C:\Users\C\.conda\envs\tryagain\lib\site-packages\openai\_base_client.py", line 1242, in post
    return cast(ResponseT, self.request(cast_to, opts, stream=stream, stream_cls=stream_cls))
  File "C:\Users\C\.conda\envs\tryagain\lib\site-packages\openai\_base_client.py", line 919, in request
    return self._request(
  File "C:\Users\C\.conda\envs\tryagain\lib\site-packages\openai\_base_client.py", line 1023, in _request
    raise self._make_status_error_from_response(err.response) from None
openai.APIStatusError: Method Not Allowed

During handling of the above exception, another exception occurred:

Traceback (most recent call last):
  File "C:\Users\C\.conda\envs\tryagain\lib\site-packages\flask\app.py", line 1473, in wsgi_app
    response = self.full_dispatch_request()
  File "C:\Users\C\.conda\envs\tryagain\lib\site-packages\flask\app.py", line 882, in full_dispatch_request
    rv = self.handle_user_exception(e)
  File "C:\Users\C\.conda\envs\tryagain\lib\site-packages\flask_cors\extension.py", line 194, in wrapped_function
    return cors_after_request(app.make_response(f(*args, **kwargs)))
  File "C:\Users\C\.conda\envs\tryagain\lib\site-packages\flask\app.py", line 880, in full_dispatch_request
    rv = self.dispatch_request()
  File "C:\Users\C\.conda\envs\tryagain\lib\site-packages\flask\app.py", line 865, in dispatch_request
    return self.ensure_sync(self.view_functions[rule.endpoint])(**view_args)  # type: ignore[no-any-return]
  File "d:\Psystem\Databased\DataBase\music\app.py", line 459, in ask_ai
    print("❌ 错误详情:", str(e))  # 调试日志
UnicodeEncodeError: 'gbk' codec can't encode character '\u274c' in position 0: illegal multibyte sequence
2025-04-02 19:32:38,630 - INFO: 临时目录创建于: C:\Users\C\AppData\Local\Temp\music_kduqxo_v
2025-04-02 19:32:38,978 - INFO: 服务启动初始化完成
2025-04-02 19:32:39,580 - ERROR: Exception on /api/ask-ai [POST]
Traceback (most recent call last):
  File "d:\Psystem\Databased\DataBase\music\app.py", line 438, in ask_ai
    response = client.chat.completions.create(
  File "C:\Users\C\.conda\envs\tryagain\lib\site-packages\openai\_utils\_utils.py", line 279, in wrapper
    return func(*args, **kwargs)
  File "C:\Users\C\.conda\envs\tryagain\lib\site-packages\openai\resources\chat\completions\completions.py", line 914, in create
    return self._post(
  File "C:\Users\C\.conda\envs\tryagain\lib\site-packages\openai\_base_client.py", line 1242, in post
    return cast(ResponseT, self.request(cast_to, opts, stream=stream, stream_cls=stream_cls))
  File "C:\Users\C\.conda\envs\tryagain\lib\site-packages\openai\_base_client.py", line 919, in request
    return self._request(
  File "C:\Users\C\.conda\envs\tryagain\lib\site-packages\openai\_base_client.py", line 1023, in _request
    raise self._make_status_error_from_response(err.response) from None
openai.APIStatusError: Method Not Allowed

During handling of the above exception, another exception occurred:

Traceback (most recent call last):
  File "C:\Users\C\.conda\envs\tryagain\lib\site-packages\flask\app.py", line 1473, in wsgi_app
    response = self.full_dispatch_request()
  File "C:\Users\C\.conda\envs\tryagain\lib\site-packages\flask\app.py", line 882, in full_dispatch_request
    rv = self.handle_user_exception(e)
  File "C:\Users\C\.conda\envs\tryagain\lib\site-packages\flask_cors\extension.py", line 194, in wrapped_function
    return cors_after_request(app.make_response(f(*args, **kwargs)))
  File "C:\Users\C\.conda\envs\tryagain\lib\site-packages\flask\app.py", line 880, in full_dispatch_request
    rv = self.dispatch_request()
  File "C:\Users\C\.conda\envs\tryagain\lib\site-packages\flask\app.py", line 865, in dispatch_request
    return self.ensure_sync(self.view_functions[rule.endpoint])(**view_args)  # type: ignore[no-any-return]
  File "d:\Psystem\Databased\DataBase\music\app.py", line 459, in ask_ai
    print("❌ 错误详情:", str(e))  # 调试日志
UnicodeEncodeError: 'gbk' codec can't encode character '\u274c' in position 0: illegal multibyte sequence
2025-04-02 19:34:04,388 - INFO: 临时目录创建于: C:\Users\C\AppData\Local\Temp\music_rllzzppj
2025-04-02 19:34:04,720 - INFO: 服务启动初始化完成
2025-04-02 19:34:13,557 - ERROR: Exception on /api/ask-ai [POST]
Traceback (most recent call last):
  File "d:\Psystem\Databased\DataBase\music\app.py", line 438, in ask_ai
    response = client.chat.completions.create(
  File "C:\Users\C\.conda\envs\tryagain\lib\site-packages\openai\_utils\_utils.py", line 279, in wrapper
    return func(*args, **kwargs)
  File "C:\Users\C\.conda\envs\tryagain\lib\site-packages\openai\resources\chat\completions\completions.py", line 914, in create
    return self._post(
  File "C:\Users\C\.conda\envs\tryagain\lib\site-packages\openai\_base_client.py", line 1242, in post
    return cast(ResponseT, self.request(cast_to, opts, stream=stream, stream_cls=stream_cls))
  File "C:\Users\C\.conda\envs\tryagain\lib\site-packages\openai\_base_client.py", line 919, in request
    return self._request(
  File "C:\Users\C\.conda\envs\tryagain\lib\site-packages\openai\_base_client.py", line 1023, in _request
    raise self._make_status_error_from_response(err.response) from None
openai.APIStatusError: Method Not Allowed

During handling of the above exception, another exception occurred:

Traceback (most recent call last):
  File "C:\Users\C\.conda\envs\tryagain\lib\site-packages\flask\app.py", line 1473, in wsgi_app
    response = self.full_dispatch_request()
  File "C:\Users\C\.conda\envs\tryagain\lib\site-packages\flask\app.py", line 882, in full_dispatch_request
    rv = self.handle_user_exception(e)
  File "C:\Users\C\.conda\envs\tryagain\lib\site-packages\flask_cors\extension.py", line 194, in wrapped_function
    return cors_after_request(app.make_response(f(*args, **kwargs)))
  File "C:\Users\C\.conda\envs\tryagain\lib\site-packages\flask\app.py", line 880, in full_dispatch_request
    rv = self.dispatch_request()
  File "C:\Users\C\.conda\envs\tryagain\lib\site-packages\flask\app.py", line 865, in dispatch_request
    return self.ensure_sync(self.view_functions[rule.endpoint])(**view_args)  # type: ignore[no-any-return]
  File "d:\Psystem\Databased\DataBase\music\app.py", line 459, in ask_ai
    print("❌ 错误详情:", str(e))  # 调试日志
UnicodeEncodeError: 'gbk' codec can't encode character '\u274c' in position 0: illegal multibyte sequence
2025-04-02 19:35:02,546 - INFO: 临时目录创建于: C:\Users\C\AppData\Local\Temp\music_oowqds_b
2025-04-02 19:35:02,895 - INFO: 服务启动初始化完成
2025-04-02 19:40:56,551 - INFO: 临时目录创建于: C:\Users\C\AppData\Local\Temp\music_npyn8mci
2025-04-02 19:40:56,878 - INFO: 服务启动初始化完成
2025-04-02 19:43:09,412 - INFO: 临时目录创建于: C:\Users\C\AppData\Local\Temp\music_myud6p75
2025-04-02 19:43:09,772 - INFO: 服务启动初始化完成
2025-04-02 19:43:43,948 - INFO: 临时目录创建于: C:\Users\C\AppData\Local\Temp\music_matbpk_h
2025-04-02 19:43:44,298 - INFO: 服务启动初始化完成
2025-04-02 19:44:14,722 - INFO: 临时目录创建于: C:\Users\C\AppData\Local\Temp\music_ci29_uxi
2025-04-02 19:44:15,045 - INFO: 服务启动初始化完成
2025-04-02 19:47:47,197 - INFO: 临时目录创建于: C:\Users\C\AppData\Local\Temp\music_n03q93bt
2025-04-02 19:47:47,529 - INFO: 服务启动初始化完成
2025-04-03 18:05:42,436 - INFO: 临时目录创建于: C:\Users\C\AppData\Local\Temp\music_8_tb68qm
2025-04-03 18:07:33,112 - INFO: 临时目录创建于: C:\Users\C\AppData\Local\Temp\music_zaa8vf7h
2025-04-03 18:08:46,409 - INFO: 临时目录创建于: C:\Users\C\AppData\Local\Temp\music__b0owyny
2025-04-03 18:09:33,278 - INFO: 临时目录创建于: C:\Users\C\AppData\Local\Temp\music_5yk2dzwf
2025-04-03 18:09:33,600 - INFO: 服务启动初始化完成
2025-04-04 00:16:57,752 - INFO: 临时目录创建于: C:\Users\C\AppData\Local\Temp\music_vf2v1hgw
2025-04-04 00:16:58,188 - INFO: 服务启动初始化完成
2025-04-04 00:20:27,390 - INFO: 临时目录创建于: C:\Users\C\AppData\Local\Temp\music_tk3ih4y8
2025-04-04 00:20:27,736 - INFO: 服务启动初始化完成
2025-04-04 00:25:09,724 - INFO: 临时目录创建于: C:\Users\C\AppData\Local\Temp\music_gl8subco
2025-04-04 00:25:10,058 - INFO: 服务启动初始化完成
2025-04-04 00:36:20,741 - INFO: 临时目录创建于: C:\Users\C\AppData\Local\Temp\music_ydeap_33
2025-04-04 00:36:21,081 - INFO: 服务启动初始化完成
2025-04-04 00:38:07,288 - INFO: 临时目录创建于: C:\Users\C\AppData\Local\Temp\music_7f82vxrb
2025-04-04 00:38:07,629 - INFO: 服务启动初始化完成
2025-04-04 00:41:17,058 - INFO: 临时目录创建于: C:\Users\C\AppData\Local\Temp\music_ri_6sd9e
2025-04-04 00:41:17,408 - INFO: 服务启动初始化完成
2025-04-04 00:43:59,820 - INFO: 临时目录创建于: C:\Users\C\AppData\Local\Temp\music_j6ysqtpo
2025-04-04 00:44:00,184 - INFO: 服务启动初始化完成
2025-04-04 01:16:53,216 - INFO: 临时目录创建于: C:\Users\C\AppData\Local\Temp\music_858aol3p
2025-04-04 01:16:53,558 - INFO: 服务启动初始化完成
2025-04-04 12:39:38,617 - INFO: 临时目录创建于: C:\Users\C\AppData\Local\Temp\music_npfk3uf0
2025-04-04 12:39:38,987 - INFO: 服务启动初始化完成
2025-04-04 12:40:26,095 - INFO: 临时目录创建于: C:\Users\C\AppData\Local\Temp\music_84xacl02
2025-04-04 12:40:26,440 - INFO: 服务启动初始化完成
2025-04-04 13:57:00,859 - INFO: 临时目录创建于: C:\Users\C\AppData\Local\Temp\music_td4ub172
2025-04-04 13:57:01,196 - INFO: 服务启动初始化完成
2025-04-04 14:07:56,256 - INFO: 临时目录创建于: C:\Users\C\AppData\Local\Temp\music_h62eqyzd
2025-04-04 14:07:56,625 - INFO: 服务启动初始化完成
2025-04-04 14:42:12,433 - INFO: 临时目录创建于: C:\Users\C\AppData\Local\Temp\music_95xa3dni
2025-04-04 14:42:13,410 - INFO: 服务启动初始化完成
2025-04-04 14:57:06,662 - INFO: 临时目录创建于: C:\Users\C\AppData\Local\Temp\music_kr322m0o
2025-04-04 14:57:07,610 - INFO: 服务启动初始化完成
2025-04-04 14:58:47,300 - INFO: 临时目录创建于: C:\Users\C\AppData\Local\Temp\music_vdxoclim
2025-04-04 14:58:48,262 - INFO: 服务启动初始化完成
2025-04-04 15:04:08,165 - INFO: 临时目录创建于: C:\Users\C\AppData\Local\Temp\music_wfpocqge
2025-04-04 15:04:09,168 - INFO: 服务启动初始化完成
2025-04-04 15:07:30,306 - INFO: 临时目录创建于: C:\Users\C\AppData\Local\Temp\music_qau80kjp
2025-04-04 15:07:30,646 - INFO: 服务启动初始化完成
2025-04-04 17:29:24,426 - INFO: 临时目录创建于: C:\Users\C\AppData\Local\Temp\music_cb5wns_x
2025-04-04 17:29:26,281 - INFO: 服务启动初始化完成
2025-04-04 17:52:51,815 - INFO: 临时目录创建于: C:\Users\C\AppData\Local\Temp\music_t5mgdazm
2025-04-04 17:52:52,795 - INFO: 服务启动初始化完成
2025-04-04 17:55:05,693 - INFO: 临时目录创建于: C:\Users\C\AppData\Local\Temp\music_sl5zlxiv
2025-04-04 17:55:06,625 - INFO: 服务启动初始化完成
2025-04-04 17:55:08,392 - INFO: 临时目录创建于: C:\Users\C\AppData\Local\Temp\music_elfy16k5
2025-04-04 17:55:09,294 - INFO: 服务启动初始化完成
2025-04-04 18:07:26,278 - INFO: 临时目录创建于: C:\Users\C\AppData\Local\Temp\music_tdh7w3g6
2025-04-04 18:07:27,207 - INFO: 服务启动初始化完成
2025-04-04 18:08:23,147 - INFO: 临时目录创建于: C:\Users\C\AppData\Local\Temp\music_6jeo9u95
2025-04-04 18:08:24,094 - INFO: 服务启动初始化完成
2025-04-04 18:08:25,761 - INFO: 临时目录创建于: C:\Users\C\AppData\Local\Temp\music_pa_guivr
2025-04-04 18:08:26,729 - INFO: 服务启动初始化完成
2025-04-04 19:10:34,022 - INFO: 临时目录创建于: C:\Users\C\AppData\Local\Temp\music_w3yuiyva
2025-04-04 19:10:35,839 - INFO: 服务启动初始化完成
2025-04-04 19:10:38,167 - INFO: 临时目录创建于: C:\Users\C\AppData\Local\Temp\music_tmhdcsyx
2025-04-04 19:10:39,275 - INFO: 服务启动初始化完成
2025-04-04 19:14:42,694 - INFO: 临时目录创建于: C:\Users\C\AppData\Local\Temp\music_o2d842fz
2025-04-04 19:14:43,676 - INFO: 服务启动初始化完成
2025-04-04 19:14:51,272 - INFO: 临时目录创建于: C:\Users\C\AppData\Local\Temp\music_gi2apa1e
2025-04-04 19:14:52,258 - INFO: 服务启动初始化完成
2025-04-04 19:14:53,983 - INFO: 临时目录创建于: C:\Users\C\AppData\Local\Temp\music_gpows_gw
2025-04-04 19:14:54,905 - INFO: 服务启动初始化完成
2025-04-04 22:33:42,106 - INFO: 临时目录创建于: C:\Users\C\AppData\Local\Temp\music_i6s41c0o
2025-04-04 22:33:42,464 - INFO: 服务启动初始化完成
2025-04-04 22:33:44,100 - INFO: 临时目录创建于: C:\Users\C\AppData\Local\Temp\music_26y9e_r_
2025-04-04 22:33:44,424 - INFO: 服务启动初始化完成
2025-04-04 23:52:29,147 - INFO: 临时目录创建于: C:\Users\C\AppData\Local\Temp\music_q696v3nw
2025-04-04 23:52:29,508 - INFO: 服务启动初始化完成
2025-04-04 23:52:35,180 - INFO: 临时目录创建于: C:\Users\C\AppData\Local\Temp\music_jo3lk5em
2025-04-04 23:52:35,530 - INFO: 服务启动初始化完成
2025-04-04 23:52:42,214 - INFO: 临时目录创建于: C:\Users\C\AppData\Local\Temp\music_rg8l9xl4
2025-04-04 23:52:42,562 - INFO: 服务启动初始化完成
2025-04-04 23:54:00,924 - INFO: 临时目录创建于: C:\Users\C\AppData\Local\Temp\music_vyh8vu9c
2025-04-04 23:54:01,277 - INFO: 服务启动初始化完成
2025-04-04 23:54:07,929 - INFO: 临时目录创建于: C:\Users\C\AppData\Local\Temp\music_vpq6wq0o
2025-04-04 23:54:08,274 - INFO: 服务启动初始化完成
2025-04-05 12:15:50,493 - INFO: 临时目录创建于: C:\Users\C\AppData\Local\Temp\music_7vh6mp3i
2025-04-05 12:15:50,982 - INFO: 服务启动初始化完成
2025-04-05 12:15:57,355 - INFO: 临时目录创建于: C:\Users\C\AppData\Local\Temp\music_9tjwsrwv
2025-04-05 12:15:57,671 - INFO: 服务启动初始化完成
2025-04-05 12:18:11,998 - INFO: 临时目录创建于: C:\Users\C\AppData\Local\Temp\music_vztvishz
2025-04-05 12:18:12,314 - INFO: 服务启动初始化完成
2025-04-05 12:18:18,725 - INFO: 临时目录创建于: C:\Users\C\AppData\Local\Temp\music_xo5s3w40
2025-04-05 12:18:19,033 - INFO: 服务启动初始化完成
2025-04-05 12:28:35,059 - INFO: 临时目录创建于: C:\Users\C\AppData\Local\Temp\music_zhr4rfrj
2025-04-05 12:28:35,409 - INFO: 服务启动初始化完成
2025-04-05 12:31:59,560 - INFO: 临时目录创建于: C:\Users\C\AppData\Local\Temp\music_6g05pi9s
2025-04-05 12:31:59,892 - INFO: 服务启动初始化完成
2025-04-05 12:32:06,430 - INFO: 临时目录创建于: C:\Users\C\AppData\Local\Temp\music_t4vz999a
2025-04-05 12:32:06,738 - INFO: 服务启动初始化完成
2025-04-05 12:39:11,737 - INFO: 临时目录创建于: C:\Users\C\AppData\Local\Temp\music_td02uydq
2025-04-05 12:39:12,092 - INFO: 服务启动初始化完成
2025-04-05 12:39:18,890 - INFO: 临时目录创建于: C:\Users\C\AppData\Local\Temp\music_u0qzj_hq
2025-04-05 12:39:19,269 - INFO: 服务启动初始化完成
2025-04-05 12:40:05,890 - INFO: 临时目录创建于: C:\Users\C\AppData\Local\Temp\music_vs76sdm6
2025-04-05 12:40:06,238 - INFO: 服务启动初始化完成
2025-04-05 12:40:12,767 - INFO: 临时目录创建于: C:\Users\C\AppData\Local\Temp\music_n9ikj46s
2025-04-05 12:40:13,105 - INFO: 服务启动初始化完成
2025-04-05 12:44:55,524 - INFO: 临时目录创建于: C:\Users\C\AppData\Local\Temp\music_v39zibd4
2025-04-05 12:44:55,867 - INFO: 服务启动初始化完成
2025-04-05 12:45:57,468 - INFO: 临时目录创建于: C:\Users\C\AppData\Local\Temp\music_99zi1db6
2025-04-05 12:45:57,807 - INFO: 服务启动初始化完成
2025-04-05 12:46:01,916 - INFO: 临时目录创建于: C:\Users\C\AppData\Local\Temp\music_jtybufbz
2025-04-05 12:46:02,244 - INFO: 服务启动初始化完成
2025-04-05 12:46:08,839 - INFO: 临时目录创建于: C:\Users\C\AppData\Local\Temp\music_ou21kq4g
2025-04-05 12:46:09,178 - INFO: 服务启动初始化完成
2025-04-05 14:27:08,236 - INFO: 临时目录创建于: C:\Users\C\AppData\Local\Temp\music_al0mnm40
2025-04-05 14:27:09,902 - INFO: 服务启动初始化完成
2025-04-05 14:27:16,934 - INFO: 临时目录创建于: C:\Users\C\AppData\Local\Temp\music_b90jbpo1
2025-04-05 14:27:17,942 - INFO: 服务启动初始化完成
2025-04-05 14:30:47,361 - INFO: 临时目录创建于: C:\Users\C\AppData\Local\Temp\music_ysmmjl68
2025-04-05 14:30:48,299 - INFO: 服务启动初始化完成
2025-04-05 14:31:54,960 - INFO: 临时目录创建于: C:\Users\C\AppData\Local\Temp\music_1x82p2xw
2025-04-05 14:31:55,917 - INFO: 服务启动初始化完成
2025-04-05 14:33:09,277 - INFO: 临时目录创建于: C:\Users\C\AppData\Local\Temp\music_iow2bhjx
2025-04-05 14:33:10,218 - INFO: 服务启动初始化完成
2025-04-05 14:33:16,956 - INFO: 临时目录创建于: C:\Users\C\AppData\Local\Temp\music_5q4yne36
2025-04-05 14:33:17,876 - INFO: 服务启动初始化完成
2025-04-05 14:34:45,721 - INFO: 临时目录创建于: C:\Users\C\AppData\Local\Temp\music_kxzjpbhb
2025-04-05 14:34:46,643 - INFO: 服务启动初始化完成
2025-04-05 14:40:31,235 - INFO: 临时目录创建于: C:\Users\C\AppData\Local\Temp\music_f0q100ub
2025-04-05 14:40:32,178 - INFO: 服务启动初始化完成
2025-04-05 14:40:38,742 - INFO: 临时目录创建于: C:\Users\C\AppData\Local\Temp\music_nsnwc3qv
2025-04-05 14:40:39,616 - INFO: 服务启动初始化完成
2025-04-05 14:52:47,594 - INFO: 临时目录创建于: C:\Users\C\AppData\Local\Temp\music_ceq6e20l
2025-04-05 14:52:47,947 - INFO: 服务启动初始化完成
2025-04-05 14:52:54,662 - INFO: 临时目录创建于: C:\Users\C\AppData\Local\Temp\music_h9a69i_g
2025-04-05 14:52:54,996 - INFO: 服务启动初始化完成
2025-04-05 22:46:58,981 - INFO: 临时目录创建于: C:\Users\C\AppData\Local\Temp\music_9kdajmrp
2025-04-05 22:46:59,334 - INFO: 服务启动初始化完成
2025-04-05 22:47:06,066 - INFO: 临时目录创建于: C:\Users\C\AppData\Local\Temp\music_vm7qasal
2025-04-05 22:47:06,405 - INFO: 服务启动初始化完成
2025-04-15 23:19:33,145 - INFO: 临时目录创建于: C:\Users\C\AppData\Local\Temp\music_uq3nxpuq
2025-04-15 23:19:33,521 - INFO: 服务启动初始化完成
2025-04-15 23:19:40,001 - INFO: 临时目录创建于: C:\Users\C\AppData\Local\Temp\music_tunzkl86
2025-04-15 23:19:40,326 - INFO: 服务启动初始化完成
2025-04-15 23:22:53,458 - INFO: 临时目录创建于: C:\Users\C\AppData\Local\Temp\music_bvhn_bex
2025-04-15 23:24:47,863 - INFO: 临时目录创建于: C:\Users\C\AppData\Local\Temp\music_nszfz3bi
2025-04-15 23:24:48,218 - INFO: 服务启动初始化完成
2025-04-15 23:24:54,757 - INFO: 临时目录创建于: C:\Users\C\AppData\Local\Temp\music_csh7qeth
2025-04-15 23:24:55,076 - INFO: 服务启动初始化完成
2025-04-15 23:31:35,967 - INFO: 临时目录创建于: C:\Users\C\AppData\Local\Temp\music_a263zv40
2025-04-15 23:31:36,306 - INFO: 服务启动初始化完成
2025-04-15 23:31:40,928 - INFO: 临时目录创建于: C:\Users\C\AppData\Local\Temp\music_8vfp19in
2025-04-15 23:31:41,275 - INFO: 服务启动初始化完成
2025-04-15 23:31:47,603 - INFO: 临时目录创建于: C:\Users\C\AppData\Local\Temp\music_wen0lhmh
2025-04-15 23:31:47,961 - INFO: 服务启动初始化完成
2025-04-15 23:32:12,048 - INFO: 临时目录创建于: C:\Users\C\AppData\Local\Temp\music_moc4popg
2025-04-15 23:32:12,400 - INFO: 服务启动初始化完成
2025-04-15 23:33:37,695 - INFO: 临时目录创建于: C:\Users\C\AppData\Local\Temp\music_5ixt61el
2025-04-15 23:33:38,030 - INFO: 服务启动初始化完成
2025-04-15 23:33:44,697 - INFO: 临时目录创建于: C:\Users\C\AppData\Local\Temp\music_c86m_07b
2025-04-15 23:33:45,047 - INFO: 服务启动初始化完成
2025-04-15 23:34:51,802 - INFO: 临时目录创建于: C:\Users\C\AppData\Local\Temp\music_q1salbub
2025-04-15 23:34:52,147 - INFO: 服务启动初始化完成
2025-04-15 23:35:27,419 - INFO: 临时目录创建于: C:\Users\C\AppData\Local\Temp\music_6k8laj2g
2025-04-15 23:35:27,772 - INFO: 服务启动初始化完成
2025-04-15 23:35:45,819 - INFO: 临时目录创建于: C:\Users\C\AppData\Local\Temp\music_l6yr4d1m
2025-04-15 23:35:46,171 - INFO: 服务启动初始化完成
2025-04-15 23:36:47,582 - INFO: 临时目录创建于: C:\Users\C\AppData\Local\Temp\music_pzq4g1nj
2025-04-15 23:36:47,925 - INFO: 服务启动初始化完成
2025-04-15 23:36:52,939 - INFO: 临时目录创建于: C:\Users\C\AppData\Local\Temp\music_f07n4wcn
2025-04-15 23:36:53,284 - INFO: 服务启动初始化完成
2025-04-15 23:38:29,326 - INFO: 临时目录创建于: C:\Users\C\AppData\Local\Temp\music_d49h_gxu
2025-04-15 23:38:29,667 - INFO: 服务启动初始化完成
2025-04-15 23:38:35,631 - INFO: 临时目录创建于: C:\Users\C\AppData\Local\Temp\music_6def9bxo
2025-04-15 23:38:35,997 - INFO: 服务启动初始化完成
2025-04-15 23:40:16,179 - INFO: 临时目录创建于: C:\Users\C\AppData\Local\Temp\music_mmec90qy
2025-04-15 23:40:16,536 - INFO: 服务启动初始化完成
2025-04-15 23:41:26,239 - INFO: 临时目录创建于: C:\Users\C\AppData\Local\Temp\music_2a61swvn
2025-04-15 23:41:26,583 - INFO: 服务启动初始化完成
2025-04-15 23:41:33,518 - INFO: 临时目录创建于: C:\Users\C\AppData\Local\Temp\music_ht5iux64
2025-04-15 23:41:33,877 - INFO: 服务启动初始化完成
2025-04-15 23:43:24,457 - INFO: 临时目录创建于: C:\Users\C\AppData\Local\Temp\music_f8c8bbqx
2025-04-15 23:43:24,820 - INFO: 服务启动初始化完成
2025-04-15 23:43:31,411 - INFO: 临时目录创建于: C:\Users\C\AppData\Local\Temp\music_kx4c1x20
2025-04-15 23:43:31,744 - INFO: 服务启动初始化完成
2025-04-15 23:49:13,212 - INFO: 临时目录创建于: C:\Users\C\AppData\Local\Temp\music_hpto4qzw
2025-04-15 23:49:58,231 - INFO: 临时目录创建于: C:\Users\C\AppData\Local\Temp\music_nap0nbxx
2025-04-15 23:49:58,581 - INFO: 服务启动初始化完成
2025-04-15 23:50:05,275 - INFO: 临时目录创建于: C:\Users\C\AppData\Local\Temp\music__v7cltoy
2025-04-15 23:50:05,650 - INFO: 服务启动初始化完成
2025-04-15 23:52:12,272 - INFO: 临时目录创建于: C:\Users\C\AppData\Local\Temp\music_rm_u_lok
2025-04-15 23:52:12,616 - INFO: 服务启动初始化完成
2025-04-15 23:54:21,207 - INFO: 临时目录创建于: C:\Users\C\AppData\Local\Temp\music_z7l1mt__
2025-04-15 23:54:21,556 - INFO: 服务启动初始化完成
2025-04-15 23:55:03,426 - INFO: 临时目录创建于: C:\Users\C\AppData\Local\Temp\music_h30ffmqm
2025-04-15 23:55:03,765 - INFO: 服务启动初始化完成
2025-04-15 23:55:10,417 - INFO: 临时目录创建于: C:\Users\C\AppData\Local\Temp\music_ic9l02ry
2025-04-15 23:55:10,774 - INFO: 服务启动初始化完成
2025-04-19 14:30:27,842 - INFO: 临时目录创建于: C:\Users\C\AppData\Local\Temp\music_pxtb97yd
2025-04-19 14:30:28,840 - INFO: 服务启动初始化完成
2025-04-19 14:30:35,402 - INFO: 临时目录创建于: C:\Users\C\AppData\Local\Temp\music_eh86jk33
2025-04-19 14:30:36,369 - INFO: 服务启动初始化完成
2025-04-19 14:34:47,218 - INFO: 临时目录创建于: C:\Users\C\AppData\Local\Temp\music_jf8sndio
2025-04-19 14:34:48,188 - INFO: 服务启动初始化完成
2025-04-19 14:35:12,305 - INFO: 临时目录创建于: C:\Users\C\AppData\Local\Temp\music_0v35ahu9
2025-04-19 14:35:13,272 - INFO: 服务启动初始化完成
2025-04-19 14:35:25,757 - INFO: 临时目录创建于: C:\Users\C\AppData\Local\Temp\music_e61wlpe2
2025-04-19 14:35:26,721 - INFO: 服务启动初始化完成
2025-04-19 14:35:33,552 - INFO: 临时目录创建于: C:\Users\C\AppData\Local\Temp\music_l90tu6um
2025-04-19 14:35:34,558 - INFO: 服务启动初始化完成
2025-04-19 14:36:45,960 - INFO: 临时目录创建于: C:\Users\C\AppData\Local\Temp\music_co6sixta
2025-04-19 14:36:46,914 - INFO: 服务启动初始化完成
2025-04-19 14:36:53,478 - INFO: 临时目录创建于: C:\Users\C\AppData\Local\Temp\music_j_l0wm8u
2025-04-19 14:36:54,500 - INFO: 服务启动初始化完成
2025-04-19 14:49:29,872 - INFO: 临时目录创建于: C:\Users\C\AppData\Local\Temp\music_2cujnibq
2025-04-19 14:49:30,921 - INFO: 服务启动初始化完成
2025-04-19 14:51:00,012 - INFO: 临时目录创建于: C:\Users\C\AppData\Local\Temp\music_ififcwpr
2025-04-19 14:51:01,015 - INFO: 服务启动初始化完成
2025-04-19 14:51:55,586 - INFO: 临时目录创建于: C:\Users\C\AppData\Local\Temp\music_nop7p33k
2025-04-19 14:51:56,558 - INFO: 服务启动初始化完成
2025-04-19 14:55:15,816 - INFO: 临时目录创建于: C:\Users\C\AppData\Local\Temp\music_m3uwnj3_
2025-04-19 14:55:16,762 - INFO: 服务启动初始化完成
2025-04-19 14:55:20,702 - INFO: 临时目录创建于: C:\Users\C\AppData\Local\Temp\music_caa72fee
2025-04-19 14:55:21,720 - INFO: 服务启动初始化完成
2025-04-19 14:56:19,221 - INFO: 临时目录创建于: C:\Users\C\AppData\Local\Temp\music_0y00juh4
2025-04-19 14:56:20,211 - INFO: 服务启动初始化完成
2025-04-19 14:57:37,915 - INFO: 临时目录创建于: C:\Users\C\AppData\Local\Temp\music_04totc_i
2025-04-19 14:57:38,264 - INFO: 服务启动初始化完成
2025-04-19 14:58:12,592 - INFO: 临时目录创建于: C:\Users\C\AppData\Local\Temp\music_oc565s8d
2025-04-19 14:58:12,942 - INFO: 服务启动初始化完成
2025-04-19 15:01:56,672 - INFO: 临时目录创建于: C:\Users\C\AppData\Local\Temp\music_vx3jyyqf
2025-04-19 15:01:57,050 - INFO: 服务启动初始化完成
2025-04-19 17:36:53,430 - INFO: 临时目录创建于: C:\Users\C\AppData\Local\Temp\music_ninrwqfh
2025-04-19 17:36:54,440 - INFO: 服务启动初始化完成
2025-04-19 17:37:01,037 - INFO: 临时目录创建于: C:\Users\C\AppData\Local\Temp\music_uqrnlglq
2025-04-19 17:37:02,007 - INFO: 服务启动初始化完成
2025-04-19 17:40:36,779 - INFO: 临时目录创建于: C:\Users\C\AppData\Local\Temp\music_9m29hnm0
2025-04-19 17:40:37,733 - INFO: 服务启动初始化完成
2025-04-19 17:41:10,963 - INFO: 临时目录创建于: C:\Users\C\AppData\Local\Temp\music_37q0upzd
2025-04-19 17:41:11,908 - INFO: 服务启动初始化完成
2025-04-19 17:43:57,727 - INFO: 临时目录创建于: C:\Users\C\AppData\Local\Temp\music_x1lwb7ld
2025-04-19 17:43:58,072 - INFO: 服务启动初始化完成
2025-04-19 17:48:07,038 - INFO: 临时目录创建于: C:\Users\C\AppData\Local\Temp\music_t3dqymko
2025-04-19 17:48:07,388 - INFO: 服务启动初始化完成
2025-04-19 17:49:47,921 - INFO: 临时目录创建于: C:\Users\C\AppData\Local\Temp\music_xpm0lm5z
2025-04-19 17:49:48,289 - INFO: 服务启动初始化完成
2025-04-19 17:49:54,858 - INFO: 临时目录创建于: C:\Users\C\AppData\Local\Temp\music_evpxs8zz
2025-04-19 17:49:55,217 - INFO: 服务启动初始化完成
2025-04-19 17:50:29,460 - INFO: 临时目录创建于: C:\Users\C\AppData\Local\Temp\music_r0w4k6ov
2025-04-19 17:50:29,802 - INFO: 服务启动初始化完成
2025-04-19 17:58:01,427 - INFO: 临时目录创建于: C:\Users\C\AppData\Local\Temp\music_d6qvgkxv
2025-04-19 17:58:01,763 - INFO: 服务启动初始化完成
2025-04-19 18:43:47,572 - INFO: 临时目录创建于: C:\Users\C\AppData\Local\Temp\music_kzsfblsx
2025-04-19 18:43:48,548 - INFO: 服务启动初始化完成
2025-04-19 18:43:55,046 - INFO: 临时目录创建于: C:\Users\C\AppData\Local\Temp\music_o82ulvzi
2025-04-19 18:43:55,964 - INFO: 服务启动初始化完成
2025-04-19 19:17:53,621 - INFO: 临时目录创建于: C:\Users\C\AppData\Local\Temp\music_dfj8uxv8
2025-04-19 19:17:54,605 - INFO: 服务启动初始化完成
2025-04-19 19:21:12,349 - INFO: 临时目录创建于: C:\Users\C\AppData\Local\Temp\music_r6ck_04k
2025-04-19 19:21:13,327 - INFO: 服务启动初始化完成
2025-04-19 19:21:20,023 - INFO: 临时目录创建于: C:\Users\C\AppData\Local\Temp\music_eqxtjav8
2025-04-19 19:21:21,007 - INFO: 服务启动初始化完成
2025-04-19 19:22:07,134 - INFO: 临时目录创建于: C:\Users\C\AppData\Local\Temp\music_5qe7l1au
2025-04-19 19:22:08,134 - INFO: 服务启动初始化完成
2025-04-19 19:22:14,833 - INFO: 临时目录创建于: C:\Users\C\AppData\Local\Temp\music_e8dwon0y
2025-04-19 19:22:15,810 - INFO: 服务启动初始化完成
2025-04-19 19:26:18,687 - INFO: 临时目录创建于: C:\Users\C\AppData\Local\Temp\music_a84gcwow
2025-04-19 19:26:19,666 - INFO: 服务启动初始化完成
2025-04-19 19:26:26,361 - INFO: 临时目录创建于: C:\Users\C\AppData\Local\Temp\music_9p5plhdl
2025-04-19 19:26:27,344 - INFO: 服务启动初始化完成
2025-04-19 19:46:02,439 - INFO: 临时目录创建于: C:\Users\C\AppData\Local\Temp\music_99jg2171
2025-04-19 19:46:03,404 - INFO: 服务启动初始化完成
2025-04-19 21:03:51,631 - INFO: 临时目录创建于: C:\Users\C\AppData\Local\Temp\music_drfho4ys
2025-04-19 21:03:52,642 - INFO: 服务启动初始化完成
2025-04-19 21:06:38,640 - INFO: 临时目录创建于: C:\Users\C\AppData\Local\Temp\music_h8kdn9sn
2025-04-19 21:06:39,601 - INFO: 服务启动初始化完成
2025-04-19 21:07:06,928 - INFO: 临时目录创建于: C:\Users\C\AppData\Local\Temp\music_jaq9i5_h
2025-04-19 21:07:07,905 - INFO: 服务启动初始化完成
2025-04-19 21:07:14,473 - INFO: 临时目录创建于: C:\Users\C\AppData\Local\Temp\music_ni3niuuf
2025-04-19 21:07:15,419 - INFO: 服务启动初始化完成
2025-04-19 21:10:47,792 - INFO: 临时目录创建于: C:\Users\C\AppData\Local\Temp\music_820sxbdj
2025-04-19 21:10:48,768 - INFO: 服务启动初始化完成
2025-04-19 21:10:58,706 - INFO: 临时目录创建于: C:\Users\C\AppData\Local\Temp\music_xi7ekump
2025-04-19 21:10:59,672 - INFO: 服务启动初始化完成
2025-04-19 21:11:17,199 - INFO: 临时目录创建于: C:\Users\C\AppData\Local\Temp\music_dlt31f77
2025-04-19 21:11:18,140 - INFO: 服务启动初始化完成
2025-04-19 21:11:24,862 - INFO: 临时目录创建于: C:\Users\C\AppData\Local\Temp\music_cvvezixj
2025-04-19 21:11:25,876 - INFO: 服务启动初始化完成
2025-04-19 21:12:21,497 - INFO: 临时目录创建于: C:\Users\C\AppData\Local\Temp\music_sf2_1urq
2025-04-19 21:12:22,494 - INFO: 服务启动初始化完成
2025-04-19 21:13:48,349 - INFO: 临时目录创建于: C:\Users\C\AppData\Local\Temp\music_7mn1xyqh
2025-04-19 21:13:49,364 - INFO: 服务启动初始化完成
2025-04-19 21:13:58,247 - INFO: 临时目录创建于: C:\Users\C\AppData\Local\Temp\music_8yen7ftl
2025-04-19 21:13:59,226 - INFO: 服务启动初始化完成
2025-04-19 21:14:43,669 - INFO: 临时目录创建于: C:\Users\C\AppData\Local\Temp\music_7w5r1o_l
2025-04-19 21:14:44,664 - INFO: 服务启动初始化完成
2025-04-19 21:17:07,050 - INFO: 临时目录创建于: C:\Users\C\AppData\Local\Temp\music_acmmwg93
2025-04-19 21:17:08,058 - INFO: 服务启动初始化完成
2025-04-19 21:17:27,164 - INFO: 临时目录创建于: C:\Users\C\AppData\Local\Temp\music_mq6boo5q
2025-04-19 21:17:28,150 - INFO: 服务启动初始化完成
2025-04-19 21:17:51,327 - INFO: 临时目录创建于: C:\Users\C\AppData\Local\Temp\music_2mq8s07j
2025-04-19 21:17:52,291 - INFO: 服务启动初始化完成
2025-04-19 21:18:36,634 - INFO: 临时目录创建于: C:\Users\C\AppData\Local\Temp\music_8tok0e0a
2025-04-19 21:18:37,622 - INFO: 服务启动初始化完成
2025-04-19 21:18:48,497 - INFO: 临时目录创建于: C:\Users\C\AppData\Local\Temp\music_njlq74no
2025-04-19 21:18:49,484 - INFO: 服务启动初始化完成
2025-04-19 21:38:49,691 - INFO: 临时目录创建于: C:\Users\C\AppData\Local\Temp\music_l_1vc4bu
2025-04-19 21:38:50,626 - INFO: 服务启动初始化完成
2025-04-19 21:38:57,276 - INFO: 临时目录创建于: C:\Users\C\AppData\Local\Temp\music_lxsor1ts
2025-04-19 21:38:58,248 - INFO: 服务启动初始化完成
2025-04-19 21:41:48,227 - INFO: 临时目录创建于: C:\Users\C\AppData\Local\Temp\music_wmckq_5w
2025-04-19 21:41:49,254 - INFO: 服务启动初始化完成
2025-04-19 21:43:47,327 - INFO: 临时目录创建于: C:\Users\C\AppData\Local\Temp\music_cienf4gv
2025-04-19 21:43:48,315 - INFO: 服务启动初始化完成
2025-04-19 22:53:51,110 - INFO: 临时目录创建于: C:\Users\C\AppData\Local\Temp\music_i0zt7ucf
2025-04-19 22:53:52,225 - INFO: 服务启动初始化完成
2025-04-19 22:53:58,738 - INFO: 临时目录创建于: C:\Users\C\AppData\Local\Temp\music_fzpfoktt
2025-04-19 22:53:59,666 - INFO: 服务启动初始化完成
2025-04-20 00:57:33,008 - INFO: 临时目录创建于: C:\Users\C\AppData\Local\Temp\music_nnlcgchj
2025-04-20 00:57:34,059 - INFO: 服务启动初始化完成
2025-04-20 00:57:40,752 - INFO: 临时目录创建于: C:\Users\C\AppData\Local\Temp\music_gxkcm83t
2025-04-20 00:57:41,752 - INFO: 服务启动初始化完成
2025-04-20 01:04:03,509 - INFO: 临时目录创建于: C:\Users\C\AppData\Local\Temp\music_tuzul0bq
2025-04-20 01:04:04,500 - INFO: 服务启动初始化完成
2025-04-20 01:05:12,318 - INFO: 临时目录创建于: C:\Users\C\AppData\Local\Temp\music_b9_p3w4o
2025-04-20 01:05:13,383 - INFO: 服务启动初始化完成
2025-04-20 01:07:55,128 - INFO: 临时目录创建于: C:\Users\C\AppData\Local\Temp\music_z42c_b8k
2025-04-20 01:07:56,158 - INFO: 服务启动初始化完成
2025-04-20 01:08:24,616 - INFO: 临时目录创建于: C:\Users\C\AppData\Local\Temp\music__qlzyt31
2025-04-20 01:08:25,696 - INFO: 服务启动初始化完成
2025-04-20 01:09:10,299 - INFO: 临时目录创建于: C:\Users\C\AppData\Local\Temp\music_s32t6s69
2025-04-20 01:09:11,349 - INFO: 服务启动初始化完成
2025-04-20 01:13:01,964 - INFO: 临时目录创建于: C:\Users\C\AppData\Local\Temp\music_vxv3edq2
2025-04-20 01:13:02,995 - INFO: 服务启动初始化完成
2025-04-20 01:13:12,031 - INFO: 临时目录创建于: C:\Users\C\AppData\Local\Temp\music_jswy086w
2025-04-20 01:13:13,023 - INFO: 服务启动初始化完成
2025-04-20 01:13:33,024 - INFO: 临时目录创建于: C:\Users\C\AppData\Local\Temp\music_qp4993ma
2025-04-20 01:13:34,006 - INFO: 服务启动初始化完成
2025-04-20 11:52:35,829 - INFO: 临时目录创建于: C:\Users\C\AppData\Local\Temp\music__9qj0cus
2025-04-20 11:52:36,764 - INFO: 服务启动初始化完成
2025-04-20 11:52:38,372 - INFO: 临时目录创建于: C:\Users\C\AppData\Local\Temp\music_we6m71jz
2025-04-20 11:52:39,309 - INFO: 服务启动初始化完成
2025-04-20 12:15:00,086 - INFO: 临时目录创建于: C:\Users\C\AppData\Local\Temp\music_7nxy_wnm
2025-04-20 12:15:00,450 - INFO: 服务启动初始化完成
2025-04-20 12:15:02,120 - INFO: 临时目录创建于: C:\Users\C\AppData\Local\Temp\music_cgpdxhqy
2025-04-20 12:15:02,471 - INFO: 服务启动初始化完成
2025-04-20 12:18:57,549 - INFO: 临时目录创建于: C:\Users\C\AppData\Local\Temp\music_r6fl7gna
2025-04-20 12:18:57,890 - INFO: 服务启动初始化完成
2025-04-20 12:18:59,487 - INFO: 临时目录创建于: C:\Users\C\AppData\Local\Temp\music_ni77urpk
2025-04-20 12:18:59,846 - INFO: 服务启动初始化完成
2025-04-21 21:50:37,964 - INFO: 临时目录创建于: C:\Users\C\AppData\Local\Temp\music_lr3pvzff
2025-04-21 21:50:39,028 - INFO: 服务启动初始化完成
2025-04-21 21:50:40,714 - INFO: 临时目录创建于: C:\Users\C\AppData\Local\Temp\music_rk8eeerx
2025-04-21 21:50:41,733 - INFO: 服务启动初始化完成
2025-04-21 22:06:55,515 - INFO: 临时目录创建于: C:\Users\C\AppData\Local\Temp\music_rr5nkjfj
2025-04-21 22:06:56,520 - INFO: 服务启动初始化完成
2025-04-21 22:16:47,760 - INFO: 临时目录创建于: C:\Users\C\AppData\Local\Temp\music_305hfshh
2025-04-21 22:16:48,778 - INFO: 服务启动初始化完成
2025-04-21 22:31:25,197 - INFO: 临时目录创建于: C:\Users\C\AppData\Local\Temp\music_o_dxbpeo
2025-04-21 22:31:26,127 - INFO: 服务启动初始化完成
2025-04-21 22:50:27,518 - INFO: 临时目录创建于: C:\Users\C\AppData\Local\Temp\music_k21eqdjh
2025-04-21 22:50:28,477 - INFO: 服务启动初始化完成
2025-04-21 22:50:30,103 - INFO: 临时目录创建于: C:\Users\C\AppData\Local\Temp\music_2auuwbwr
2025-04-21 22:50:31,087 - INFO: 服务启动初始化完成
2025-04-21 22:52:18,346 - INFO: 临时目录创建于: C:\Users\C\AppData\Local\Temp\music_aq4q5bpu
2025-04-21 22:52:19,286 - INFO: 服务启动初始化完成
2025-04-21 22:53:11,887 - INFO: 临时目录创建于: C:\Users\C\AppData\Local\Temp\music_umjw4ae4
2025-04-21 22:53:12,870 - INFO: 服务启动初始化完成
2025-04-21 22:55:39,843 - INFO: 临时目录创建于: C:\Users\C\AppData\Local\Temp\music_uq2bnhym
2025-04-21 22:55:40,833 - INFO: 服务启动初始化完成
2025-04-21 22:56:10,124 - INFO: 临时目录创建于: C:\Users\C\AppData\Local\Temp\music_uc5sx_ju
2025-04-21 22:56:11,134 - INFO: 服务启动初始化完成
2025-04-21 22:57:43,462 - INFO: 临时目录创建于: C:\Users\C\AppData\Local\Temp\music_zpzhymw5
2025-04-21 22:57:44,459 - INFO: 服务启动初始化完成
2025-04-21 23:00:14,476 - INFO: 临时目录创建于: C:\Users\C\AppData\Local\Temp\music_k1nozx64
2025-04-21 23:00:14,876 - INFO: 服务启动初始化完成
2025-04-21 23:00:39,635 - INFO: 临时目录创建于: C:\Users\C\AppData\Local\Temp\music_gxyssg1w
2025-04-21 23:00:39,973 - INFO: 服务启动初始化完成
2025-04-21 23:00:41,818 - INFO: 临时目录创建于: C:\Users\C\AppData\Local\Temp\music_cp5272w1
2025-04-21 23:00:42,188 - INFO: 服务启动初始化完成
2025-04-21 23:04:44,407 - INFO: 临时目录创建于: C:\Users\C\AppData\Local\Temp\music_b3kb2gm9
2025-04-21 23:04:44,793 - INFO: 服务启动初始化完成
2025-04-21 23:04:46,474 - INFO: 临时目录创建于: C:\Users\C\AppData\Local\Temp\music_vj3vfr_l
2025-04-21 23:04:46,848 - INFO: 服务启动初始化完成
2025-04-21 23:10:52,600 - INFO: 临时目录创建于: C:\Users\C\AppData\Local\Temp\music_evhrxsw1
2025-04-21 23:10:53,595 - INFO: 服务启动初始化完成
2025-04-21 23:11:22,575 - INFO: 临时目录创建于: C:\Users\C\AppData\Local\Temp\music_vwa9f2ih
2025-04-21 23:11:23,613 - INFO: 服务启动初始化完成
2025-04-21 23:13:12,823 - INFO: 临时目录创建于: C:\Users\C\AppData\Local\Temp\music_vgvtx1k0
2025-04-21 23:13:13,788 - INFO: 服务启动初始化完成
2025-04-21 23:17:33,995 - INFO: 临时目录创建于: C:\Users\C\AppData\Local\Temp\music_hfuzflta
2025-04-21 23:17:34,976 - INFO: 服务启动初始化完成
2025-04-21 23:19:44,538 - INFO: 临时目录创建于: C:\Users\C\AppData\Local\Temp\music_puvripsu
2025-04-21 23:19:45,550 - INFO: 服务启动初始化完成
2025-04-21 23:19:48,383 - INFO: 临时目录创建于: C:\Users\C\AppData\Local\Temp\music_v12ru3w1
2025-04-21 23:19:49,371 - INFO: 服务启动初始化完成
2025-04-21 23:20:22,796 - INFO: 临时目录创建于: C:\Users\C\AppData\Local\Temp\music_jinpeybl
2025-04-21 23:20:23,762 - INFO: 服务启动初始化完成
2025-04-21 23:24:16,672 - INFO: 临时目录创建于: C:\Users\C\AppData\Local\Temp\music_0_82ij0i
2025-04-21 23:24:17,599 - INFO: 服务启动初始化完成
2025-04-21 23:26:16,949 - INFO: 临时目录创建于: C:\Users\C\AppData\Local\Temp\music_r0ki5l7o
2025-04-21 23:26:17,969 - INFO: 服务启动初始化完成
2025-04-21 23:37:27,998 - INFO: 临时目录创建于: C:\Users\C\AppData\Local\Temp\music_0_4ha8sf
2025-04-21 23:37:28,978 - INFO: 服务启动初始化完成
2025-04-21 23:37:30,616 - INFO: 临时目录创建于: C:\Users\C\AppData\Local\Temp\music_nqiujb_u
2025-04-21 23:37:31,570 - INFO: 服务启动初始化完成
2025-04-21 23:44:20,857 - INFO: 临时目录创建于: C:\Users\C\AppData\Local\Temp\music_sxun2c03
2025-04-21 23:44:21,825 - INFO: 服务启动初始化完成
2025-04-21 23:44:42,857 - INFO: 临时目录创建于: C:\Users\C\AppData\Local\Temp\music_zzxoihdl
2025-04-21 23:44:43,836 - INFO: 服务启动初始化完成
2025-04-21 23:46:43,565 - INFO: 临时目录创建于: C:\Users\C\AppData\Local\Temp\music_df8bg35j
2025-04-21 23:46:44,536 - INFO: 服务启动初始化完成
2025-04-22 00:08:43,749 - INFO: 临时目录创建于: C:\Users\C\AppData\Local\Temp\music_7hac2_rq
2025-04-22 00:08:45,594 - INFO: 服务启动初始化完成
2025-04-22 10:23:31,026 - INFO: 临时目录创建于: C:\Users\C\AppData\Local\Temp\music_2ro4qtfu
2025-04-22 10:23:32,321 - INFO: 服务启动初始化完成
2025-04-22 10:23:39,237 - INFO: 临时目录创建于: C:\Users\C\AppData\Local\Temp\music_b77z2vo1
2025-04-22 10:23:40,282 - INFO: 服务启动初始化完成
2025-04-22 14:37:39,623 - INFO: 临时目录创建于: C:\Users\C\AppData\Local\Temp\music_qlmbqcln
2025-04-22 14:37:40,219 - INFO: 服务启动初始化完成
2025-04-22 14:37:43,560 - INFO: 临时目录创建于: C:\Users\C\AppData\Local\Temp\music_r9j_62ue
2025-04-22 14:37:44,174 - INFO: 服务启动初始化完成
2025-04-22 14:40:03,914 - INFO: 临时目录创建于: C:\Users\C\AppData\Local\Temp\music_uu6rc160
2025-04-22 14:40:04,645 - INFO: 服务启动初始化完成
2025-04-22 14:56:30,155 - INFO: 临时目录创建于: C:\Users\C\AppData\Local\Temp\music_o8ktkp8u
2025-04-22 14:56:31,992 - INFO: 服务启动初始化完成
2025-04-22 14:56:36,817 - INFO: 临时目录创建于: C:\Users\C\AppData\Local\Temp\music_6zv8qjr7
2025-04-22 14:56:38,571 - INFO: 服务启动初始化完成
2025-04-22 14:56:51,254 - INFO: 临时目录创建于: C:\Users\C\AppData\Local\Temp\music_k_j3o6gc
2025-04-22 14:56:52,644 - INFO: 服务启动初始化完成
2025-04-22 14:57:05,979 - INFO: 临时目录创建于: C:\Users\C\AppData\Local\Temp\music_1j4y1yyf
2025-04-22 14:57:08,106 - INFO: 服务启动初始化完成
2025-04-22 14:57:11,719 - INFO: 临时目录创建于: C:\Users\C\AppData\Local\Temp\music_pblkx6ag
2025-04-22 14:57:13,473 - INFO: 服务启动初始化完成
2025-04-22 15:02:20,651 - INFO: 临时目录创建于: C:\Users\C\AppData\Local\Temp\music_srj0fq4b
2025-04-22 15:02:22,386 - INFO: 服务启动初始化完成
2025-04-22 15:03:47,660 - INFO: 临时目录创建于: C:\Users\C\AppData\Local\Temp\music__bmy0vlg
2025-04-22 15:03:49,436 - INFO: 服务启动初始化完成
2025-04-22 15:04:00,124 - INFO: 临时目录创建于: C:\Users\C\AppData\Local\Temp\music_v8b9wm8m
2025-04-22 15:04:01,969 - INFO: 服务启动初始化完成
2025-04-22 15:04:05,567 - INFO: 临时目录创建于: C:\Users\C\AppData\Local\Temp\music_739qoa9x
2025-04-22 15:04:07,767 - INFO: 服务启动初始化完成
2025-04-22 16:49:14,282 - INFO: 临时目录创建于: C:\Users\C\AppData\Local\Temp\music_4gbxz80b
2025-04-22 16:49:14,678 - INFO: 服务启动初始化完成
2025-04-22 16:49:21,231 - INFO: 临时目录创建于: C:\Users\C\AppData\Local\Temp\music_x7vskeaa
2025-04-22 16:49:21,569 - INFO: 服务启动初始化完成
2025-04-22 16:51:42,500 - INFO: 临时目录创建于: C:\Users\C\AppData\Local\Temp\music_hl6ksbvi
2025-04-22 16:51:42,839 - INFO: 服务启动初始化完成
2025-04-22 16:57:43,016 - INFO: 临时目录创建于: C:\Users\C\AppData\Local\Temp\music_i1o6q8uy
2025-04-22 16:57:43,384 - INFO: 服务启动初始化完成
2025-04-22 16:57:50,013 - INFO: 临时目录创建于: C:\Users\C\AppData\Local\Temp\music_jmcy2xd5
2025-04-22 16:57:50,362 - INFO: 服务启动初始化完成
2025-04-22 17:03:19,698 - INFO: 临时目录创建于: C:\Users\C\AppData\Local\Temp\music_rbr9tf8q
2025-04-22 17:03:20,674 - INFO: 服务启动初始化完成
2025-04-22 20:03:11,520 - INFO: 临时目录创建于: C:\Users\C\AppData\Local\Temp\music_lbvkrfoe
2025-04-22 20:03:12,438 - INFO: 服务启动初始化完成
2025-04-22 20:03:18,965 - INFO: 临时目录创建于: C:\Users\C\AppData\Local\Temp\music_7e8l_ga4
2025-04-22 20:03:19,912 - INFO: 服务启动初始化完成
2025-04-22 20:37:11,476 - INFO: 临时目录创建于: C:\Users\C\AppData\Local\Temp\music_xn44sm2h
2025-04-22 20:37:12,414 - INFO: 服务启动初始化完成
2025-04-22 20:37:18,892 - INFO: 临时目录创建于: C:\Users\C\AppData\Local\Temp\music_ljj7qbvu
2025-04-22 20:37:19,795 - INFO: 服务启动初始化完成
2025-04-22 20:39:58,887 - INFO: 临时目录创建于: C:\Users\C\AppData\Local\Temp\music_ja2wn_uf
2025-04-22 20:39:59,938 - INFO: 服务启动初始化完成
2025-04-22 20:40:06,417 - INFO: 临时目录创建于: C:\Users\C\AppData\Local\Temp\music_0a3ycbzt
2025-04-22 20:40:07,424 - INFO: 服务启动初始化完成
2025-04-22 20:41:22,383 - INFO: 临时目录创建于: C:\Users\C\AppData\Local\Temp\music_rx71w5z_
2025-04-22 20:41:23,323 - INFO: 服务启动初始化完成
2025-04-22 20:41:52,593 - INFO: 临时目录创建于: C:\Users\C\AppData\Local\Temp\music_67fy4z7a
2025-04-22 20:41:53,604 - INFO: 服务启动初始化完成
2025-04-22 20:45:19,523 - INFO: 临时目录创建于: C:\Users\C\AppData\Local\Temp\music_09p096n4
2025-04-22 20:45:20,505 - INFO: 服务启动初始化完成
2025-04-22 20:45:27,096 - INFO: 临时目录创建于: C:\Users\C\AppData\Local\Temp\music_bnqfzvdv
2025-04-22 20:45:28,051 - INFO: 服务启动初始化完成
2025-04-22 20:47:27,453 - INFO: 临时目录创建于: C:\Users\C\AppData\Local\Temp\music_hbdzi6u2
2025-04-22 20:47:28,415 - INFO: 服务启动初始化完成
2025-04-22 20:47:48,475 - INFO: 临时目录创建于: C:\Users\C\AppData\Local\Temp\music_9d0o1tih
2025-04-22 20:47:49,466 - INFO: 服务启动初始化完成
2025-04-22 20:47:59,344 - INFO: 临时目录创建于: C:\Users\C\AppData\Local\Temp\music_2k1gj25k
2025-04-22 20:48:00,273 - INFO: 服务启动初始化完成
2025-04-22 20:49:05,926 - INFO: 临时目录创建于: C:\Users\C\AppData\Local\Temp\music_kcpkts74
2025-04-22 20:49:06,894 - INFO: 服务启动初始化完成
2025-04-22 21:05:05,081 - INFO: 临时目录创建于: C:\Users\C\AppData\Local\Temp\music_g4pjc_4q
2025-04-22 21:05:06,082 - INFO: 服务启动初始化完成
2025-04-22 21:05:12,647 - INFO: 临时目录创建于: C:\Users\C\AppData\Local\Temp\music_4x0xq1ji
2025-04-22 21:05:13,592 - INFO: 服务启动初始化完成
2025-04-22 21:05:34,811 - INFO: 临时目录创建于: C:\Users\C\AppData\Local\Temp\music_5ooes7au
2025-04-22 21:05:35,774 - INFO: 服务启动初始化完成
2025-04-22 21:06:24,367 - INFO: 临时目录创建于: C:\Users\C\AppData\Local\Temp\music_ouocip2f
2025-04-22 21:06:25,364 - INFO: 服务启动初始化完成
2025-04-23 14:57:46,647 - INFO: 临时目录创建于: C:\Users\C\AppData\Local\Temp\music_trtjycjw
2025-04-23 14:57:49,373 - INFO: 服务启动初始化完成
2025-04-23 14:57:57,631 - INFO: 临时目录创建于: C:\Users\C\AppData\Local\Temp\music_5wom39zc
2025-04-23 14:57:59,499 - INFO: 服务启动初始化完成
2025-04-23 15:41:59,705 - INFO: 临时目录创建于: C:\Users\C\AppData\Local\Temp\music_rsgg826v
2025-04-23 15:42:01,600 - INFO: 服务启动初始化完成
2025-04-23 16:06:20,098 - INFO: 临时目录创建于: C:\Users\C\AppData\Local\Temp\music_ch0pvi8a
2025-04-23 16:06:21,294 - INFO: 服务启动初始化完成
2025-04-23 16:06:29,309 - INFO: 临时目录创建于: C:\Users\C\AppData\Local\Temp\music__aono34u
2025-04-23 16:06:30,316 - INFO: 服务启动初始化完成
2025-04-23 16:10:26,415 - INFO: 临时目录创建于: C:\Users\C\AppData\Local\Temp\music_zrybrdam
2025-04-23 16:10:27,491 - INFO: 服务启动初始化完成
2025-04-23 16:11:22,158 - INFO: 临时目录创建于: C:\Users\C\AppData\Local\Temp\music_sibgtpy3
2025-04-23 16:11:23,166 - INFO: 服务启动初始化完成
2025-04-23 16:13:12,641 - INFO: 临时目录创建于: C:\Users\C\AppData\Local\Temp\music_unz3x7ba
2025-04-23 16:13:13,630 - INFO: 服务启动初始化完成
2025-04-23 16:23:37,907 - INFO: 临时目录创建于: C:\Users\C\AppData\Local\Temp\music_e_9oidye
2025-04-23 16:23:38,904 - INFO: 服务启动初始化完成
2025-04-23 16:23:45,472 - INFO: 临时目录创建于: C:\Users\C\AppData\Local\Temp\music_ryq0w6uh
2025-04-23 16:23:46,413 - INFO: 服务启动初始化完成
2025-04-23 16:24:51,224 - INFO: 临时目录创建于: C:\Users\C\AppData\Local\Temp\music_qzjhm0oc
2025-04-23 16:24:52,206 - INFO: 服务启动初始化完成
2025-04-23 16:32:42,049 - INFO: 临时目录创建于: C:\Users\C\AppData\Local\Temp\music_wvagfx6e
2025-04-23 16:32:43,033 - INFO: 服务启动初始化完成
2025-04-23 16:33:08,067 - INFO: 临时目录创建于: C:\Users\C\AppData\Local\Temp\music_bl53m3hp
2025-04-23 16:33:09,036 - INFO: 服务启动初始化完成
2025-04-23 17:02:10,972 - INFO: 临时目录创建于: C:\Users\C\AppData\Local\Temp\music_yxfbjupt
2025-04-23 17:02:11,339 - INFO: 服务启动初始化完成
2025-04-23 17:02:18,158 - INFO: 临时目录创建于: C:\Users\C\AppData\Local\Temp\music_km7e9wet
2025-04-23 17:02:18,492 - INFO: 服务启动初始化完成
2025-04-23 17:02:40,835 - INFO: 临时目录创建于: C:\Users\C\AppData\Local\Temp\music_s4972p4e
2025-04-23 17:02:41,179 - INFO: 服务启动初始化完成
2025-04-23 17:04:47,754 - INFO: 临时目录创建于: C:\Users\C\AppData\Local\Temp\music_th3his_z
2025-04-23 17:04:48,095 - INFO: 服务启动初始化完成
2025-04-23 17:04:55,004 - INFO: 临时目录创建于: C:\Users\C\AppData\Local\Temp\music_xg0h1a49
2025-04-23 17:04:55,351 - INFO: 服务启动初始化完成
2025-04-23 17:05:21,836 - INFO: 临时目录创建于: C:\Users\C\AppData\Local\Temp\music_cvnauuc5
2025-04-23 17:05:22,174 - INFO: 服务启动初始化完成
2025-04-23 17:09:27,608 - INFO: 临时目录创建于: C:\Users\C\AppData\Local\Temp\music_6vdd8hdc
2025-04-23 17:09:27,953 - INFO: 服务启动初始化完成
2025-04-23 17:09:45,316 - INFO: 临时目录创建于: C:\Users\C\AppData\Local\Temp\music_ppuhxiik
2025-04-23 17:09:45,672 - INFO: 服务启动初始化完成
2025-04-23 17:10:54,770 - INFO: 临时目录创建于: C:\Users\C\AppData\Local\Temp\music_7547t3y8
2025-04-23 17:10:55,118 - INFO: 服务启动初始化完成
2025-04-23 17:11:06,293 - INFO: 临时目录创建于: C:\Users\C\AppData\Local\Temp\music_0mj720rc
2025-04-23 17:11:06,642 - INFO: 服务启动初始化完成
2025-04-23 17:11:19,952 - INFO: 临时目录创建于: C:\Users\C\AppData\Local\Temp\music_84g5yknf
2025-04-23 17:11:20,295 - INFO: 服务启动初始化完成
2025-04-23 17:11:27,195 - INFO: 临时目录创建于: C:\Users\C\AppData\Local\Temp\music_326m3cu3
2025-04-23 17:11:27,547 - INFO: 服务启动初始化完成
2025-04-23 17:17:19,166 - INFO: 临时目录创建于: C:\Users\C\AppData\Local\Temp\music_qou5n2k3
2025-04-23 17:17:20,170 - INFO: 服务启动初始化完成
2025-04-23 17:32:59,193 - INFO: 临时目录创建于: C:\Users\C\AppData\Local\Temp\music_7n_mfnsi
2025-04-23 17:33:00,161 - INFO: 服务启动初始化完成
2025-04-23 17:33:07,018 - INFO: 临时目录创建于: C:\Users\C\AppData\Local\Temp\music_27bn32ni
2025-04-23 17:33:07,969 - INFO: 服务启动初始化完成
2025-04-23 22:10:14,136 - INFO: 临时目录创建于: C:\Users\C\AppData\Local\Temp\music_edtquvad
2025-04-23 22:10:14,657 - INFO: 服务启动初始化完成
2025-04-23 22:10:21,337 - INFO: 临时目录创建于: C:\Users\C\AppData\Local\Temp\music_136l7_i8
2025-04-23 22:10:21,691 - INFO: 服务启动初始化完成
2025-04-23 22:12:41,584 - INFO: 临时目录创建于: C:\Users\C\AppData\Local\Temp\music_8r5nr8rv
2025-04-23 22:12:41,930 - INFO: 服务启动初始化完成
2025-04-24 10:09:11,961 - INFO: 临时目录创建于: C:\Users\C\AppData\Local\Temp\music_j3348n7g
2025-04-24 10:09:12,326 - INFO: 服务启动初始化完成
2025-04-24 10:09:19,074 - INFO: 临时目录创建于: C:\Users\C\AppData\Local\Temp\music_iueonxqq
2025-04-24 10:09:19,399 - INFO: 服务启动初始化完成
2025-04-24 10:41:00,302 - INFO: 临时目录创建于: C:\Users\C\AppData\Local\Temp\music_p3rfti6v
2025-04-24 10:41:00,665 - INFO: 服务启动初始化完成
2025-04-24 10:46:33,133 - INFO: 临时目录创建于: C:\Users\C\AppData\Local\Temp\music_0dyi5o5b
2025-04-24 10:46:33,478 - INFO: 服务启动初始化完成
2025-04-24 10:52:04,884 - INFO: 临时目录创建于: C:\Users\C\AppData\Local\Temp\music_x4jumlr7
2025-04-24 10:52:05,237 - INFO: 服务启动初始化完成
2025-04-24 10:52:08,346 - INFO: 临时目录创建于: C:\Users\C\AppData\Local\Temp\music_0745reva
2025-04-24 10:52:08,765 - INFO: 服务启动初始化完成
2025-04-24 10:52:38,239 - INFO: 临时目录创建于: C:\Users\C\AppData\Local\Temp\music_bt87auph
2025-04-24 10:52:38,617 - INFO: 服务启动初始化完成
2025-04-24 10:53:27,302 - INFO: 临时目录创建于: C:\Users\C\AppData\Local\Temp\music_3brqubmq
2025-04-24 10:53:27,649 - INFO: 服务启动初始化完成
2025-04-24 10:53:42,844 - INFO: 临时目录创建于: C:\Users\C\AppData\Local\Temp\music_pizfemeq
2025-04-24 10:53:43,183 - INFO: 服务启动初始化完成
2025-04-24 10:54:16,732 - INFO: 临时目录创建于: C:\Users\C\AppData\Local\Temp\music_b4yo1rer
2025-04-24 10:54:17,084 - INFO: 服务启动初始化完成
2025-04-24 10:54:47,596 - INFO: 临时目录创建于: C:\Users\C\AppData\Local\Temp\music_vlgd8tv6
2025-04-24 10:54:47,962 - INFO: 服务启动初始化完成
2025-04-24 16:43:51,808 - INFO: 临时目录创建于: C:\Users\C\AppData\Local\Temp\music_sxjro476
2025-04-24 16:43:52,878 - INFO: 服务启动初始化完成
2025-04-24 16:43:59,723 - INFO: 临时目录创建于: C:\Users\C\AppData\Local\Temp\music_6qtc6y5d
2025-04-24 16:44:00,697 - INFO: 服务启动初始化完成
2025-04-24 17:48:02,700 - INFO: 临时目录创建于: C:\Users\C\AppData\Local\Temp\music_76x4rxqd
2025-04-24 17:48:03,080 - INFO: 服务启动初始化完成
2025-04-24 17:48:33,264 - INFO: 临时目录创建于: C:\Users\C\AppData\Local\Temp\music_4k5nk2q1
2025-04-24 17:48:33,610 - INFO: 服务启动初始化完成
2025-04-24 17:48:40,450 - INFO: 临时目录创建于: C:\Users\C\AppData\Local\Temp\music_j0bhz4pn
2025-04-24 17:48:40,807 - INFO: 服务启动初始化完成
2025-04-24 17:50:01,083 - INFO: 临时目录创建于: C:\Users\C\AppData\Local\Temp\music_s66fngi0
2025-04-24 17:50:01,444 - INFO: 服务启动初始化完成
2025-04-24 17:52:39,807 - INFO: 临时目录创建于: C:\Users\C\AppData\Local\Temp\music_w8nv8yko
2025-04-24 17:52:40,156 - INFO: 服务启动初始化完成
2025-04-24 17:52:44,252 - INFO: 临时目录创建于: C:\Users\C\AppData\Local\Temp\music_9cq87yjo
2025-04-24 17:52:44,605 - INFO: 服务启动初始化完成
2025-04-24 17:52:51,597 - INFO: 临时目录创建于: C:\Users\C\AppData\Local\Temp\music_mvr5jq4s
2025-04-24 17:52:51,955 - INFO: 服务启动初始化完成
2025-04-24 17:54:59,768 - INFO: 临时目录创建于: C:\Users\C\AppData\Local\Temp\music_0hao5ksz
2025-04-24 17:55:00,115 - INFO: 服务启动初始化完成
2025-04-24 17:55:07,197 - INFO: 临时目录创建于: C:\Users\C\AppData\Local\Temp\music_qo2vxchs
2025-04-24 17:55:07,530 - INFO: 服务启动初始化完成
2025-04-24 17:55:14,317 - INFO: 临时目录创建于: C:\Users\C\AppData\Local\Temp\music_6c5lbvcb
2025-04-24 17:55:14,664 - INFO: 服务启动初始化完成
2025-04-24 17:57:50,964 - INFO: 临时目录创建于: C:\Users\C\AppData\Local\Temp\music_il3v7esh
2025-04-24 17:57:51,315 - INFO: 服务启动初始化完成
2025-04-24 17:57:56,510 - INFO: 临时目录创建于: C:\Users\C\AppData\Local\Temp\music_xsu9bkqd
2025-04-24 17:57:59,678 - INFO: 临时目录创建于: C:\Users\C\AppData\Local\Temp\music_8lzogd1n
2025-04-24 17:58:00,069 - INFO: 服务启动初始化完成
2025-04-24 17:58:06,814 - INFO: 临时目录创建于: C:\Users\C\AppData\Local\Temp\music_jd5bome6
2025-04-24 17:58:07,150 - INFO: 服务启动初始化完成
2025-04-24 18:03:26,540 - INFO: 临时目录创建于: C:\Users\C\AppData\Local\Temp\music_xxa2gk3x
2025-04-24 18:03:27,487 - INFO: 服务启动初始化完成
2025-04-24 18:07:11,045 - INFO: 临时目录创建于: C:\Users\C\AppData\Local\Temp\music_ah9cax6h
2025-04-24 18:07:12,013 - INFO: 服务启动初始化完成
2025-04-24 18:07:18,800 - INFO: 临时目录创建于: C:\Users\C\AppData\Local\Temp\music_sq1czqls
2025-04-24 18:07:19,709 - INFO: 服务启动初始化完成
2025-04-24 18:10:29,287 - INFO: 临时目录创建于: C:\Users\C\AppData\Local\Temp\music_rxzqi60y
2025-04-24 18:10:31,934 - INFO: 临时目录创建于: C:\Users\C\AppData\Local\Temp\music_k6vlv189
2025-04-24 18:10:32,939 - INFO: 服务启动初始化完成
2025-04-24 18:10:39,716 - INFO: 临时目录创建于: C:\Users\C\AppData\Local\Temp\music_c6c2hjpt
2025-04-24 18:10:40,060 - INFO: 服务启动初始化完成
2025-04-24 18:14:56,750 - INFO: 临时目录创建于: C:\Users\C\AppData\Local\Temp\music_l574qq5i
2025-04-24 18:14:57,827 - INFO: 服务启动初始化完成
2025-04-24 18:17:47,212 - INFO: 临时目录创建于: C:\Users\C\AppData\Local\Temp\music_yd1hxfk3
2025-04-24 18:17:48,193 - INFO: 服务启动初始化完成
2025-04-24 18:17:58,389 - INFO: 临时目录创建于: C:\Users\C\AppData\Local\Temp\music_9bbslddn
2025-04-24 18:17:59,340 - INFO: 服务启动初始化完成
2025-04-24 18:18:17,838 - INFO: 临时目录创建于: C:\Users\C\AppData\Local\Temp\music_m522peua
2025-04-24 18:18:18,234 - INFO: 服务启动初始化完成
2025-04-24 18:23:33,581 - INFO: 临时目录创建于: C:\Users\C\AppData\Local\Temp\music_32s25nnz
2025-04-24 18:23:34,711 - INFO: 服务启动初始化完成
2025-04-24 18:23:39,499 - INFO: 临时目录创建于: C:\Users\C\AppData\Local\Temp\music_n5qvtioy
2025-04-24 18:23:39,859 - INFO: 服务启动初始化完成
2025-04-24 18:23:46,744 - INFO: 临时目录创建于: C:\Users\C\AppData\Local\Temp\music_5mrzmqwh
2025-04-24 18:23:47,101 - INFO: 服务启动初始化完成
2025-04-24 18:30:50,978 - INFO: 临时目录创建于: C:\Users\C\AppData\Local\Temp\music_58poguub
2025-04-24 18:30:51,962 - INFO: 服务启动初始化完成
2025-04-24 18:31:20,471 - INFO: 临时目录创建于: C:\Users\C\AppData\Local\Temp\music_6p852js1
2025-04-24 18:31:31,502 - INFO: 临时目录创建于: C:\Users\C\AppData\Local\Temp\music_l5c09skj
2025-04-24 18:31:31,868 - INFO: 服务启动初始化完成
2025-04-24 18:31:38,614 - INFO: 临时目录创建于: C:\Users\C\AppData\Local\Temp\music_l6zjuu89
2025-04-24 18:31:38,963 - INFO: 服务启动初始化完成
2025-04-24 18:52:21,642 - INFO: 临时目录创建于: C:\Users\C\AppData\Local\Temp\music_djtsb562
2025-04-24 18:52:22,385 - INFO: 服务启动初始化完成
2025-04-24 18:52:30,282 - INFO: 临时目录创建于: C:\Users\C\AppData\Local\Temp\music_pdnvjafz
2025-04-24 18:52:30,846 - INFO: 服务启动初始化完成
2025-04-24 18:58:48,097 - INFO: 临时目录创建于: C:\Users\C\AppData\Local\Temp\music_f07nx2wu
2025-04-24 18:58:48,762 - INFO: 服务启动初始化完成
2025-04-24 18:58:57,520 - INFO: 临时目录创建于: C:\Users\C\AppData\Local\Temp\music_3s3pr4dl
2025-04-24 18:58:58,237 - INFO: 服务启动初始化完成
2025-04-24 19:03:48,898 - INFO: 临时目录创建于: C:\Users\C\AppData\Local\Temp\music__tqmm5vl
2025-04-24 19:03:50,510 - INFO: 服务启动初始化完成
2025-04-24 19:03:59,499 - INFO: 临时目录创建于: C:\Users\C\AppData\Local\Temp\music_9a5r936u
2025-04-24 19:04:00,162 - INFO: 服务启动初始化完成
2025-04-24 19:05:44,638 - INFO: 临时目录创建于: C:\Users\C\AppData\Local\Temp\music_utg03lwp
2025-04-24 19:05:45,201 - INFO: 服务启动初始化完成
2025-04-24 19:23:08,064 - INFO: 临时目录创建于: C:\Users\C\AppData\Local\Temp\music_w3qh943p
2025-04-24 19:23:09,755 - INFO: 服务启动初始化完成
2025-04-24 19:23:30,890 - INFO: 临时目录创建于: C:\Users\C\AppData\Local\Temp\music_6un5bj96
2025-04-24 19:23:32,774 - INFO: 服务启动初始化完成
2025-04-24 21:22:23,504 - INFO: 临时目录创建于: C:\Users\C\AppData\Local\Temp\music__e3m_qol
2025-04-24 21:22:23,906 - INFO: 服务启动初始化完成
2025-04-24 21:22:30,865 - INFO: 临时目录创建于: C:\Users\C\AppData\Local\Temp\music_qme07coi
2025-04-24 21:22:31,197 - INFO: 服务启动初始化完成
2025-04-24 21:41:17,641 - INFO: 临时目录创建于: C:\Users\C\AppData\Local\Temp\music_rggdl089
2025-04-24 21:41:18,006 - INFO: 服务启动初始化完成
2025-04-24 21:41:22,842 - INFO: 临时目录创建于: C:\Users\C\AppData\Local\Temp\music_75jut_0f
2025-04-24 21:41:23,176 - INFO: 服务启动初始化完成
2025-04-24 21:41:30,004 - INFO: 临时目录创建于: C:\Users\C\AppData\Local\Temp\music_u9ct6gjv
2025-04-24 21:41:30,329 - INFO: 服务启动初始化完成
2025-04-25 01:09:02,630 - INFO: 临时目录创建于: C:\Users\C\AppData\Local\Temp\music_6qnkgu9n
2025-04-25 01:09:03,292 - INFO: 服务启动初始化完成
2025-04-25 01:09:12,879 - INFO: 临时目录创建于: C:\Users\C\AppData\Local\Temp\music_cew_m7xp
2025-04-25 01:09:13,536 - INFO: 服务启动初始化完成
2025-04-25 01:09:28,414 - INFO: 临时目录创建于: C:\Users\C\AppData\Local\Temp\music_j494uwz3
2025-04-25 01:09:29,345 - INFO: 服务启动初始化完成
2025-04-25 01:09:38,321 - INFO: 临时目录创建于: C:\Users\C\AppData\Local\Temp\music_wk3abulv
2025-04-25 01:09:39,256 - INFO: 服务启动初始化完成
2025-04-25 11:15:39,397 - INFO: 临时目录创建于: C:\Users\C\AppData\Local\Temp\music_kbyid43l
2025-04-25 11:15:39,758 - INFO: 服务启动初始化完成
2025-04-25 11:15:46,592 - INFO: 临时目录创建于: C:\Users\C\AppData\Local\Temp\music_i9yeqcvk
2025-04-25 11:15:46,954 - INFO: 服务启动初始化完成
2025-04-25 11:40:20,415 - INFO: 临时目录创建于: C:\Users\C\AppData\Local\Temp\music_dwr09vcz
2025-04-25 11:40:20,763 - INFO: 服务启动初始化完成
2025-04-25 11:40:27,735 - INFO: 临时目录创建于: C:\Users\C\AppData\Local\Temp\music_n5ilz1dq
2025-04-25 11:40:28,075 - INFO: 服务启动初始化完成
2025-04-25 11:50:32,257 - INFO: 临时目录创建于: C:\Users\C\AppData\Local\Temp\music_ilxry2yv
2025-04-25 11:50:33,229 - INFO: 服务启动初始化完成
2025-04-25 11:50:55,566 - INFO: 临时目录创建于: C:\Users\C\AppData\Local\Temp\music_uwum2eoq
2025-04-25 11:50:56,643 - INFO: 服务启动初始化完成
2025-04-25 11:51:05,482 - INFO: 临时目录创建于: C:\Users\C\AppData\Local\Temp\music_scloboe4
2025-04-25 11:51:06,477 - INFO: 服务启动初始化完成
2025-04-25 11:51:13,558 - INFO: 临时目录创建于: C:\Users\C\AppData\Local\Temp\music_jynow9ti
2025-04-25 11:51:14,657 - INFO: 服务启动初始化完成
2025-04-25 19:03:22,662 - INFO: 临时目录创建于: C:\Users\C\AppData\Local\Temp\music_fmkd2u1y
2025-04-25 19:03:23,076 - INFO: 服务启动初始化完成
2025-04-25 19:03:29,952 - INFO: 临时目录创建于: C:\Users\C\AppData\Local\Temp\music_15ws4lak
2025-04-25 19:03:30,309 - INFO: 服务启动初始化完成
2025-04-25 19:14:25,179 - INFO: 临时目录创建于: C:\Users\C\AppData\Local\Temp\music_k0vf6l8p
2025-04-25 19:14:25,598 - INFO: 服务启动初始化完成
2025-04-25 19:14:32,731 - INFO: 临时目录创建于: C:\Users\C\AppData\Local\Temp\music_rcr01vkc
2025-04-25 19:14:33,170 - INFO: 服务启动初始化完成
2025-04-25 19:19:32,001 - INFO: 临时目录创建于: C:\Users\C\AppData\Local\Temp\music_jetaxo7w
2025-04-25 19:19:32,416 - INFO: 服务启动初始化完成
2025-04-25 19:32:47,434 - INFO: 临时目录创建于: C:\Users\C\AppData\Local\Temp\music_vp_xd_5e
2025-04-25 19:32:47,810 - INFO: 服务启动初始化完成
2025-04-25 19:32:54,834 - INFO: 临时目录创建于: C:\Users\C\AppData\Local\Temp\music_tmfqdbe5
2025-04-25 19:32:55,189 - INFO: 服务启动初始化完成
2025-04-25 19:38:16,621 - INFO: 临时目录创建于: C:\Users\C\AppData\Local\Temp\music_1ak1hj8k
2025-04-25 19:38:17,013 - INFO: 服务启动初始化完成
2025-04-25 19:44:53,271 - INFO: 临时目录创建于: C:\Users\C\AppData\Local\Temp\music_sn9a912n
2025-04-25 19:44:54,422 - INFO: 服务启动初始化完成
2025-04-25 20:01:46,974 - INFO: 临时目录创建于: C:\Users\C\AppData\Local\Temp\music_gxgxn818
2025-04-25 20:01:48,143 - INFO: 服务启动初始化完成
2025-04-25 20:01:55,482 - INFO: 临时目录创建于: C:\Users\C\AppData\Local\Temp\music_amgh2dnq
2025-04-25 20:01:56,691 - INFO: 服务启动初始化完成
2025-04-25 20:05:30,616 - INFO: 临时目录创建于: C:\Users\C\AppData\Local\Temp\music_diybblwb
2025-04-25 20:05:31,709 - INFO: 服务启动初始化完成
2025-04-25 20:06:02,813 - INFO: 临时目录创建于: C:\Users\C\AppData\Local\Temp\music_u743vqvv
2025-04-25 20:06:03,847 - INFO: 服务启动初始化完成
